Workbook

Sheet Cover
B3: ASM International NV
B4: Equity Valuation Report
B6: AC444 Valuation and Security Analysis
B7: London School of Economics
B9: Ticker: | C9: ENXTAM:ASM
B10: Currency: | C10: EUR (Thousands)
B11: Data Period: | C11: FY 2019 - FY 2024
B12: Forecast Period: | C12: FY 2025E - FY 2030E
B13: Peers: | C13: AIXTRON SE, Applied Materials, Lam Research
B15: Table of Contents
B16: 1. Cover | C16: Title page and overview
B17: 2. Input ASM | C17: Raw financial data - ASM International
B18: 3. Input ASM (Reported) | C18: As-reported financial data - ASM International
B19: 4. Input AIXTRON | C19: Raw financial data - AIXTRON SE
B20: 5. Input AMAT | C20: Raw financial data - Applied Materials
B21: 6. Input LRCX | C21: Raw financial data - Lam Research
B22: 7. Standardized ASM | C22: Standardized financial statements - ASM
B23: 8. Standardized AIXTRON | C23: Standardized financial statements - AIXTRON
B24: 9. Standardized AMAT | C24: Standardized financial statements - Applied Materials
B25: 10. Standardized LRCX | C25: Standardized financial statements - Lam Research
B26: 11. Adjustments | C26: Adjustments and adjusted financial statements
B27: 12. Ratio Analysis | C27: Key financial ratios and analysis
... B32: 17. Football Field | C32: Valuation range summary
B34: Generated: 26 March 2026

Sheet Input ASM
A2: ASM International NV | Income Statement
A3: ENXTAM:ASM (MI KEY: 4231951; SPCIQ KEY: 322899)
A5: Source: Recommended
A6: Period Category: Fiscal
A7: Period Type: Years
A8: Reporting Basis: Current/Restated
A9: Sort Order: Latest on Right
A10: Currency: Euro (EUR)
A11: Magnitude: Thousands (K)
A13: Recommended: S&P Capital IQ - Standard | B13: 2019 FY | C13: 2020 FY | D13: 2021 FY | E13: 2022 FY | F13: 2023 FY | G13: 2024 FY
B14: Current/Restated | C14: Current/Restated | D14: Current/Restated | E14: Current/Restated | F14: Current/Restated | G14: Current/Restated
A15: Period Ended | B15: 43830 | C15: 44196 | D15: 44561 | E15: 44926 | F15: 45291 | G15: 45657
A16: Financial Filing Date | B16: 44260 | C16: 44623 | D16: 44987 | E16: 45352 | F16: 45722 | G16: 45722
A17: Spot Exchange Rate | B17: 1 | C17: 1 | D17: 1 | E17: 1 | F17: 1 | G17: 1
A18: Average Exchange Rate | B18: 1 | C18: 1 | D18: 1 | E18: 1 | F18: 1 | G18: 1
A20: (€000)
A21: Revenue | B21: 1283860 | C21: 1328122 | D21: 1729911 | E21: 2410927 | F21: 2634331 | G21: 2932724
A22: Total Revenue | B22: 1283860 | C22: 1328122 | D22: 1729911 | E22: 2410927 | F22: 2634331 | G22: 2932724
A23: Cost Of Goods Sold | B23: 645396 | C23: 704553 | D23: 901780 | E23: 1268046 | F23: 1362635 | G23: 1451351
A24: Gross Profit | B24: 638464 | C24: 623569 | D24: 828131 | E24: 1142881 | F24: 1271696 | G24: 1481373
A26: Selling General & Admin Exp. | B26: 148929 | C26: 157424 | D26: 189547 | E26: 276620 | F26: 308727 | G26: 316811
A27: R & D Exp. | B27: 106091 | C27: 128876 | D27: 149230 | E27: 233860 | F27: 306822 | G27: 369370
A28: Amort. of Goodwill and Intangibles | B28: 13788 | C28: 12863 | D28: 12213 | E28: 13642 | F28: 3666 | G28: 378
A29: Other Operating Expense | B29: NA | C29: NA | D29: NA | E29: NA | F29: -254 | G29: -355
A30: Other Operating Exp., Total | B30: 268808 | C30: 299163 | D30: 350990 | E30: 524122 | F30: 618961 | G30: 686204
A31: Operating Income | B31: 369656 | C31: 324406 | D31: 477141 | E31: 618759 | F31: 652735 | G31: 795169
A33: Interest Expense | B33: -1766 | C33: -2008 | D33: -2012 | E33: -1523 | F33: -3945 | G33: -1884
A34: Interest and Invest. Income | B34: 1639 | C34: 141 | D34: 23 | E34: 2246 | F34: 14826 | G34: 21658
A35: Net Interest Exp. | B35: -127 | C35: -1867 | D35: -1989 | E35: 723 | F35: 10881 | G35: 19774
A36: Income from Affiliates | B36: 18035 | C36: 44813 | D36: 86595 | E36: 78413 | F36: 21206 | G36: 10021
A37: Currency Exchange Gains | B37: -146 | C37: -23157 | D37: 33473 | E37: 25011 | F37: -21375 | G37: 45048
A38: EBT Excl Unusual Items | B38: 387418 | C38: 344195 | D38: 595220 | E38: 722906 | F38: 663447 | G38: 870012
A39: Gain (Loss) On Sale Of Invest. | B39: NA | C39: NA | D39: NA | E39: -215389 | F39: 215389 | G39: NA
A40: Gain (Loss) On Sale Of Assets | B40: NA | C40: NA | D40: 4071 | E40: 40 | F40: -185 | G40: 7036
A41: Asset Writedown | B41: -4755 | C41: -10126 | D41: -1967 | E41: -6 | F41: -2475 | G41: -448
A42: Other Unusual Items | B42: NA | C42: NA | D42: NA | E42: -2575 | F42: -9655 | G42: -8698
A43: EBT Incl. Unusual Items | B43: 382663 | C43: 334069 | D43: 597324 | E43: 504976 | F43: 866521 | G43: 867902
A45: Income Tax Expense | B45: 53650 | C45: 48673 | D45: 102615 | E45: 115863 | F45: 114448 | G45: 182168
A46: Earnings from Cont. Ops. | B46: 329013 | C46: 285396 | D46: 494709 | E46: 389113 | F46: 752073 | G46: 685734
A47: Net Income to Company | B47: 329013 | C47: 285396 | D47: 494709 | E47: 389113 | F47: 752073 | G47: 685734
...

Sheet Input ASM (Reported)
A2: ASM International NV | Income Statement (As Reported)
A3: ENXTAM: ASM (MI KEY: 4231951; SPCIQ KEY: 322899)
A5: Source: Recommended
A6: Period Category: Fiscal
A7: Period Type: Years
A8: Sort Order: Latest on Right
A9: Currency: Euro
A12: Recommended: S&P Capital IQ - Standard | B12: 2019 FY | C12: 2020 FY | D12: 2021 FY | E12: 2022 FY | F12: 2023 FY | G12: 2024 FY
A13: Period Ended | B13: 43830 | C13: 44196 | D13: 44561 | E13: 44926 | F13: 45291 | G13: 45657
A14: Currency | B14: EUR | C14: EUR | D14: EUR | E14: EUR | F14: EUR | G14: EUR
A15: Units | B15: Thousands | C15: Thousands | D15: Thousands | E15: Thousands | F15: Thousands | G15: Thousands
A16: Revenues
A17: Revenues | B17: 1283860 | C17: 1328122 | D17: 1729911 | E17: 2410927 | F17: 2634331 | G17: 2932724
A18: Expenses
A19: Cost of Sales | B19: -645396 | C19: -704553 | D19: -901780 | E19: -1268046 | F19: -1362635 | G19: -1451351
A20: Selling, General and Administrative | B20: -148929 | C20: -157424 | D20: -189547 | E20: -276620 | F20: -308727 | G20: -316811
A21: Research and Development | B21: -110846 | C21: -139002 | D21: -151197 | E21: -233866 | F21: -309297 | G21: -369818
A22: Other Income | B22: NA | C22: NA | D22: 4071 | E22: 40 | F22: 69 | G22: 7391
A23: Gain/loss from Sale of Investments | B23: NA | C23: NA | D23: NA | E23: -215389 | F23: 215389 | G23: NA
A24: Currency Translation Gain(Loss) | B24: -146 | C24: -23157 | D24: 33473 | E24: 25011 | F24: -21375 | G24: 45048
A25: Finance Income | B25: 1639 | C25: 141 | D25: 23 | E25: 2246 | F25: 14826 | G25: 21658
A26: Finance Expenses | B26: -1766 | C26: -2008 | D26: -2012 | E26: -4098 | F26: -13600 | G26: -10582
A27: Share in Income of Investments and Associates | B27: 4247 | C27: 31950 | D27: 74382 | E27: 64771 | F27: 17540 | G27: 9643
A28: Earnings before Taxes | B28: 382663 | C28: 334069 | D28: 597324 | E28: 504976 | F28: 866521 | G28: 867902
A29: Taxes and Other Expenses
A30: Provision for Income Tax | B30: -53650 | C30: -48673 | D30: -102615 | E30: -115863 | F30: -114448 | G30: -182168
A31: Net Income (Loss) | B31: 329013 | C31: 285396 | D31: 494709 | E31: 389113 | F31: 752073 | G31: 685734
A32: Supplementary Info
A33: Gross Profit/loss | B33: 638464 | C33: 623569 | D33: 828131 | E33: 1142881 | F33: 1271696 | G33: 1481373
A34: Operating Income (Loss) | B34: 378689 | C34: 327143 | D34: 491458 | E34: 632435 | F34: 653741 | G34: 802135
A35: Basic EPS - Continuing Operations | B35: 6.66 | C35: 5.84 | D35: 10.17 | E35: 7.97 | F35: 15.26 | G35: 13.95
A36: Diluted EPS - Continuing Operations | B36: 6.58 | C36: 5.78 | D36: 10.11 | E36: 7.93 | F36: 15.18 | G36: 13.89
A39: Recommended: S&P Capital IQ - Standard | B39: 2019 FY | C39: 2020 FY | D39: 2021 FY | E39: 2022 FY | F39: 2023 FY | G39: 2024 FY
A40: Period Ended | B40: 43830 | C40: 44196 | D40: 44561 | E40: 44926 | F40: 45291 | G40: 45657
A41: Currency | B41: EUR | C41: EUR | D41: EUR | E41: EUR | F41: EUR | G41: EUR
A42: Units | B42: Thousands | C42: Thousands | D42: Thousands | E42: Thousands | F42: Thousands | G42: Thousands
A43: Operating Activities
A44: Net Income | B44: 329013 | C44: 285396 | D44: 494709 | E44: 389113 | F44: 752073 | G44: 685734
A45: Depreciation, amortization and Impairment | B45: 78321 | C45: 89029 | D45: 95580 | E45: 122434 | F45: 180896 | G45: 195800
A46: Net Gain/loss on Sale of Property, Plant & Equipment | B46: NA | C46: NA | D46: -4071 | E46: -40 | F46: 185 | G46: -7036
...

Sheet Input AIXTRON
A2: AIXTRON SE | Income Statement
A3: XTRA:AIXA (MI KEY: 4434404; SPCIQ KEY: 138633)
A5: Source: Recommended
A6: Period Category: Fiscal
A7: Period Type: Years
A8: Reporting Basis: Current/Restated
A9: Sort Order: Latest on Right
A10: Currency: Euro (EUR)
A11: Magnitude: Thousands (K)
A13: Recommended: S&P Capital IQ - Standard | B13: 2019 FY | C13: 2020 FY | D13: 2021 FY | E13: 2022 FY | F13: 2023 FY | G13: 2024 FY
B14: Current/Restated | C14: Current/Restated | D14: Current/Restated | E14: Current/Restated | F14: Current/Restated | G14: Current/Restated
A15: Period Ended | B15: 43830 | C15: 44196 | D15: 44561 | E15: 44926 | F15: 45291 | G15: 45657
A16: Financial Filing Date | B16: 44252 | C16: 44616 | D16: 44985 | E16: 45351 | F16: 45715 | G16: 45715
A17: Spot Exchange Rate | B17: 1 | C17: 1 | D17: 1 | E17: 1 | F17: 1 | G17: 1
A18: Average Exchange Rate | B18: 1 | C18: 1 | D18: 1 | E18: 1 | F18: 1 | G18: 1
A20: (€000)
A21: Revenue | B21: 259627 | C21: 269247 | D21: 428954 | E21: 463167 | F21: 629879 | G21: 633159
A22: Total Revenue | B22: 259627 | C22: 269247 | D22: 428954 | E22: 463167 | F22: 629879 | G22: 633159
A23: Cost Of Goods Sold | B23: 150882 | C23: 160960 | D23: 247433 | E23: 267896 | F23: 350847 | G23: 370688
A24: Gross Profit | B24: 108745 | C24: 108287 | D24: 181521 | E24: 195271 | F24: 279032 | G24: 262471
A26: Selling General & Admin Exp. | B26: 26400 | C26: 27673 | D26: 34683 | E26: 40439 | F26: 46654 | G26: 46052
A27: R & D Exp. | B27: 54955 | C27: 58379 | D27: 53211 | E27: 57726 | F27: 87681 | G27: 91365
A28: Other Operating Expense | B28: -8951 | C28: -10013 | D28: -9316 | E28: -5857 | F28: -6686 | G28: -6616
A29: Other Operating Exp., Total | B29: 72404 | C29: 76039 | D29: 78578 | E29: 92308 | F29: 127649 | G29: 130801
A30: Operating Income | B30: 36341 | C30: 32248 | D30: 102943 | E30: 102963 | F30: 151383 | G30: 131670
A32: Interest Expense | B32: -143 | C32: -104 | D32: -279 | E32: -356 | F32: -205 | G32: -429
A33: Interest and Invest. Income | B33: 865 | C33: 348 | D33: 232 | E33: 803 | F33: 1119 | G33: 1389
A34: Net Interest Exp. | B34: 722 | C34: 244 | D34: -47 | E34: 447 | F34: 914 | G34: 960
... A36: EBT Excl Unusual Items | B36: 38327 | C36: 31697 | D36: 104056 | E36: 106204 | F36: 153056 | G36: 131290
A37: Restructuring Charges | B37: NA | C37: NA | D37: -3888 | E37: NA | F37: NA | G37: NA
A38: Gain (Loss) On Sale Of Invest. | B38: NA | C38: -16 | D38: -708 | E38: -1047 | F38: 4846 | G38: 1042
A39: Gain (Loss) On Sale Of Assets | B39: -35 | C39: -51 | D39: -83 | E39: -14 | F39: -221 | G39: -139
A40: Asset Writedown | B40: NA | C40: 2909 | D40: -456 | E40: NA | F40: NA | G40: NA
A41: Insurance Settlements | B41: 1427 | C41: 535 | D41: 10 | E41: NA | F41: NA | G41: NA
A42: EBT Incl. Unusual Items | B42: 39719 | C42: 35074 | D42: 98931 | E42: 105143 | F42: 157681 | G42: 132193
A44: Income Tax Expense | B44: 7241 | C44: 604 | D44: 4092 | E44: 4671 | F44: 12492 | G44: 25945
A45: Earnings from Cont. Ops. | B45: 32478 | C45: 34470 | D45: 94839 | E45: 100472 | F45: 145189 | G45: 106248
A46: Net Income to Company | B46: 32478 | C46: 34470 | D46: 94839 | E46: 100472 | F46: 145189 | G46: 106248
A47: Minority Int. in Earnings | B47: 355 | C47: 409 | D47: 821 | E47: -35 | F47: -4 | G47: 35
A48: Net Income | B48: 32833 | C48: 34879 | D48: 95660 | E48: 100437 | F48: 145185 | G48: 106283
...

Sheet Input AMAT
A2: Applied Materials, Inc. | Income Statement
A3: NASDAQGS:AMAT (MI KEY: 4073928; SPCIQ KEY: 251230)
A5: Source: Recommended
A6: Period Category: Fiscal
A7: Period Type: Years
A8: Reporting Basis: Current/Restated
A9: Sort Order: Latest on Right
A10: Currency: Euro (EUR)
A11: Magnitude: Thousands (K)
A13: Recommended: S&P Capital IQ - Standard | B13: 2019 FY | C13: 2020 FY | D13: 2021 FY | E13: 2022 FY | F13: 2023 FY | G13: 2024 FY
B14: Current/Restated | C14: Current/Restated | D14: Current/Restated | E14: Current/Restated | F14: Current/Restated | G14: Current/Restated
A15: Period Ended | B15: 43765 | C15: 44129 | D15: 44500 | E15: 44864 | F15: 45228 | G15: 45592
A16: Financial Filing Date | B16: 44547 | C16: 44911 | D16: 45275 | E16: 45639 | F16: 46003 | G16: 46003
A17: Spot Exchange Rate | B17: 0.9018 | C17: 0.8448 | D17: 0.8648 | E17: 1.0057 | F17: 0.9441 | G17: 0.924
A18: Average Exchange Rate | B18: 0.88938677 | C18: 0.88947617 | D18: 0.83772769 | E18: 0.93702308 | F18: 0.9317722 | G18: 0.91991899
A20: (€000)
A21: Revenue | B21: 12992162 | C21: 15300769 | D21: 19320514 | E21: 24161140 | F21: 24707803 | G21: 24999719
A22: Total Revenue | B22: 12992162 | C22: 15300769 | D22: 19320514 | E22: 24161140 | F22: 24707803 | G22: 24999719
A23: Cost Of Goods Sold | B23: 7312538 | C23: 8438460.4 | D23: 10177554 | E23: 12923422 | F23: 13168737 | G23: 13135523
A24: Gross Profit | B24: 5679623.9 | C24: 6862308.7 | D24: 9142960 | E24: 11237718 | F24: 11539067 | G24: 11864195
A26: Selling General & Admin Exp. | B26: 853811.3 | C26: 901039.36 | D26: 1029567.3 | E26: 1347439.2 | F26: 1516925.1 | G26: 1653094.4
A27: R & D Exp. | B27: 1826800.4 | C27: 1987089.8 | D27: 2081753.3 | E27: 2596490.9 | F27: 2890357.4 | G27: 2974098.1
A28: Other Operating Exp., Total | B28: 2680611.7 | C28: 2888129.1 | D28: 3111320.6 | E28: 3943930.1 | F28: 4407282.5 | G28: 4627192.5
A29: Operating Income | B29: 2999012.2 | C29: 3974179.5 | D29: 6031639.4 | E29: 7293787.6 | F29: 7131784.4 | G29: 7237002.7
A31: Interest Expense | B31: -210784.66 | C31: -213474.28 | D31: -197703.74 | E31: -213641.26 | F31: -221761.78 | G31: -227219.99
A32: Interest and Invest. Income | B32: 106726.41 | C32: 67600.189 | D32: NA | E32: 29984.738 | F32: 254373.81 | G32: 470998.52
A33: Net Interest Exp. | B33: -104058.25 | C33: -145874.09 | D33: -197703.74 | E33: -183656.52 | F33: 32612.027 | G33: 243778.53
A34: Currency Exchange Gains | B34: NA | C34: -8894.7617 | D34: 24294.103 | E34: NA | F34: NA | G34: NA
A35: Other Non-Operating Inc. | B35: NA | C35: -889.47617 | D35: -8377.2769 | E35: NA | F35: NA | G35: NA
A36: EBT Excl Unusual Items | B36: 2894953.9 | C36: 3818521.2 | D36: 5849852.5 | E36: 7110131.1 | F36: 7164396.5 | G36: 7480781.2
A37: Restructuring Charges | B37: NA | C37: NA | D37: -131523.25 | E37: 3748.0923 | F37: NA | G37: NA
A38: Merger & Related Restruct. Charges | B38: -19566.509 | C38: -71158.094 | D38: NA | E38: NA | F38: NA | G38: NA
A39: Gain (Loss) On Sale Of Invest. | B39: 32017.924 | C39: 8005.2855 | D39: 82935.042 | E39: 6559.1615 | F39: 25157.849 | G39: 18398.38
A40: Other Unusual Items | B40: NA | C40: -49810.666 | D40: -129010.06 | E40: NA | F40: NA | G40: NA
A41: EBT Incl. Unusual Items | B41: 2907405.4 | C41: 3705557.7 | D41: 5672254.2 | E41: 7120438.4 | F41: 7189554.3 | G41: 7499179.6
A43: Income Tax Expense | B43: 500724.75 | C43: 486543.47 | D43: 739713.55 | E43: 1006362.8 | F43: 801324.09 | G43: 896921.02
A44: Earnings from Cont. Ops. | B44: 2406680.6 | C44: 3219014.3 | D44: 4932540.7 | E44: 6114075.6 | F44: 6388230.2 | G44: 6602258.6
A45: Net Income to Company | B45: 2406680.6 | C45: 3219014.3 | D45: 4932540.7 | E45: 6114075.6 | F45: 6388230.2 | G45: 6602258.6
A46: Net Income | B46: 2406680.6 | C46: 3219014.3 | D46: 4932540.7 | E46: 6114075.6 | F46: 6388230.2 | G46: 6602258.6
A47: NI to Common Incl Extra Items | B47: 2406680.6 | C47: 3219014.3 | D47: 4932540.7 | E47: 6114075.6 | F47: 6388230.2 | G47: 6602258.6
...

Sheet Input LRCX
A2: Lam Research Corporation | Income Statement
A3: NASDAQGS:LRCX (MI KEY: 4069378; SPCIQ KEY: 30655)
A5: Source: Recommended
A6: Period Category: Fiscal
A7: Period Type: Years
A8: Reporting Basis: Current/Restated
A9: Sort Order: Latest on Right
A10: Currency: Euro (EUR)
A11: Magnitude: Thousands (K)
A13: Recommended: S&P Capital IQ - Standard | B13: 2019 FY | C13: 2020 FY | D13: 2021 FY | E13: 2022 FY | F13: 2023 FY | G13: 2024 FY
B14: Current/Restated | C14: Current/Restated | D14: Current/Restated | E14: Current/Restated | F14: Current/Restated | G14: Current/Restated
A15: Period Ended | B15: 43646 | C15: 44010 | D15: 44374 | E15: 44738 | F15: 45102 | G15: 45473
A16: Financial Filing Date | B16: 44425 | C16: 44797 | D16: 45153 | E16: 45533 | F16: 45880 | G16: 45880
A17: Spot Exchange Rate | B17: 0.8788 | C17: 0.8921 | D17: 0.8373 | E17: 0.948 | F17: 0.9189 | G17: 0.9333
A18: Average Exchange Rate | B18: 0.87664962 | C18: 0.90458538 | D18: 0.83852713 | E18: 0.88731128 | F18: 0.9568543 | G18: 0.92466808
A20: (€000)
A21: Revenue | B21: 8462788.8 | C21: 9086321.4 | D21: 12264424 | E21: 15285746 | F21: 16676550 | G21: 13782535
A22: Total Revenue | B22: 8462788.8 | C22: 9086321.4 | D22: 12264424 | E22: 15285746 | F22: 16676550 | G22: 13782535
A23: Cost Of Goods Sold | B23: 4641947.4 | C23: 4917365 | D23: 6557989.9 | E23: 8301002.9 | F23: 9160372.8 | G23: 7220936.4
A24: Gross Profit | B24: 3820841.4 | C24: 4168956.3 | D24: 5706433.7 | E24: 6984743.2 | F24: 7516177.6 | G24: 6561598.2
A26: Selling General & Admin Exp. | B26: 615764.83 | C26: 617360.53 | D26: 695872.7 | E26: 785924.43 | F26: 796823.29 | G26: 802840.28
A27: R & D Exp. | B27: 1044370.2 | C27: 1132913.6 | D27: 1252263.1 | E27: 1423467.4 | F27: 1652642.4 | G27: 1759129.2
A28: Other Operating Exp., Total | B28: 1660135 | C28: 1750274.1 | D28: 1948135.8 | E28: 2209391.8 | F28: 2449465.7 | G28: 2561969.5
A29: Operating Income | B29: 2160706.4 | C29: 2418682.2 | D29: 3758297.9 | E29: 4775351.4 | F29: 5066711.9 | G29: 3999628.7
A31: Interest Expense | B31: -102798.56 | C31: -160509.63 | D31: -174914.24 | E31: -163938.75 | F31: -178416.97 | G31: -171281.82
A32: Interest and Invest. Income | B32: 86587.559 | C32: 77281.443 | D32: 16508.084 | E32: 13495.117 | F32: 132987.44 | G32: 232959.03
A33: Net Interest Exp. | B33: -16211.005 | C33: -83228.187 | D33: -158406.16 | E33: -150443.63 | F33: -45429.528 | G33: 61677.21
A34: Currency Exchange Gains | B34: 724.11258 | C34: -3000.5097 | D34: -5837.8259 | E34: -641.52606 | F34: -6772.6147 | G34: -4472.6195
... A36: EBT Excl Unusual Items | B36: 2144785.5 | C36: 2329287.5 | D36: 3665037.7 | E36: 4607908.7 | F36: 5003894.4 | G36: 4088682.5
A37: Restructuring Charges | B37: NA | C37: NA | D37: NA | E37: NA | F37: -115124.88 | G37: -56924.416
A38: EBT Incl. Unusual Items | B38: 2144785.5 | C38: 2329287.5 | D38: 3665037.7 | E38: 4607908.7 | F38: 4888769.5 | G38: 4031758.1
A40: Income Tax Expense | B40: 223669.26 | C40: 292384.61 | D40: 387689.67 | E40: 521586.42 | F40: 572465.83 | G40: 492339.52
A41: Earnings from Cont. Ops. | B41: 1921116.3 | C41: 2036902.9 | D41: 3277348.1 | E41: 4086322.2 | F41: 4316303.7 | G41: 3539418.6
A42: Net Income to Company | B42: 1921116.3 | C42: 2036902.9 | D42: 3277348.1 | E42: 4086322.2 | F42: 4316303.7 | G42: 3539418.6
A43: Net Income | B43: 1921116.3 | C43: 2036902.9 | D43: 3277348.1 | E43: 4086322.2 | F43: 4316303.7 | G43: 3539418.6
A44: NI to Common Incl Extra Items | B44: 1921116.3 | C44: 2036902.9 | D44: 3277348.1 | E44: 4086322.2 | F44: 4316303.7 | G44: 3539418.6
A45: NI to Common Excl. Extra Items | B45: 1921116.3 | C45: 2036902.9 | D45: 3277348.1 | E45: 4086322.2 | F45: 4316303.7 | G45: 3539418.6
A46: Per Share Items (€)
A47: Basic EPS | B47: 1.2597455 | C47: 1.4066303 | D47: 2.2824709 | E47: 2.9210287 | F47: 3.1863248 | G47: 2.6935581
A48: Basic EPS Excl. Extra Items | B48: 1.2597455 | C48: 1.4066303 | D48: 2.2824709 | E48: 2.9210287 | F48: 3.1863248 | G48: 2.6935581
...

Sheet Std ASM
A1: Standardized Financial Statements - ASM International NV
A2: (EUR 000)
B3: 2019 | C3: 2020 | D3: 2021 | E3: 2022 | F3: 2023 | G3: 2024
A5: Operating cash % | B5: 0.02 | C5: 0.02 | D5: 0.02 | E5: 0.02 | F5: 0.02 | G5: 0.02
A6: Tax rate (effective) | B6: =IF(ISNUMBER('Input ASM'!B68),'Input ASM'!B68,0) | C6: =IF(ISNUMBER('Input ASM'!C68),'Input ASM'!C68,0) | D6: =IF(ISNUMBER('Input ASM'!D68),'Input ASM'!D68,0) | E6: =IF(ISNUMBER('Input ASM'!E68),'Input ASM'!E68,0) | F6: =IF(ISNUMBER('Input ASM'!F68),'Input ASM'!F68,0) | G6: =IF(ISNUMBER('Input ASM'!G68),'Input ASM'!G68,0)
A8: INCOME STATEMENT
A9: Revenue | B9: =IF(ISNUMBER('Input ASM'!B21),'Input ASM'!B21,0) | C9: =IF(ISNUMBER('Input ASM'!C21),'Input ASM'!C21,0) | D9: =IF(ISNUMBER('Input ASM'!D21),'Input ASM'!D21,0) | E9: =IF(ISNUMBER('Input ASM'!E21),'Input ASM'!E21,0) | F9: =IF(ISNUMBER('Input ASM'!F21),'Input ASM'!F21,0) | G9: =IF(ISNUMBER('Input ASM'!G21),'Input ASM'!G21,0)
A10: Cost of Sales | B10: =IF(ISNUMBER('Input ASM'!B23),'Input ASM'!B23,0) | C10: =IF(ISNUMBER('Input ASM'!C23),'Input ASM'!C23,0) | D10: =IF(ISNUMBER('Input ASM'!D23),'Input ASM'!D23,0) | E10: =IF(ISNUMBER('Input ASM'!E23),'Input ASM'!E23,0) | F10: =IF(ISNUMBER('Input ASM'!F23),'Input ASM'!F23,0) | G10: =IF(ISNUMBER('Input ASM'!G23),'Input ASM'!G23,0)
A11: Gross Profit | B11: =B9-B10 | C11: =C9-C10 | D11: =D9-D10 | E11: =E9-E10 | F11: =F9-F10 | G11: =G9-G10
A12: SG&A | B12: =IF(ISNUMBER('Input ASM'!B26),'Input ASM'!B26,0) | C12: =IF(ISNUMBER('Input ASM'!C26),'Input ASM'!C26,0) | D12: =IF(ISNUMBER('Input ASM'!D26),'Input ASM'!D26,0) | E12: =IF(ISNUMBER('Input ASM'!E26),'Input ASM'!E26,0) | F12: =IF(ISNUMBER('Input ASM'!F26),'Input ASM'!F26,0) | G12: =IF(ISNUMBER('Input ASM'!G26),'Input ASM'!G26,0)
A13: R&D | B13: =IF(ISNUMBER('Input ASM'!B27),'Input ASM'!B27,0) | C13: =IF(ISNUMBER('Input ASM'!C27),'Input ASM'!C27,0) | D13: =IF(ISNUMBER('Input ASM'!D27),'Input ASM'!D27,0) | E13: =IF(ISNUMBER('Input ASM'!E27),'Input ASM'!E27,0) | F13: =IF(ISNUMBER('Input ASM'!F27),'Input ASM'!F27,0) | G13: =IF(ISNUMBER('Input ASM'!G27),'Input ASM'!G27,0)
A14: Depreciation & Amortization | B14: =IF(ISNUMBER('Input ASM'!B113),'Input ASM'!B113,0) | C14: =IF(ISNUMBER('Input ASM'!C113),'Input ASM'!C113,0) | D14: =IF(ISNUMBER('Input ASM'!D113),'Input ASM'!D113,0) | E14: =IF(ISNUMBER('Input ASM'!E113),'Input ASM'!E113,0) | F14: =IF(ISNUMBER('Input ASM'!F113),'Input ASM'!F113,0) | G14: =IF(ISNUMBER('Input ASM'!G113),'Input ASM'!G113,0)
A15: Other Operating Expense | B15: =IF(ISNUMBER('Input ASM'!B29),'Input ASM'!B29,0) | C15: =IF(ISNUMBER('Input ASM'!C29),'Input ASM'!C29,0) | D15: =IF(ISNUMBER('Input ASM'!D29),'Input ASM'!D29,0) | E15: =IF(ISNUMBER('Input ASM'!E29),'Input ASM'!E29,0) | F15: =IF(ISNUMBER('Input ASM'!F29),'Input ASM'!F29,0) | G15: =IF(ISNUMBER('Input ASM'!G29),'Input ASM'!G29,0)
A16: Total Operating Expense | B16: =B10+B12+B13+B14+B15 | C16: =C10+C12+C13+C14+C15 | D16: =D10+D12+D13+D14+D15 | E16: =E10+E12+E13+E14+E15 | F16: =F10+F12+F13+F14+F15 | G16: =G10+G12+G13+G14+G15
A17: Recurring Operating Profit | B17: =B9-B16 | C17: =C9-C16 | D17: =D9-D16 | E17: =E9-E16 | F17: =F9-F16 | G17: =G9-G16
A19: Non-recurring items:
A20: Gain/Loss on Sale of Investments | B20: =IF(ISNUMBER('Input ASM'!B39),'Input ASM'!B39,0) | C20: =IF(ISNUMBER('Input ASM'!C39),'Input ASM'!C39,0) | D20: =IF(ISNUMBER('Input ASM'!D39),'Input ASM'!D39,0) | E20: =IF(ISNUMBER('Input ASM'!E39),'Input ASM'!E39,0) | F20: =IF(ISNUMBER('Input ASM'!F39),'Input ASM'!F39,0) | G20: =IF(ISNUMBER('Input ASM'!G39),'Input ASM'!G39,0)
A21: Gain/Loss on Sale of Assets | B21: =IF(ISNUMBER('Input ASM'!B40),'Input ASM'!B40,0) | C21: =IF(ISNUMBER('Input ASM'!C40),'Input ASM'!C40,0) | D21: =IF(ISNUMBER('Input ASM'!D40),'Input ASM'!D40,0) | E21: =IF(ISNUMBER('Input ASM'!E40),'Input ASM'!E40,0) | F21: =IF(ISNUMBER('Input ASM'!F40),'Input ASM'!F40,0) | G21: =IF(ISNUMBER('Input ASM'!G40),'Input ASM'!G40,0)
A22: Asset Writedown | B22: =IF(ISNUMBER('Input ASM'!B41),'Input ASM'!B41,0) | C22: =IF(ISNUMBER('Input ASM'!C41),'Input ASM'!C41,0) | D22: =IF(ISNUMBER('Input ASM'!D41),'Input ASM'!D41,0) | E22: =IF(ISNUMBER('Input ASM'!E41),'Input ASM'!E41,0) | F22: =IF(ISNUMBER('Input ASM'!F41),'Input ASM'!F41,0) | G22: =IF(ISNUMBER('Input ASM'!G41),'Input ASM'!G41,0)
A23: Other Unusual Items | B23: =IF(ISNUMBER('Input ASM'!B42),'Input ASM'!B42,0) | C23: =IF(ISNUMBER('Input ASM'!C42),'Input ASM'!C42,0) | D23: =IF(ISNUMBER('Input ASM'!D42),'Input ASM'!D42,0) | E23: =IF(ISNUMBER('Input ASM'!E42),'Input ASM'!E42,0) | F23: =IF(ISNUMBER('Input ASM'!F42),'Input ASM'!F42,0) | G23: =IF(ISNUMBER('Input ASM'!G42),'Input ASM'!G42,0)
A24: Total Non-recurring | B24: =SUM(B20:B23) | C24: =SUM(C20:C23) | D24: =SUM(D20:D23) | E24: =SUM(E20:E23) | F24: =SUM(F20:F23) | G24: =SUM(G20:G23)
A25: EBIT | B25: =B17+B24 | C25: =C17+C24 | D25: =D17+D24 | E25: =E17+E24 | F25: =F17+F24 | G25: =G17+G24
A27: Investment Income (Equity Method) | B27: =IF(ISNUMBER('Input ASM'!B36),'Input ASM'!B36,0) | C27: =IF(ISNUMBER('Input ASM'!C36),'Input ASM'!C36,0) | D27: =IF(ISNUMBER('Input ASM'!D36),'Input ASM'!D36,0) | E27: =IF(ISNUMBER('Input ASM'!E36),'Input ASM'!E36,0) | F27: =IF(ISNUMBER('Input ASM'!F36),'Input ASM'!F36,0) | G27: =IF(ISNUMBER('Input ASM'!G36),'Input ASM'!G36,0)
A28: Interest Income | B28: =IF(ISNUMBER('Input ASM'!B34),'Input ASM'!B34,0) | C28: =IF(ISNUMBER('Input ASM'!C34),'Input ASM'!C34,0) | D28: =IF(ISNUMBER('Input ASM'!D34),'Input ASM'!D34,0) | E28: =IF(ISNUMBER('Input ASM'!E34),'Input ASM'!E34,0) | F28: =IF(ISNUMBER('Input ASM'!F34),'Input ASM'!F34,0) | G28: =IF(ISNUMBER('Input ASM'!G34),'Input ASM'!G34,0)
A29: Interest Expense | B29: =IF(ISNUMBER('Input ASM'!B33),'Input ASM'!B33,0) | C29: =IF(ISNUMBER('Input ASM'!C33),'Input ASM'!C33,0) | D29: =IF(ISNUMBER('Input ASM'!D33),'Input ASM'!D33,0) | E29: =IF(ISNUMBER('Input ASM'!E33),'Input ASM'!E33,0) | F29: =IF(ISNUMBER('Input ASM'!F33),'Input ASM'!F33,0) | G29: =IF(ISNUMBER('Input ASM'!G33),'Input ASM'!G33,0)
A30: FX Gains/(Losses) | B30: =IF(ISNUMBER('Input ASM'!B37),'Input ASM'!B37,0) | C30: =IF(ISNUMBER('Input ASM'!C37),'Input ASM'!C37,0) | D30: =IF(ISNUMBER('Input ASM'!D37),'Input ASM'!D37,0) | E30: =IF(ISNUMBER('Input ASM'!E37),'Input ASM'!E37,0) | F30: =IF(ISNUMBER('Input ASM'!F37),'Input ASM'!F37,0) | G30: =IF(ISNUMBER('Input ASM'!G37),'Input ASM'!G37,0)
A31: Profit Before Tax | B31: =B25+B27+B28+B29+B30 | C31: =C25+C27+C28+C29+C30 | D31: =D25+D27+D28+D29+D30 | E31: =E25+E27+E28+E29+E30 | F31: =F25+F27+F28+F29+F30 | G31: =G25+G27+G28+G29+G30
A32: Tax Expense | B32: =IF(ISNUMBER('Input ASM'!B45),'Input ASM'!B45,0) | C32: =IF(ISNUMBER('Input ASM'!C45),'Input ASM'!C45,0) | D32: =IF(ISNUMBER('Input ASM'!D45),'Input ASM'!D45,0) | E32: =IF(ISNUMBER('Input ASM'!E45),'Input ASM'!E45,0) | F32: =IF(ISNUMBER('Input ASM'!F45),'Input ASM'!F45,0) | G32: =IF(ISNUMBER('Input ASM'!G45),'Input ASM'!G45,0)
A33: Net Income | B33: =B31-B32 | C33: =C31-C32 | D33: =D31-D32 | E33: =E31-E32 | F33: =F31-F32 | G33: =G31-G32
A35: Effective Tax Rate | B35: =IF(B31<>0,B32/B31,0) | C35: =IF(C31<>0,C32/C31,0) | D35: =IF(D31<>0,D32/D31,0) | E35: =IF(E31<>0,E32/E31,0) | F35: =IF(F31<>0,F32/F31,0) | G35: =IF(G31<>0,G32/G31,0)
A36: NOPAT | B36: =B17*(1-B35) | C36: =C17*(1-C35) | D36: =D17*(1-D35) | E36: =E17*(1-E35) | F36: =F17*(1-F35) | G36: =G17*(1-G35)
A38: Shares Outstanding (diluted) | B38: =IF(ISNUMBER('Input ASM'!B57),'Input ASM'!B57,0) | C38: =IF(ISNUMBER('Input ASM'!C57),'Input ASM'!C57,0) | D38: =IF(ISNUMBER('Input ASM'!D57),'Input ASM'!D57,0) | E38: =IF(ISNUMBER('Input ASM'!E57),'Input ASM'!E57,0) | F38: =IF(ISNUMBER('Input ASM'!F57),'Input ASM'!F57,0) | G38: =IF(ISNUMBER('Input ASM'!G57),'Input ASM'!G57,0)
A39: EPS (diluted) | B39: =IF(B38<>0,B33/B38*1000,0) | C39: =IF(C38<>0,C33/C38*1000,0) | D39: =IF(D38<>0,D33/D38*1000,0) | E39: =IF(E38<>0,E33/E38*1000,0) | F39: =IF(F38<>0,F33/F38*1000,0) | G39: =IF(G38<>0,G33/G38*1000,0)
A40: Dividends per Share | B40: =IF(ISNUMBER('Input ASM'!B60),'Input ASM'!B60,0) | C40: =IF(ISNUMBER('Input ASM'!C60),'Input ASM'!C60,0) | D40: =IF(ISNUMBER('Input ASM'!D60),'Input ASM'!D60,0) | E40: =IF(ISNUMBER('Input ASM'!E60),'Input ASM'!E60,0) | F40: =IF(ISNUMBER('Input ASM'!F60),'Input ASM'!F60,0) | G40: =IF(ISNUMBER('Input ASM'!G60),'Input ASM'!G60,0)
A43: BALANCE SHEET (Reformulated)
A44: Operating Working Capital:
A45: Trade Receivables | B45: =IF(ISNUMBER('Input ASM'!B167),'Input ASM'!B167,0) | C45: =IF(ISNUMBER('Input ASM'!C167),'Input ASM'!C167,0) | D45: =IF(ISNUMBER('Input ASM'!D167),'Input ASM'!D167,0) | E45: =IF(ISNUMBER('Input ASM'!E167),'Input ASM'!E167,0) | F45: =IF(ISNUMBER('Input ASM'!F167),'Input ASM'!F167,0) | G45: =IF(ISNUMBER('Input ASM'!G167),'Input ASM'!G167,0)
A46: + Other Receivables | B46: =IF(ISNUMBER('Input ASM'!B168),'Input ASM'!B168,0) | C46: =IF(ISNUMBER('Input ASM'!C168),'Input ASM'!C168,0) | D46: =IF(ISNUMBER('Input ASM'!D168),'Input ASM'!D168,0) | E46: =IF(ISNUMBER('Input ASM'!E168),'Input ASM'!E168,0) | F46: =IF(ISNUMBER('Input ASM'!F168),'Input ASM'!F168,0) | G46: =IF(ISNUMBER('Input ASM'!G168),'Input ASM'!G168,0)
A47: + Inventories | B47: =IF(ISNUMBER('Input ASM'!B170),'Input ASM'!B170,0) | C47: =IF(ISNUMBER('Input ASM'!C170),'Input ASM'!C170,0) | D47: =IF(ISNUMBER('Input ASM'!D170),'Input ASM'!D170,0) | E47: =IF(ISNUMBER('Input ASM'!E170),'Input ASM'!E170,0) | F47: =IF(ISNUMBER('Input ASM'!F170),'Input ASM'!F170,0) | G47: =IF(ISNUMBER('Input ASM'!G170),'Input ASM'!G170,0)
A48: + Prepaid & Other CA | B48: =IF(ISNUMBER('Input ASM'!B171),'Input ASM'!B171,0)+IF(ISNUMBER('Input ASM'!B172),'Input ASM'!B172,0) | C48: =IF(ISNUMBER('Input ASM'!C171),'Input ASM'!C171,0)+IF(ISNUMBER('Input ASM'!C172),'Input ASM'!C172,0) | D48: =IF(ISNUMBER('Input ASM'!D171),'Input ASM'!D171,0)+IF(ISNUMBER('Input ASM'!D172),'Input ASM'!D172,0) | E48: =IF(ISNUMBER('Input ASM'!E171),'Input ASM'!E171,0)+IF(ISNUMBER('Input ASM'!E172),'Input ASM'!E172,0) | F48: =IF(ISNUMBER('Input ASM'!F171),'Input ASM'!F171,0)+IF(ISNUMBER('Input ASM'!F172),'Input ASM'!F172,0) | G48: =IF(ISNUMBER('Input ASM'!G171),'Input ASM'!G171,0)+IF(ISNUMBER('Input ASM'!G172),'Input ASM'!G172,0)
...

Sheet Std AIXTRON
A1: Standardized Financial Statements - AIXTRON SE
A2: (EUR 000)
B3: 2019 | C3: 2020 | D3: 2021 | E3: 2022 | F3: 2023 | G3: 2024
A5: Operating cash % | B5: 0.02 | C5: 0.02 | D5: 0.02 | E5: 0.02 | F5: 0.02 | G5: 0.02
A6: Tax rate (effective) | B6: =IF(ISNUMBER('Input AIXTRON'!B68),'Input AIXTRON'!B68,0) | C6: =IF(ISNUMBER('Input AIXTRON'!C68),'Input AIXTRON'!C68,0) | D6: =IF(ISNUMBER('Input AIXTRON'!D68),'Input AIXTRON'!D68,0) | E6: =IF(ISNUMBER('Input AIXTRON'!E68),'Input AIXTRON'!E68,0) | F6: =IF(ISNUMBER('Input AIXTRON'!F68),'Input AIXTRON'!F68,0) | G6: =IF(ISNUMBER('Input AIXTRON'!G68),'Input AIXTRON'!G68,0)
A8: INCOME STATEMENT
A9: Revenue | B9: =IF(ISNUMBER('Input AIXTRON'!B21),'Input AIXTRON'!B21,0) | C9: =IF(ISNUMBER('Input AIXTRON'!C21),'Input AIXTRON'!C21,0) | D9: =IF(ISNUMBER('Input AIXTRON'!D21),'Input AIXTRON'!D21,0) | E9: =IF(ISNUMBER('Input AIXTRON'!E21),'Input AIXTRON'!E21,0) | F9: =IF(ISNUMBER('Input AIXTRON'!F21),'Input AIXTRON'!F21,0) | G9: =IF(ISNUMBER('Input AIXTRON'!G21),'Input AIXTRON'!G21,0)
A10: Cost of Sales | B10: =IF(ISNUMBER('Input AIXTRON'!B23),'Input AIXTRON'!B23,0) | C10: =IF(ISNUMBER('Input AIXTRON'!C23),'Input AIXTRON'!C23,0) | D10: =IF(ISNUMBER('Input AIXTRON'!D23),'Input AIXTRON'!D23,0) | E10: =IF(ISNUMBER('Input AIXTRON'!E23),'Input AIXTRON'!E23,0) | F10: =IF(ISNUMBER('Input AIXTRON'!F23),'Input AIXTRON'!F23,0) | G10: =IF(ISNUMBER('Input AIXTRON'!G23),'Input AIXTRON'!G23,0)
A11: Gross Profit | B11: =B9-B10 | C11: =C9-C10 | D11: =D9-D10 | E11: =E9-E10 | F11: =F9-F10 | G11: =G9-G10
A12: SG&A | B12: =IF(ISNUMBER('Input AIXTRON'!B26),'Input AIXTRON'!B26,0) | C12: =IF(ISNUMBER('Input AIXTRON'!C26),'Input AIXTRON'!C26,0) | D12: =IF(ISNUMBER('Input AIXTRON'!D26),'Input AIXTRON'!D26,0) | E12: =IF(ISNUMBER('Input AIXTRON'!E26),'Input AIXTRON'!E26,0) | F12: =IF(ISNUMBER('Input AIXTRON'!F26),'Input AIXTRON'!F26,0) | G12: =IF(ISNUMBER('Input AIXTRON'!G26),'Input AIXTRON'!G26,0)
A13: R&D | B13: =IF(ISNUMBER('Input AIXTRON'!B27),'Input AIXTRON'!B27,0) | C13: =IF(ISNUMBER('Input AIXTRON'!C27),'Input AIXTRON'!C27,0) | D13: =IF(ISNUMBER('Input AIXTRON'!D27),'Input AIXTRON'!D27,0) | E13: =IF(ISNUMBER('Input AIXTRON'!E27),'Input AIXTRON'!E27,0) | F13: =IF(ISNUMBER('Input AIXTRON'!F27),'Input AIXTRON'!F27,0) | G13: =IF(ISNUMBER('Input AIXTRON'!G27),'Input AIXTRON'!G27,0)
A14: Depreciation & Amortization | B14: =IF(ISNUMBER('Input AIXTRON'!B111),'Input AIXTRON'!B111,0) | C14: =IF(ISNUMBER('Input AIXTRON'!C111),'Input AIXTRON'!C111,0) | D14: =IF(ISNUMBER('Input AIXTRON'!D111),'Input AIXTRON'!D111,0) | E14: =IF(ISNUMBER('Input AIXTRON'!E111),'Input AIXTRON'!E111,0) | F14: =IF(ISNUMBER('Input AIXTRON'!F111),'Input AIXTRON'!F111,0) | G14: =IF(ISNUMBER('Input AIXTRON'!G111),'Input AIXTRON'!G111,0)
A15: Other Operating Expense | B15: =IF(ISNUMBER('Input AIXTRON'!B28),'Input AIXTRON'!B28,0) | C15: =IF(ISNUMBER('Input AIXTRON'!C28),'Input AIXTRON'!C28,0) | D15: =IF(ISNUMBER('Input AIXTRON'!D28),'Input AIXTRON'!D28,0) | E15: =IF(ISNUMBER('Input AIXTRON'!E28),'Input AIXTRON'!E28,0) | F15: =IF(ISNUMBER('Input AIXTRON'!F28),'Input AIXTRON'!F28,0) | G15: =IF(ISNUMBER('Input AIXTRON'!G28),'Input AIXTRON'!G28,0)
A16: Total Operating Expense | B16: =B10+B12+B13+B14+B15 | C16: =C10+C12+C13+C14+C15 | D16: =D10+D12+D13+D14+D15 | E16: =E10+E12+E13+E14+E15 | F16: =F10+F12+F13+F14+F15 | G16: =G10+G12+G13+G14+G15
A17: Recurring Operating Profit | B17: =B9-B16 | C17: =C9-C16 | D17: =D9-D16 | E17: =E9-E16 | F17: =F9-F16 | G17: =G9-G16
A19: Non-recurring items:
A20: Gain/Loss on Sale of Investments | B20: =IF(ISNUMBER('Input AIXTRON'!B38),'Input AIXTRON'!B38,0) | C20: =IF(ISNUMBER('Input AIXTRON'!C38),'Input AIXTRON'!C38,0) | D20: =IF(ISNUMBER('Input AIXTRON'!D38),'Input AIXTRON'!D38,0) | E20: =IF(ISNUMBER('Input AIXTRON'!E38),'Input AIXTRON'!E38,0) | F20: =IF(ISNUMBER('Input AIXTRON'!F38),'Input AIXTRON'!F38,0) | G20: =IF(ISNUMBER('Input AIXTRON'!G38),'Input AIXTRON'!G38,0)
A21: Gain/Loss on Sale of Assets | B21: =IF(ISNUMBER('Input AIXTRON'!B39),'Input AIXTRON'!B39,0) | C21: =IF(ISNUMBER('Input AIXTRON'!C39),'Input AIXTRON'!C39,0) | D21: =IF(ISNUMBER('Input AIXTRON'!D39),'Input AIXTRON'!D39,0) | E21: =IF(ISNUMBER('Input AIXTRON'!E39),'Input AIXTRON'!E39,0) | F21: =IF(ISNUMBER('Input AIXTRON'!F39),'Input AIXTRON'!F39,0) | G21: =IF(ISNUMBER('Input AIXTRON'!G39),'Input AIXTRON'!G39,0)
A22: Asset Writedown | B22: =IF(ISNUMBER('Input AIXTRON'!B40),'Input AIXTRON'!B40,0) | C22: =IF(ISNUMBER('Input AIXTRON'!C40),'Input AIXTRON'!C40,0) | D22: =IF(ISNUMBER('Input AIXTRON'!D40),'Input AIXTRON'!D40,0) | E22: =IF(ISNUMBER('Input AIXTRON'!E40),'Input AIXTRON'!E40,0) | F22: =IF(ISNUMBER('Input AIXTRON'!F40),'Input AIXTRON'!F40,0) | G22: =IF(ISNUMBER('Input AIXTRON'!G40),'Input AIXTRON'!G40,0)
A23: Other Unusual Items | B23: =IF(ISNUMBER('Input AIXTRON'!B37),'Input AIXTRON'!B37,0)+IF(ISNUMBER('Input AIXTRON'!B41),'Input AIXTRON'!B41,0) | C23: =IF(ISNUMBER('Input AIXTRON'!C37),'Input AIXTRON'!C37,0)+IF(ISNUMBER('Input AIXTRON'!C41),'Input AIXTRON'!C41,0) | D23: =IF(ISNUMBER('Input AIXTRON'!D37),'Input AIXTRON'!D37,0)+IF(ISNUMBER('Input AIXTRON'!D41),'Input AIXTRON'!D41,0) | E23: =IF(ISNUMBER('Input AIXTRON'!E37),'Input AIXTRON'!E37,0)+IF(ISNUMBER('Input AIXTRON'!E41),'Input AIXTRON'!E41,0) | F23: =IF(ISNUMBER('Input AIXTRON'!F37),'Input AIXTRON'!F37,0)+IF(ISNUMBER('Input AIXTRON'!F41),'Input AIXTRON'!F41,0) | G23: =IF(ISNUMBER('Input AIXTRON'!G37),'Input AIXTRON'!G37,0)+IF(ISNUMBER('Input AIXTRON'!G41),'Input AIXTRON'!G41,0)
A24: Total Non-recurring | B24: =SUM(B20:B23) | C24: =SUM(C20:C23) | D24: =SUM(D20:D23) | E24: =SUM(E20:E23) | F24: =SUM(F20:F23) | G24: =SUM(G20:G23)
A25: EBIT | B25: =B17+B24 | C25: =C17+C24 | D25: =D17+D24 | E25: =E17+E24 | F25: =F17+F24 | G25: =G17+G24
A27: Investment Income (Equity Method) | B27: 0 | C27: 0 | D27: 0 | E27: 0 | F27: 0 | G27: 0
A28: Interest Income | B28: =IF(ISNUMBER('Input AIXTRON'!B33),'Input AIXTRON'!B33,0) | C28: =IF(ISNUMBER('Input AIXTRON'!C33),'Input AIXTRON'!C33,0) | D28: =IF(ISNUMBER('Input AIXTRON'!D33),'Input AIXTRON'!D33,0) | E28: =IF(ISNUMBER('Input AIXTRON'!E33),'Input AIXTRON'!E33,0) | F28: =IF(ISNUMBER('Input AIXTRON'!F33),'Input AIXTRON'!F33,0) | G28: =IF(ISNUMBER('Input AIXTRON'!G33),'Input AIXTRON'!G33,0)
A29: Interest Expense | B29: =IF(ISNUMBER('Input AIXTRON'!B32),'Input AIXTRON'!B32,0) | C29: =IF(ISNUMBER('Input AIXTRON'!C32),'Input AIXTRON'!C32,0) | D29: =IF(ISNUMBER('Input AIXTRON'!D32),'Input AIXTRON'!D32,0) | E29: =IF(ISNUMBER('Input AIXTRON'!E32),'Input AIXTRON'!E32,0) | F29: =IF(ISNUMBER('Input AIXTRON'!F32),'Input AIXTRON'!F32,0) | G29: =IF(ISNUMBER('Input AIXTRON'!G32),'Input AIXTRON'!G32,0)
A30: FX Gains/(Losses) | B30: =IF(ISNUMBER('Input AIXTRON'!B35),'Input AIXTRON'!B35,0) | C30: =IF(ISNUMBER('Input AIXTRON'!C35),'Input AIXTRON'!C35,0) | D30: =IF(ISNUMBER('Input AIXTRON'!D35),'Input AIXTRON'!D35,0) | E30: =IF(ISNUMBER('Input AIXTRON'!E35),'Input AIXTRON'!E35,0) | F30: =IF(ISNUMBER('Input AIXTRON'!F35),'Input AIXTRON'!F35,0) | G30: =IF(ISNUMBER('Input AIXTRON'!G35),'Input AIXTRON'!G35,0)
A31: Profit Before Tax | B31: =B25+B27+B28+B29+B30 | C31: =C25+C27+C28+C29+C30 | D31: =D25+D27+D28+D29+D30 | E31: =E25+E27+E28+E29+E30 | F31: =F25+F27+F28+F29+F30 | G31: =G25+G27+G28+G29+G30
A32: Tax Expense | B32: =IF(ISNUMBER('Input AIXTRON'!B44),'Input AIXTRON'!B44,0) | C32: =IF(ISNUMBER('Input AIXTRON'!C44),'Input AIXTRON'!C44,0) | D32: =IF(ISNUMBER('Input AIXTRON'!D44),'Input AIXTRON'!D44,0) | E32: =IF(ISNUMBER('Input AIXTRON'!E44),'Input AIXTRON'!E44,0) | F32: =IF(ISNUMBER('Input AIXTRON'!F44),'Input AIXTRON'!F44,0) | G32: =IF(ISNUMBER('Input AIXTRON'!G44),'Input AIXTRON'!G44,0)
A33: Net Income | B33: =B31-B32 | C33: =C31-C32 | D33: =D31-D32 | E33: =E31-E32 | F33: =F31-F32 | G33: =G31-G32
A35: Effective Tax Rate | B35: =IF(B31<>0,B32/B31,0) | C35: =IF(C31<>0,C32/C31,0) | D35: =IF(D31<>0,D32/D31,0) | E35: =IF(E31<>0,E32/E31,0) | F35: =IF(F31<>0,F32/F31,0) | G35: =IF(G31<>0,G32/G31,0)
A36: NOPAT | B36: =B17*(1-B35) | C36: =C17*(1-C35) | D36: =D17*(1-D35) | E36: =E17*(1-E35) | F36: =F17*(1-F35) | G36: =G17*(1-G35)
A38: Shares Outstanding (diluted) | B38: =IF(ISNUMBER('Input AIXTRON'!B57),'Input AIXTRON'!B57,0) | C38: =IF(ISNUMBER('Input AIXTRON'!C57),'Input AIXTRON'!C57,0) | D38: =IF(ISNUMBER('Input AIXTRON'!D57),'Input AIXTRON'!D57,0) | E38: =IF(ISNUMBER('Input AIXTRON'!E57),'Input AIXTRON'!E57,0) | F38: =IF(ISNUMBER('Input AIXTRON'!F57),'Input AIXTRON'!F57,0) | G38: =IF(ISNUMBER('Input AIXTRON'!G57),'Input AIXTRON'!G57,0)
A39: EPS (diluted) | B39: =IF(B38<>0,B33/B38*1000,0) | C39: =IF(C38<>0,C33/C38*1000,0) | D39: =IF(D38<>0,D33/D38*1000,0) | E39: =IF(E38<>0,E33/E38*1000,0) | F39: =IF(F38<>0,F33/F38*1000,0) | G39: =IF(G38<>0,G33/G38*1000,0)
A40: Dividends per Share | B40: =IF(ISNUMBER('Input AIXTRON'!B60),'Input AIXTRON'!B60,0) | C40: =IF(ISNUMBER('Input AIXTRON'!C60),'Input AIXTRON'!C60,0) | D40: =IF(ISNUMBER('Input AIXTRON'!D60),'Input AIXTRON'!D60,0) | E40: =IF(ISNUMBER('Input AIXTRON'!E60),'Input AIXTRON'!E60,0) | F40: =IF(ISNUMBER('Input AIXTRON'!F60),'Input AIXTRON'!F60,0) | G40: =IF(ISNUMBER('Input AIXTRON'!G60),'Input AIXTRON'!G60,0)
A43: BALANCE SHEET (Reformulated)
A44: Operating Working Capital:
A45: Trade Receivables | B45: =IF(ISNUMBER('Input AIXTRON'!B167),'Input AIXTRON'!B167,0) | C45: =IF(ISNUMBER('Input AIXTRON'!C167),'Input AIXTRON'!C167,0) | D45: =IF(ISNUMBER('Input AIXTRON'!D167),'Input AIXTRON'!D167,0) | E45: =IF(ISNUMBER('Input AIXTRON'!E167),'Input AIXTRON'!E167,0) | F45: =IF(ISNUMBER('Input AIXTRON'!F167),'Input AIXTRON'!F167,0) | G45: =IF(ISNUMBER('Input AIXTRON'!G167),'Input AIXTRON'!G167,0)
A46: + Other Receivables | B46: =IF(ISNUMBER('Input AIXTRON'!B168),'Input AIXTRON'!B168,0) | C46: =IF(ISNUMBER('Input AIXTRON'!C168),'Input AIXTRON'!C168,0) | D46: =IF(ISNUMBER('Input AIXTRON'!D168),'Input AIXTRON'!D168,0) | E46: =IF(ISNUMBER('Input AIXTRON'!E168),'Input AIXTRON'!E168,0) | F46: =IF(ISNUMBER('Input AIXTRON'!F168),'Input AIXTRON'!F168,0) | G46: =IF(ISNUMBER('Input AIXTRON'!G168),'Input AIXTRON'!G168,0)
A47: + Inventories | B47: =IF(ISNUMBER('Input AIXTRON'!B170),'Input AIXTRON'!B170,0) | C47: =IF(ISNUMBER('Input AIXTRON'!C170),'Input AIXTRON'!C170,0) | D47: =IF(ISNUMBER('Input AIXTRON'!D170),'Input AIXTRON'!D170,0) | E47: =IF(ISNUMBER('Input AIXTRON'!E170),'Input AIXTRON'!E170,0) | F47: =IF(ISNUMBER('Input AIXTRON'!F170),'Input AIXTRON'!F170,0) | G47: =IF(ISNUMBER('Input AIXTRON'!G170),'Input AIXTRON'!G170,0)
A48: + Prepaid & Other CA | B48: =IF(ISNUMBER('Input AIXTRON'!B171),'Input AIXTRON'!B171,0)+IF(ISNUMBER('Input AIXTRON'!B172),'Input AIXTRON'!B172,0) | C48: =IF(ISNUMBER('Input AIXTRON'!C171),'Input AIXTRON'!C171,0)+IF(ISNUMBER('Input AIXTRON'!C172),'Input AIXTRON'!C172,0) | D48: =IF(ISNUMBER('Input AIXTRON'!D171),'Input AIXTRON'!D171,0)+IF(ISNUMBER('Input AIXTRON'!D172),'Input AIXTRON'!D172,0) | E48: =IF(ISNUMBER('Input AIXTRON'!E171),'Input AIXTRON'!E171,0)+IF(ISNUMBER('Input AIXTRON'!E172),'Input AIXTRON'!E172,0) | F48: =IF(ISNUMBER('Input AIXTRON'!F171),'Input AIXTRON'!F171,0)+IF(ISNUMBER('Input AIXTRON'!F172),'Input AIXTRON'!F172,0) | G48: =IF(ISNUMBER('Input AIXTRON'!G171),'Input AIXTRON'!G171,0)+IF(ISNUMBER('Input AIXTRON'!G172),'Input AIXTRON'!G172,0)
...

Sheet Std AMAT
A1: Standardized Financial Statements - Applied Materials, Inc.
A2: (EUR 000)
B3: 2019 | C3: 2020 | D3: 2021 | E3: 2022 | F3: 2023 | G3: 2024
A5: Operating cash % | B5: 0.02 | C5: 0.02 | D5: 0.02 | E5: 0.02 | F5: 0.02 | G5: 0.02
A6: Tax rate (effective) | B6: =IF(ISNUMBER('Input AMAT'!B66),'Input AMAT'!B66,0) | C6: =IF(ISNUMBER('Input AMAT'!C66),'Input AMAT'!C66,0) | D6: =IF(ISNUMBER('Input AMAT'!D66),'Input AMAT'!D66,0) | E6: =IF(ISNUMBER('Input AMAT'!E66),'Input AMAT'!E66,0) | F6: =IF(ISNUMBER('Input AMAT'!F66),'Input AMAT'!F66,0) | G6: =IF(ISNUMBER('Input AMAT'!G66),'Input AMAT'!G66,0)
A8: INCOME STATEMENT
A9: Revenue | B9: =IF(ISNUMBER('Input AMAT'!B21),'Input AMAT'!B21,0) | C9: =IF(ISNUMBER('Input AMAT'!C21),'Input AMAT'!C21,0) | D9: =IF(ISNUMBER('Input AMAT'!D21),'Input AMAT'!D21,0) | E9: =IF(ISNUMBER('Input AMAT'!E21),'Input AMAT'!E21,0) | F9: =IF(ISNUMBER('Input AMAT'!F21),'Input AMAT'!F21,0) | G9: =IF(ISNUMBER('Input AMAT'!G21),'Input AMAT'!G21,0)
A10: Cost of Sales | B10: =IF(ISNUMBER('Input AMAT'!B23),'Input AMAT'!B23,0) | C10: =IF(ISNUMBER('Input AMAT'!C23),'Input AMAT'!C23,0) | D10: =IF(ISNUMBER('Input AMAT'!D23),'Input AMAT'!D23,0) | E10: =IF(ISNUMBER('Input AMAT'!E23),'Input AMAT'!E23,0) | F10: =IF(ISNUMBER('Input AMAT'!F23),'Input AMAT'!F23,0) | G10: =IF(ISNUMBER('Input AMAT'!G23),'Input AMAT'!G23,0)
A11: Gross Profit | B11: =B9-B10 | C11: =C9-C10 | D11: =D9-D10 | E11: =E9-E10 | F11: =F9-F10 | G11: =G9-G10
A12: SG&A | B12: =IF(ISNUMBER('Input AMAT'!B26),'Input AMAT'!B26,0) | C12: =IF(ISNUMBER('Input AMAT'!C26),'Input AMAT'!C26,0) | D12: =IF(ISNUMBER('Input AMAT'!D26),'Input AMAT'!D26,0) | E12: =IF(ISNUMBER('Input AMAT'!E26),'Input AMAT'!E26,0) | F12: =IF(ISNUMBER('Input AMAT'!F26),'Input AMAT'!F26,0) | G12: =IF(ISNUMBER('Input AMAT'!G26),'Input AMAT'!G26,0)
A13: R&D | B13: =IF(ISNUMBER('Input AMAT'!B27),'Input AMAT'!B27,0) | C13: =IF(ISNUMBER('Input AMAT'!C27),'Input AMAT'!C27,0) | D13: =IF(ISNUMBER('Input AMAT'!D27),'Input AMAT'!D27,0) | E13: =IF(ISNUMBER('Input AMAT'!E27),'Input AMAT'!E27,0) | F13: =IF(ISNUMBER('Input AMAT'!F27),'Input AMAT'!F27,0) | G13: =IF(ISNUMBER('Input AMAT'!G27),'Input AMAT'!G27,0)
A14: Depreciation & Amortization | B14: =IF(ISNUMBER('Input AMAT'!B108),'Input AMAT'!B108,0) | C14: =IF(ISNUMBER('Input AMAT'!C108),'Input AMAT'!C108,0) | D14: =IF(ISNUMBER('Input AMAT'!D108),'Input AMAT'!D108,0) | E14: =IF(ISNUMBER('Input AMAT'!E108),'Input AMAT'!E108,0) | F14: =IF(ISNUMBER('Input AMAT'!F108),'Input AMAT'!F108,0) | G14: =IF(ISNUMBER('Input AMAT'!G108),'Input AMAT'!G108,0)
A15: Other Operating Expense | B15: 0 | C15: 0 | D15: 0 | E15: 0 | F15: 0 | G15: 0
A16: Total Operating Expense | B16: =B10+B12+B13+B14+B15 | C16: =C10+C12+C13+C14+C15 | D16: =D10+D12+D13+D14+D15 | E16: =E10+E12+E13+E14+E15 | F16: =F10+F12+F13+F14+F15 | G16: =G10+G12+G13+G14+G15
A17: Recurring Operating Profit | B17: =B9-B16 | C17: =C9-C16 | D17: =D9-D16 | E17: =E9-E16 | F17: =F9-F16 | G17: =G9-G16
A19: Non-recurring items:
A20: Gain/Loss on Sale of Investments | B20: =IF(ISNUMBER('Input AMAT'!B39),'Input AMAT'!B39,0) | C20: =IF(ISNUMBER('Input AMAT'!C39),'Input AMAT'!C39,0) | D20: =IF(ISNUMBER('Input AMAT'!D39),'Input AMAT'!D39,0) | E20: =IF(ISNUMBER('Input AMAT'!E39),'Input AMAT'!E39,0) | F20: =IF(ISNUMBER('Input AMAT'!F39),'Input AMAT'!F39,0) | G20: =IF(ISNUMBER('Input AMAT'!G39),'Input AMAT'!G39,0)
A21: Gain/Loss on Sale of Assets | B21: 0 | C21: 0 | D21: 0 | E21: 0 | F21: 0 | G21: 0
A22: Asset Writedown | B22: 0 | C22: 0 | D22: 0 | E22: 0 | F22: 0 | G22: 0
A23: Other Unusual Items | B23: =IF(ISNUMBER('Input AMAT'!B40),'Input AMAT'!B40,0)+IF(ISNUMBER('Input AMAT'!B37),'Input AMAT'!B37,0)+IF(ISNUMBER('Input AMAT'!B38),'Input AMAT'!B38,0) | C23: =IF(ISNUMBER('Input AMAT'!C40),'Input AMAT'!C40,0)+IF(ISNUMBER('Input AMAT'!C37),'Input AMAT'!C37,0)+IF(ISNUMBER('Input AMAT'!C38),'Input AMAT'!C38,0) | D23: =IF(ISNUMBER('Input AMAT'!D40),'Input AMAT'!D40,0)+IF(ISNUMBER('Input AMAT'!D37),'Input AMAT'!D37,0)+IF(ISNUMBER('Input AMAT'!D38),'Input AMAT'!D38,0) | E23: =IF(ISNUMBER('Input AMAT'!E40),'Input AMAT'!E40,0)+IF(ISNUMBER('Input AMAT'!E37),'Input AMAT'!E37,0)+IF(ISNUMBER('Input AMAT'!E38),'Input AMAT'!E38,0) | F23: =IF(ISNUMBER('Input AMAT'!F40),'Input AMAT'!F40,0)+IF(ISNUMBER('Input AMAT'!F37),'Input AMAT'!F37,0)+IF(ISNUMBER('Input AMAT'!F38),'Input AMAT'!F38,0) | G23: =IF(ISNUMBER('Input AMAT'!G40),'Input AMAT'!G40,0)+IF(ISNUMBER('Input AMAT'!G37),'Input AMAT'!G37,0)+IF(ISNUMBER('Input AMAT'!G38),'Input AMAT'!G38,0)
A24: Total Non-recurring | B24: =SUM(B20:B23) | C24: =SUM(C20:C23) | D24: =SUM(D20:D23) | E24: =SUM(E20:E23) | F24: =SUM(F20:F23) | G24: =SUM(G20:G23)
A25: EBIT | B25: =B17+B24 | C25: =C17+C24 | D25: =D17+D24 | E25: =E17+E24 | F25: =F17+F24 | G25: =G17+G24
A27: Investment Income (Equity Method) | B27: 0 | C27: 0 | D27: 0 | E27: 0 | F27: 0 | G27: 0
A28: Interest Income | B28: =IF(ISNUMBER('Input AMAT'!B32),'Input AMAT'!B32,0) | C28: =IF(ISNUMBER('Input AMAT'!C32),'Input AMAT'!C32,0) | D28: =IF(ISNUMBER('Input AMAT'!D32),'Input AMAT'!D32,0) | E28: =IF(ISNUMBER('Input AMAT'!E32),'Input AMAT'!E32,0) | F28: =IF(ISNUMBER('Input AMAT'!F32),'Input AMAT'!F32,0) | G28: =IF(ISNUMBER('Input AMAT'!G32),'Input AMAT'!G32,0)
A29: Interest Expense | B29: =IF(ISNUMBER('Input AMAT'!B31),'Input AMAT'!B31,0) | C29: =IF(ISNUMBER('Input AMAT'!C31),'Input AMAT'!C31,0) | D29: =IF(ISNUMBER('Input AMAT'!D31),'Input AMAT'!D31,0) | E29: =IF(ISNUMBER('Input AMAT'!E31),'Input AMAT'!E31,0) | F29: =IF(ISNUMBER('Input AMAT'!F31),'Input AMAT'!F31,0) | G29: =IF(ISNUMBER('Input AMAT'!G31),'Input AMAT'!G31,0)
A30: FX Gains/(Losses) | B30: =IF(ISNUMBER('Input AMAT'!B34),'Input AMAT'!B34,0) | C30: =IF(ISNUMBER('Input AMAT'!C34),'Input AMAT'!C34,0) | D30: =IF(ISNUMBER('Input AMAT'!D34),'Input AMAT'!D34,0) | E30: =IF(ISNUMBER('Input AMAT'!E34),'Input AMAT'!E34,0) | F30: =IF(ISNUMBER('Input AMAT'!F34),'Input AMAT'!F34,0) | G30: =IF(ISNUMBER('Input AMAT'!G34),'Input AMAT'!G34,0)
A31: Profit Before Tax | B31: =B25+B27+B28+B29+B30 | C31: =C25+C27+C28+C29+C30 | D31: =D25+D27+D28+D29+D30 | E31: =E25+E27+E28+E29+E30 | F31: =F25+F27+F28+F29+F30 | G31: =G25+G27+G28+G29+G30
A32: Tax Expense | B32: =IF(ISNUMBER('Input AMAT'!B43),'Input AMAT'!B43,0) | C32: =IF(ISNUMBER('Input AMAT'!C43),'Input AMAT'!C43,0) | D32: =IF(ISNUMBER('Input AMAT'!D43),'Input AMAT'!D43,0) | E32: =IF(ISNUMBER('Input AMAT'!E43),'Input AMAT'!E43,0) | F32: =IF(ISNUMBER('Input AMAT'!F43),'Input AMAT'!F43,0) | G32: =IF(ISNUMBER('Input AMAT'!G43),'Input AMAT'!G43,0)
A33: Net Income | B33: =B31-B32 | C33: =C31-C32 | D33: =D31-D32 | E33: =E31-E32 | F33: =F31-F32 | G33: =G31-G32
A35: Effective Tax Rate | B35: =IF(B31<>0,B32/B31,0) | C35: =IF(C31<>0,C32/C31,0) | D35: =IF(D31<>0,D32/D31,0) | E35: =IF(E31<>0,E32/E31,0) | F35: =IF(F31<>0,F32/F31,0) | G35: =IF(G31<>0,G32/G31,0)
A36: NOPAT | B36: =B17*(1-B35) | C36: =C17*(1-C35) | D36: =D17*(1-D35) | E36: =E17*(1-E35) | F36: =F17*(1-F35) | G36: =G17*(1-G35)
A38: Shares Outstanding (diluted) | B38: =IF(ISNUMBER('Input AMAT'!B55),'Input AMAT'!B55,0) | C38: =IF(ISNUMBER('Input AMAT'!C55),'Input AMAT'!C55,0) | D38: =IF(ISNUMBER('Input AMAT'!D55),'Input AMAT'!D55,0) | E38: =IF(ISNUMBER('Input AMAT'!E55),'Input AMAT'!E55,0) | F38: =IF(ISNUMBER('Input AMAT'!F55),'Input AMAT'!F55,0) | G38: =IF(ISNUMBER('Input AMAT'!G55),'Input AMAT'!G55,0)
A39: EPS (diluted) | B39: =IF(B38<>0,B33/B38*1000,0) | C39: =IF(C38<>0,C33/C38*1000,0) | D39: =IF(D38<>0,D33/D38*1000,0) | E39: =IF(E38<>0,E33/E38*1000,0) | F39: =IF(F38<>0,F33/F38*1000,0) | G39: =IF(G38<>0,G33/G38*1000,0)
A40: Dividends per Share | B40: =IF(ISNUMBER('Input AMAT'!B58),'Input AMAT'!B58,0) | C40: =IF(ISNUMBER('Input AMAT'!C58),'Input AMAT'!C58,0) | D40: =IF(ISNUMBER('Input AMAT'!D58),'Input AMAT'!D58,0) | E40: =IF(ISNUMBER('Input AMAT'!E58),'Input AMAT'!E58,0) | F40: =IF(ISNUMBER('Input AMAT'!F58),'Input AMAT'!F58,0) | G40: =IF(ISNUMBER('Input AMAT'!G58),'Input AMAT'!G58,0)
A43: BALANCE SHEET (Reformulated)
A44: Operating Working Capital:
A45: Trade Receivables | B45: =IF(ISNUMBER('Input AMAT'!B161),'Input AMAT'!B161,0) | C45: =IF(ISNUMBER('Input AMAT'!C161),'Input AMAT'!C161,0) | D45: =IF(ISNUMBER('Input AMAT'!D161),'Input AMAT'!D161,0) | E45: =IF(ISNUMBER('Input AMAT'!E161),'Input AMAT'!E161,0) | F45: =IF(ISNUMBER('Input AMAT'!F161),'Input AMAT'!F161,0) | G45: =IF(ISNUMBER('Input AMAT'!G161),'Input AMAT'!G161,0)
A46: + Other Receivables | B46: 0 | C46: 0 | D46: 0 | E46: 0 | F46: 0 | G46: 0
A47: + Inventories | B47: =IF(ISNUMBER('Input AMAT'!B163),'Input AMAT'!B163,0) | C47: =IF(ISNUMBER('Input AMAT'!C163),'Input AMAT'!C163,0) | D47: =IF(ISNUMBER('Input AMAT'!D163),'Input AMAT'!D163,0) | E47: =IF(ISNUMBER('Input AMAT'!E163),'Input AMAT'!E163,0) | F47: =IF(ISNUMBER('Input AMAT'!F163),'Input AMAT'!F163,0) | G47: =IF(ISNUMBER('Input AMAT'!G163),'Input AMAT'!G163,0)
A48: + Prepaid & Other CA | B48: =IF(ISNUMBER('Input AMAT'!B164),'Input AMAT'!B164,0)+IF(ISNUMBER('Input AMAT'!B165),'Input AMAT'!B165,0) | C48: =IF(ISNUMBER('Input AMAT'!C164),'Input AMAT'!C164,0)+IF(ISNUMBER('Input AMAT'!C165),'Input AMAT'!C165,0) | D48: =IF(ISNUMBER('Input AMAT'!D164),'Input AMAT'!D164,0)+IF(ISNUMBER('Input AMAT'!D165),'Input AMAT'!D165,0) | E48: =IF(ISNUMBER('Input AMAT'!E164),'Input AMAT'!E164,0)+IF(ISNUMBER('Input AMAT'!E165),'Input AMAT'!E165,0) | F48: =IF(ISNUMBER('Input AMAT'!F164),'Input AMAT'!F164,0)+IF(ISNUMBER('Input AMAT'!F165),'Input AMAT'!F165,0) | G48: =IF(ISNUMBER('Input AMAT'!G164),'Input AMAT'!G164,0)+IF(ISNUMBER('Input AMAT'!G165),'Input AMAT'!G165,0)
...

Sheet Std LRCX
A1: Standardized Financial Statements - Lam Research Corporation
A2: (EUR 000)
B3: 2019 | C3: 2020 | D3: 2021 | E3: 2022 | F3: 2023 | G3: 2024
A5: Operating cash % | B5: 0.02 | C5: 0.02 | D5: 0.02 | E5: 0.02 | F5: 0.02 | G5: 0.02
A6: Tax rate (effective) | B6: =IF(ISNUMBER('Input LRCX'!B63),'Input LRCX'!B63,0) | C6: =IF(ISNUMBER('Input LRCX'!C63),'Input LRCX'!C63,0) | D6: =IF(ISNUMBER('Input LRCX'!D63),'Input LRCX'!D63,0) | E6: =IF(ISNUMBER('Input LRCX'!E63),'Input LRCX'!E63,0) | F6: =IF(ISNUMBER('Input LRCX'!F63),'Input LRCX'!F63,0) | G6: =IF(ISNUMBER('Input LRCX'!G63),'Input LRCX'!G63,0)
A8: INCOME STATEMENT
A9: Revenue | B9: =IF(ISNUMBER('Input LRCX'!B21),'Input LRCX'!B21,0) | C9: =IF(ISNUMBER('Input LRCX'!C21),'Input LRCX'!C21,0) | D9: =IF(ISNUMBER('Input LRCX'!D21),'Input LRCX'!D21,0) | E9: =IF(ISNUMBER('Input LRCX'!E21),'Input LRCX'!E21,0) | F9: =IF(ISNUMBER('Input LRCX'!F21),'Input LRCX'!F21,0) | G9: =IF(ISNUMBER('Input LRCX'!G21),'Input LRCX'!G21,0)
A10: Cost of Sales | B10: =IF(ISNUMBER('Input LRCX'!B23),'Input LRCX'!B23,0) | C10: =IF(ISNUMBER('Input LRCX'!C23),'Input LRCX'!C23,0) | D10: =IF(ISNUMBER('Input LRCX'!D23),'Input LRCX'!D23,0) | E10: =IF(ISNUMBER('Input LRCX'!E23),'Input LRCX'!E23,0) | F10: =IF(ISNUMBER('Input LRCX'!F23),'Input LRCX'!F23,0) | G10: =IF(ISNUMBER('Input LRCX'!G23),'Input LRCX'!G23,0)
A11: Gross Profit | B11: =B9-B10 | C11: =C9-C10 | D11: =D9-D10 | E11: =E9-E10 | F11: =F9-F10 | G11: =G9-G10
A12: SG&A | B12: =IF(ISNUMBER('Input LRCX'!B26),'Input LRCX'!B26,0) | C12: =IF(ISNUMBER('Input LRCX'!C26),'Input LRCX'!C26,0) | D12: =IF(ISNUMBER('Input LRCX'!D26),'Input LRCX'!D26,0) | E12: =IF(ISNUMBER('Input LRCX'!E26),'Input LRCX'!E26,0) | F12: =IF(ISNUMBER('Input LRCX'!F26),'Input LRCX'!F26,0) | G12: =IF(ISNUMBER('Input LRCX'!G26),'Input LRCX'!G26,0)
A13: R&D | B13: =IF(ISNUMBER('Input LRCX'!B27),'Input LRCX'!B27,0) | C13: =IF(ISNUMBER('Input LRCX'!C27),'Input LRCX'!C27,0) | D13: =IF(ISNUMBER('Input LRCX'!D27),'Input LRCX'!D27,0) | E13: =IF(ISNUMBER('Input LRCX'!E27),'Input LRCX'!E27,0) | F13: =IF(ISNUMBER('Input LRCX'!F27),'Input LRCX'!F27,0) | G13: =IF(ISNUMBER('Input LRCX'!G27),'Input LRCX'!G27,0)
A14: Depreciation & Amortization | B14: =IF(ISNUMBER('Input LRCX'!B98),'Input LRCX'!B98,0) | C14: =IF(ISNUMBER('Input LRCX'!C98),'Input LRCX'!C98,0) | D14: =IF(ISNUMBER('Input LRCX'!D98),'Input LRCX'!D98,0) | E14: =IF(ISNUMBER('Input LRCX'!E98),'Input LRCX'!E98,0) | F14: =IF(ISNUMBER('Input LRCX'!F98),'Input LRCX'!F98,0) | G14: =IF(ISNUMBER('Input LRCX'!G98),'Input LRCX'!G98,0)
A15: Other Operating Expense | B15: 0 | C15: 0 | D15: 0 | E15: 0 | F15: 0 | G15: 0
A16: Total Operating Expense | B16: =B10+B12+B13+B14+B15 | C16: =C10+C12+C13+C14+C15 | D16: =D10+D12+D13+D14+D15 | E16: =E10+E12+E13+E14+E15 | F16: =F10+F12+F13+F14+F15 | G16: =G10+G12+G13+G14+G15
A17: Recurring Operating Profit | B17: =B9-B16 | C17: =C9-C16 | D17: =D9-D16 | E17: =E9-E16 | F17: =F9-F16 | G17: =G9-G16
A19: Non-recurring items:
A20: Gain/Loss on Sale of Investments | B20: 0 | C20: 0 | D20: 0 | E20: 0 | F20: 0 | G20: 0
A21: Gain/Loss on Sale of Assets | B21: 0 | C21: 0 | D21: 0 | E21: 0 | F21: 0 | G21: 0
A22: Asset Writedown | B22: 0 | C22: 0 | D22: 0 | E22: 0 | F22: 0 | G22: 0
A23: Other Unusual Items | B23: =IF(ISNUMBER('Input LRCX'!B37),'Input LRCX'!B37,0) | C23: =IF(ISNUMBER('Input LRCX'!C37),'Input LRCX'!C37,0) | D23: =IF(ISNUMBER('Input LRCX'!D37),'Input LRCX'!D37,0) | E23: =IF(ISNUMBER('Input LRCX'!E37),'Input LRCX'!E37,0) | F23: =IF(ISNUMBER('Input LRCX'!F37),'Input LRCX'!F37,0) | G23: =IF(ISNUMBER('Input LRCX'!G37),'Input LRCX'!G37,0)
A24: Total Non-recurring | B24: =SUM(B20:B23) | C24: =SUM(C20:C23) | D24: =SUM(D20:D23) | E24: =SUM(E20:E23) | F24: =SUM(F20:F23) | G24: =SUM(G20:G23)
A25: EBIT | B25: =B17+B24 | C25: =C17+C24 | D25: =D17+D24 | E25: =E17+E24 | F25: =F17+F24 | G25: =G17+G24
A27: Investment Income (Equity Method) | B27: 0 | C27: 0 | D27: 0 | E27: 0 | F27: 0 | G27: 0
A28: Interest Income | B28: =IF(ISNUMBER('Input LRCX'!B32),'Input LRCX'!B32,0) | C28: =IF(ISNUMBER('Input LRCX'!C32),'Input LRCX'!C32,0) | D28: =IF(ISNUMBER('Input LRCX'!D32),'Input LRCX'!D32,0) | E28: =IF(ISNUMBER('Input LRCX'!E32),'Input LRCX'!E32,0) | F28: =IF(ISNUMBER('Input LRCX'!F32),'Input LRCX'!F32,0) | G28: =IF(ISNUMBER('Input LRCX'!G32),'Input LRCX'!G32,0)
A29: Interest Expense | B29: =IF(ISNUMBER('Input LRCX'!B31),'Input LRCX'!B31,0) | C29: =IF(ISNUMBER('Input LRCX'!C31),'Input LRCX'!C31,0) | D29: =IF(ISNUMBER('Input LRCX'!D31),'Input LRCX'!D31,0) | E29: =IF(ISNUMBER('Input LRCX'!E31),'Input LRCX'!E31,0) | F29: =IF(ISNUMBER('Input LRCX'!F31),'Input LRCX'!F31,0) | G29: =IF(ISNUMBER('Input LRCX'!G31),'Input LRCX'!G31,0)
A30: FX Gains/(Losses) | B30: =IF(ISNUMBER('Input LRCX'!B34),'Input LRCX'!B34,0) | C30: =IF(ISNUMBER('Input LRCX'!C34),'Input LRCX'!C34,0) | D30: =IF(ISNUMBER('Input LRCX'!D34),'Input LRCX'!D34,0) | E30: =IF(ISNUMBER('Input LRCX'!E34),'Input LRCX'!E34,0) | F30: =IF(ISNUMBER('Input LRCX'!F34),'Input LRCX'!F34,0) | G30: =IF(ISNUMBER('Input LRCX'!G34),'Input LRCX'!G34,0)
A31: Profit Before Tax | B31: =B25+B27+B28+B29+B30 | C31: =C25+C27+C28+C29+C30 | D31: =D25+D27+D28+D29+D30 | E31: =E25+E27+E28+E29+E30 | F31: =F25+F27+F28+F29+F30 | G31: =G25+G27+G28+G29+G30
A32: Tax Expense | B32: =IF(ISNUMBER('Input LRCX'!B40),'Input LRCX'!B40,0) | C32: =IF(ISNUMBER('Input LRCX'!C40),'Input LRCX'!C40,0) | D32: =IF(ISNUMBER('Input LRCX'!D40),'Input LRCX'!D40,0) | E32: =IF(ISNUMBER('Input LRCX'!E40),'Input LRCX'!E40,0) | F32: =IF(ISNUMBER('Input LRCX'!F40),'Input LRCX'!F40,0) | G32: =IF(ISNUMBER('Input LRCX'!G40),'Input LRCX'!G40,0)
A33: Net Income | B33: =B31-B32 | C33: =C31-C32 | D33: =D31-D32 | E33: =E31-E32 | F33: =F31-F32 | G33: =G31-G32
A35: Effective Tax Rate | B35: =IF(B31<>0,B32/B31,0) | C35: =IF(C31<>0,C32/C31,0) | D35: =IF(D31<>0,D32/D31,0) | E35: =IF(E31<>0,E32/E31,0) | F35: =IF(F31<>0,F32/F31,0) | G35: =IF(G31<>0,G32/G31,0)
A36: NOPAT | B36: =B17*(1-B35) | C36: =C17*(1-C35) | D36: =D17*(1-D35) | E36: =E17*(1-E35) | F36: =F17*(1-F35) | G36: =G17*(1-G35)
A38: Shares Outstanding (diluted) | B38: =IF(ISNUMBER('Input LRCX'!B52),'Input LRCX'!B52,0) | C38: =IF(ISNUMBER('Input LRCX'!C52),'Input LRCX'!C52,0) | D38: =IF(ISNUMBER('Input LRCX'!D52),'Input LRCX'!D52,0) | E38: =IF(ISNUMBER('Input LRCX'!E52),'Input LRCX'!E52,0) | F38: =IF(ISNUMBER('Input LRCX'!F52),'Input LRCX'!F52,0) | G38: =IF(ISNUMBER('Input LRCX'!G52),'Input LRCX'!G52,0)
A39: EPS (diluted) | B39: =IF(B38<>0,B33/B38*1000,0) | C39: =IF(C38<>0,C33/C38*1000,0) | D39: =IF(D38<>0,D33/D38*1000,0) | E39: =IF(E38<>0,E33/E38*1000,0) | F39: =IF(F38<>0,F33/F38*1000,0) | G39: =IF(G38<>0,G33/G38*1000,0)
A40: Dividends per Share | B40: =IF(ISNUMBER('Input LRCX'!B55),'Input LRCX'!B55,0) | C40: =IF(ISNUMBER('Input LRCX'!C55),'Input LRCX'!C55,0) | D40: =IF(ISNUMBER('Input LRCX'!D55),'Input LRCX'!D55,0) | E40: =IF(ISNUMBER('Input LRCX'!E55),'Input LRCX'!E55,0) | F40: =IF(ISNUMBER('Input LRCX'!F55),'Input LRCX'!F55,0) | G40: =IF(ISNUMBER('Input LRCX'!G55),'Input LRCX'!G55,0)
A43: BALANCE SHEET (Reformulated)
A44: Operating Working Capital:
A45: Trade Receivables | B45: =IF(ISNUMBER('Input LRCX'!B152),'Input LRCX'!B152,0) | C45: =IF(ISNUMBER('Input LRCX'!C152),'Input LRCX'!C152,0) | D45: =IF(ISNUMBER('Input LRCX'!D152),'Input LRCX'!D152,0) | E45: =IF(ISNUMBER('Input LRCX'!E152),'Input LRCX'!E152,0) | F45: =IF(ISNUMBER('Input LRCX'!F152),'Input LRCX'!F152,0) | G45: =IF(ISNUMBER('Input LRCX'!G152),'Input LRCX'!G152,0)
A46: + Other Receivables | B46: 0 | C46: 0 | D46: 0 | E46: 0 | F46: 0 | G46: 0
A47: + Inventories | B47: =IF(ISNUMBER('Input LRCX'!B154),'Input LRCX'!B154,0) | C47: =IF(ISNUMBER('Input LRCX'!C154),'Input LRCX'!C154,0) | D47: =IF(ISNUMBER('Input LRCX'!D154),'Input LRCX'!D154,0) | E47: =IF(ISNUMBER('Input LRCX'!E154),'Input LRCX'!E154,0) | F47: =IF(ISNUMBER('Input LRCX'!F154),'Input LRCX'!F154,0) | G47: =IF(ISNUMBER('Input LRCX'!G154),'Input LRCX'!G154,0)
A48: + Prepaid & Other CA | B48: =IF(ISNUMBER('Input LRCX'!B155),'Input LRCX'!B155,0)+IF(ISNUMBER('Input LRCX'!B156),'Input LRCX'!B156,0) | C48: =IF(ISNUMBER('Input LRCX'!C155),'Input LRCX'!C155,0)+IF(ISNUMBER('Input LRCX'!C156),'Input LRCX'!C156,0) | D48: =IF(ISNUMBER('Input LRCX'!D155),'Input LRCX'!D155,0)+IF(ISNUMBER('Input LRCX'!D156),'Input LRCX'!D156,0) | E48: =IF(ISNUMBER('Input LRCX'!E155),'Input LRCX'!E155,0)+IF(ISNUMBER('Input LRCX'!E156),'Input LRCX'!E156,0) | F48: =IF(ISNUMBER('Input LRCX'!F155),'Input LRCX'!F155,0)+IF(ISNUMBER('Input LRCX'!F156),'Input LRCX'!F156,0) | G48: =IF(ISNUMBER('Input LRCX'!G155),'Input LRCX'!G155,0)+IF(ISNUMBER('Input LRCX'!G156),'Input LRCX'!G156,0)
...

Sheet Adjustments
A1: Accounting Analysis & Adjustments - ASM International NV
A3: Areas Examined
A5: 1. R&D Capitalization Policy
B6: Description: | C6: ASM capitalizes development expenditure (significant amounts).
B7: Finding: | C7: Compare with peers: all semi equipment companies capitalize similarly.
B8: Decision: | C8: No Adjustment
B9: Justification: | C9: Consistent with industry practice and peers.
A11: 2. Equity Method Investment (ASMPT)
B12: Description: | C12: ~25% stake in ASM Pacific Technology.
B13: Finding: | C13: Already separated as Investment Income in standardized IS.
B14: Decision: | C14: No Adjustment
B15: Justification: | C15: No further adjustment needed.
