Workbook

Sheet Income Statements
A1: Standard Accounts | B1: Income Statement in EUR million (IFRS) | C1: FY 2021 | D1: FY 2020 | E1: FY 2019 | F1: FY 2018 | G1: FY 2017 | H1: FY 2016
A3: Revenue | B3: Net sales | C3: =13792.612-C17 -> 13792.612 | D3: =12526.595-1.768 -> 12524.827 | E3: =11083.514-2.7 -> 11080.814 | F3: =10406.96-2.738 -> 10404.222 | G3: =9434.67-1.678 -> 9432.992 | H3: =8196.265-1.747 -> 8194.518
A4: Cost of Materials (nature) | B4: Cost of merchandise | C4: -5612.216 | D4: -5104.573 | E4: -4755.505 | F4: -4492.72 | G4: -4085.959 | H4: -3589.276
B5: Gross profit | C5: =SUM(C3:C4) -> 8180.396 | D5: =SUM(D3:D4) -> 7420.254 | E5: =SUM(E3:E4) -> 6325.309 | F5: =SUM(F3:F4) -> 5911.502 | G5: =SUM(G3:G4) -> 5347.033 | H5: =SUM(H3:H4) -> 4605.242
A7: Personnel Expenses (nature) | B7: Personnel expenses | C7: -2234.178 | D7: -2009.429 | E7: -1791.632 | F7: -1703.188 | G7: -1472.9 | H7: -1250.845
A8: Other Operating Income, Net of Other Operating Expenses (function) | B8: Operating leases | C8: -1398.732 | D8: -1272.076 | E8: -1134.032 | F8: -1028.377 | G8: -855.378 | H8: -717.915
A9: Depreciation and Amortization (nature) | B9: Amortization and depreciation | C9: -735.666 | D9: -675.738 | E9: -645.801 | F9: -578.32 | G9: -496.663 | H9: -433.427
A10: Other Operating Income, Net of Other Operating Expenses (function) | B10: Other operating expenses | C10: =-1286.418-3.396 -> -1289.814 | D10: =-3.604-1170.706 -> -1174.31 | E10: =-1.118-1027.038 -> -1028.156 | F10: =-976.322-19.497 -> -995.819 | G10: =-898.091+26.501 -> -871.59 | H10: =-831.483-17.06 -> -848.543
B11: Operating profit (EBIT) | C11: =SUM(C5:C10) -> 2522.006 | D11: =SUM(D5:D10) -> 2288.701 | E11: =SUM(E5:E10) -> 1725.688 | F11: =SUM(F5:F10) -> 1605.798 | G11: =SUM(G5:G10) -> 1650.502 | H11: =SUM(H5:H10) -> 1354.512
A12: Interest Income | B12: Interest income | C12: 30.237 | D12: 21.026 | E12: 8.368 | F12: 26.067 | G12: 20.603 | H12: 16.425
A13: Interest Expense | B13: Interest expense | C13: -3.672 | D13: -3.561 | E13: -9.428 | F13: -9.372 | G13: -4.659 | H13: -10.993
A14: Other Income, Net of Other Expense | B14: Foreign exchange gains/losses | C14: =24.315-3.835 -> 20.48 | D14: =21.909-8.489 -> 13.42 | E14: =37.172-32.641 -> 4.531 | F14: =20.075-58.546 -> -38.471 | G14: =15.28-28.836 -> -13.556 | H14: =3.515-21.067 -> -17.552
A15: Investment Income | B15: Dividends | C15: 0.147 | D15: 0.231 | E15: 0.311 | F15: 0.177 | G15: 0.144 | H15: 0.223
A16: Other Income, Net of Other Expense | B16: Changes in fair value of financial instruments | C16: 0 | D16: 0 | E16: 0 | F16: 0 | G16: -1.568 | H16: -2.137
A17: Investment Income | B17: Rental income on investment property | C17: 0 | D17: 1.768 | E17: 2.7 | F17: 2.738 | G17: 1.678 | H17: 1.747
A18: Investment Income | B18: Equity accounting losses | C18: -10.186 | D18: 0 | E18: 0 | F18: 0 | G18: -7.508 | H18: -2.786
B19: Income before taxes | C19: =SUM(C11:C18) -> 2559.012 | D19: =SUM(D11:D18) -> 2321.585 | E19: =SUM(E11:E18) -> 1732.17 | F19: =SUM(F11:F18) -> 1586.937 | G19: =SUM(G11:G18) -> 1645.636 | H19: =SUM(H11:H18) -> 1339.439
A20: Tax Expense | B20: Income tax | C20: -613.48 | D20: -580.305 | E20: -410.033 | F20: -325.322 | G20: -387.872 | H20: -329.502
A21: Profit/Loss to Non-Controlling Interest | B21: Minority interest | C21: -13.244 | D21: -9.451 | E21: -7.783 | F21: -8.164 | G21: -7.495 | H21: -8.396
A22: Profit/Loss to Ordinary Shareholders | B22: Net income | C22: =SUM(C19:C21) -> 1932.288 | D22: =SUM(D19:D21) -> 1731.829 | E22: =SUM(E19:E21) -> 1314.354 | F22: =SUM(F19:F21) -> 1253.451 | G22: =SUM(G19:G21) -> 1250.269 | H22: =SUM(H19:H21) -> 1001.541

Sheet Balance Sheets
A1: Standard Accounts | B1: Balance Sheet in EUR million (IFRS) | C1: FY 2021 | D1: FY 2020 | E1: FY 2019 | F1: FY 2018 | G1: FY 2017 | H1: FY 2016 | I1: Notes:
A3: Cash and Cash Equivalents | B3: Cash and cash equivalents | C3: 3466.752 | D3: 3433.452 | E3: 2420.11 | F3: 1466.291 | G3: 1465.835 | H3: 906.148
A4: Trade Receivables | B4: Trade and other receivables | C4: 531.048 | D4: 481.844 | E4: 421.781 | F4: 585.311 | G4: 463.716 | H4: 363.635
A5: Inventories | B5: Inventories | C5: 1277.009 | D5: 1214.623 | E5: 992.57 | F5: 1054.84 | G5: 1007.213 | H5: 823.903
A6: Other Current Assets | B6: Income tax receivable | C6: 17.235 | D6: 16.958 | E6: 15.663 | F6: 15.342 | G6: 1.719 | H6: 20.87
A7: Other Current Assets | B7: Other current assets | C7: =94.561+50.684 -> 145.245 | D7: 55.635 | E7: 93.671 | F7: 142.257 | G7: 43.112 | H7: 33.776
B8: Total current assets | C8: =SUM(C3:C7) -> 5437.289 | D8: =SUM(D3:D7) -> 5202.512 | E8: =SUM(E3:E7) -> 3943.795 | F8: =SUM(F3:F7) -> 3264.041 | G8: =SUM(G3:G7) -> 2981.595 | H8: =SUM(H3:H7) -> 2148.332
A10: Non-Current Tangible Assets | B10: Property, plant and equipment | C10: 4063.066 | D10: 3397.083 | E10: 3293.535 | F10: 3442.321 | G10: 3182.112 | H10: 2788.816
A11: Other Non-Operating Investments | B11: Investment property | C11: 19.807 | D11: 17.354 | E11: 13.273 | F11: 8.455 | G11: 9.475 | H11: 11.851
A12: Non-Current Intangible Assets | B12: Rights over leased assets | C12: 499.96 | D12: 526.306 | E12: 514.159 | F12: 531.468 | G12: 504.604 | H12: 454.196
A13: Non-Current Intangible Assets | B13: Other intangible assets | C13: 114.148 | D13: 29.444 | E13: 19.118 | F13: 16.476 | G13: 13.344 | H13: 15.22
A14: Non-Current Intangible Assets | B14: Goodwill | C14: 218.094 | D14: 131.685 | E14: 131.685 | F14: 131.685 | G14: 125.583 | H14: 98.992
A15: Other Non-Operating Investments | B15: Financial investments | C15: 9.501 | D15: 8.921 | E15: 15.392 | F15: 14.416 | G15: 36.174 | H15: 33.375
A16: Other Non-Operating Investments | B16: Investments in associates | C16: 0 | D16: 0 | E16: 0 | F16: 0 | G16: 0 | H16: 4.446
A17: Deferred Tax Assets | B17: Deferred tax assets | C17: 356.372 | D17: 299.35 | E17: 234.203 | F17: 203.1 | G17: 133.02 | H17: 88.851
A18: Other Non-Operating Investments | B18: Other | C18: 240.941 | D18: 213.425 | E18: 170.277 | F18: 164.684 | G18: 119.695 | H18: 98.083
B19: Total non-current assets | C19: =SUM(C10:C18) -> 5521.889 | D19: =SUM(D10:D18) -> 4623.568 | E19: =SUM(E10:E18) -> 4391.642 | F19: =SUM(F10:F18) -> 4512.605 | G19: =SUM(G10:G18) -> 4124.007 | H19: =SUM(H10:H18) -> 3593.83
A21: Total Assets | B21: Total assets | C21: =C8+C19 -> 10959.178 | D21: =D8+D19 -> 9826.08 | E21: =E8+E19 -> 8335.437 | F21: =F8+F19 -> 7776.646 | G21: =G8+G19 -> 7105.602 | H21: =H8+H19 -> 5742.162
A23: Trade Payables | B23: Trade and other payables | C23: =2475.14+22.88 -> 2498.02 | D23: 2458.857 | E23: 2103.029 | F23: 2073.141 | G23: 1975.251 | H23: 1618.825
A24: Current Debt | B24: Financial debt | C24: 0.686 | D24: 2.682 | E24: 35.058 | F24: 234.037 | G24: 371.276 | H24: 145.077
A25: Other Current Liabilities | B25: Income tax payable | C25: 204.068 | D25: 213.368 | E25: 166.873 | F25: 83.67 | G25: 111.54 | H25: 120.839
B26: Current liabilities | C26: =SUM(C23:C25) -> 2702.774 | D26: =SUM(D23:D25) -> 2674.907 | E26: =SUM(E23:E25) -> 2304.96 | F26: =SUM(F23:F25) -> 2390.848 | G26: =SUM(G23:G25) -> 2458.067 | H26: =SUM(H23:H25) -> 1884.741
A28: Non-Current Debt | B28: Financial debt | C28: 1.544 | D28: 4.172 | E28: 4.996 | F28: 13.241 | G28: 42.358 | H28: 47.314
A29: Deferred Tax Liabilities | B29: Deferred tax liabilities | C29: 182.531 | D29: 172.648 | E29: 172.892 | F29: 213.847 | G29: 110.957 | H29: 104.319
A30: Non-Current Debt | B30: Provisions | C30: 147.318 | D30: 156.61 | E30: 127.054 | F30: 101.82 | G30: 47.481 | H30: 45.114 | I30: This could also be classified as Other Non-Current Liabilities (non interest bearing)
A31: Other Non-Current Liabilities (non interest bearing) | B31: Other non-current liabilities | C31: 469.434 | D31: 394.575 | E31: 354.989 | F31: 308.29 | G31: 229.488 | H31: 190.07
B32: Non-current liabilities | C32: =SUM(C28:C31) -> 800.827 | D32: =SUM(D28:D31) -> 728.005 | E32: =SUM(E28:E31) -> 659.931 | F32: =SUM(F28:F31) -> 637.198 | G32: =SUM(G28:G31) -> 430.284 | H32: =SUM(H28:H31) -> 386.817
A34: Ordinary Shareholders' Equity | B34: Net equity attributable to the parent | C34: 7414.806 | D34: 6386.183 | E34: 5329.166 | F34: 4721.714 | G34: 4193.129 | H34: 3448.377
A35: Non-Controlling Interest in Equity | B35: Net equity attributable to minority interest | C35: 40.771 | D35: 36.984 | E35: 41.38 | F35: 26.886 | G35: 23.922 | H35: 22.227
B36: Total equity | C36: =SUM(C34:C35) -> 7455.577 | D36: =SUM(D34:D35) -> 6423.167 | E36: =SUM(E34:E35) -> 5370.546 | F36: =SUM(F34:F35) -> 4748.6 | G36: =SUM(G34:G35) -> 4217.051 | H36: =SUM(H34:H35) -> 3470.604
A38: Total Liabilities and Shareholders' Equity | B38: Total liabilities and shareholders' equity | C38: =C26+C32+C36 -> 10959.178 | D38: =D26+D32+D36 -> 9826.079 | E38: =E26+E32+E36 -> 8335.437 | F38: =F26+F32+F36 -> 7776.646 | G38: =G26+G32+G36 -> 7105.402 | H38: =H26+H32+H36 -> 5742.162

Sheet Cash Flow Statements
A1: Standard Accounts | B1: Cash flow statement in EUR million (IFRS) | C1: FY 2021 | D1: FY 2020 | E1: FY 2019 | F1: FY 2018 | G1: FY 2017 | H1: FY 2016
B3: Operating activities
A4: Profit Before Interest and Tax | B4: Income before taxes and minority interest | C4: 2559.012 | D4: 2321.585 | E4: 1732.17 | F4: 1586.937 | G4: 1645.636 | H4: 1339.438
B5: Interest income | C5: -30.237 | D5: -21.026 | E5: -8.368 | F5: -26.067 | G5: -20.603 | H5: -16.425
B6: Interest expense | C6: 3.672 | D6: 3.561 | E6: 9.428 | F6: 9.372 | G6: 4.659 | H6: 10.993
A7: Interest Received | B7: Interest income | C7: 30.237 | D7: 21.026 | E7: 8.368 | F7: 26.067 | G7: 20.603 | H7: 16.425
A8: Interest Paid | B8: Interest expense | C8: -3.672 | D8: -3.561 | E8: -9.428 | F8: -9.372 | G8: -4.659 | H8: -10.993
B9: Adjustment for:
A10: Non-Current Operating Accruals | B10: Amortization and depreciation | C10: 692.621 | D10: 636.281 | E10: 624.711 | F10: 578.32 | G10: 496.663 | H10: 433.427
A11: Taxes Paid | B11: Income tax | C11: -693.201 | D11: -508 | E11: -391.059 | F11: -325.322 | G11: -387.872 | H11: -329.502
A12: Non-Current Operating Accruals | B12: Deferred tax assets and liabilities | C12: 0 | D12: 0 | E12: 0 | F12: 35.253 | G12: -38.465 | H12: -13.285
A13: Non-Current Operating Accruals | B13: Foreign exchange translation differences | C13: -29.218 | D13: -29.681 | E13: 30.665 | F13: -11.097 | G13: 1.837 | H13: 0.271
A14: Non-Current Operating Accruals | B14: Provision for impairment | C14: 41.181 | D14: 61.175 | E14: 53.087 | F14: 0 | G14: 0 | H14: 0
A15: Non-Current Operating Accruals | B15: Other adjustments to income | C15: 42.437 | D15: 58.601 | E15: 10.074 | F15: -14.022 | G15: 39.338 | H15: 61.335
A16: Net (Investments in) or Liquidation of Operating Working Capital | B16: Change in inventories | C16: -56.663 | D16: -227.08 | E16: 48.466 | F16: -60.736 | G16: -197.485 | H16: -135.457
A17: Net (Investments in) or Liquidation of Operating Working Capital | B17: Change in receivables and other current assets | C17: -80.1 | D17: -119.68 | E17: 162.75 | F17: -157.425 | G17: -87.608 | H17: -51.312
A18: Net (Investments in) or Liquidation of Operating Working Capital | B18: Change in current payables | C18: -67.408 | D18: 363.011 | E18: 49.983 | F18: 143.268 | G18: 345.408 | H18: 92.426
B19: Cash flows from operations | C19: 2408.661 | D19: 2556.212 | E19: 2320.847 | F19: 1775.176 | G19: 1817.452 | H19: 1397.341
A21: Net (Investments in) or Liquidation of Operating or Investment Non-Current Assets | B21: Investments in intangible assets | C21: -121.807 | D21: -74.19 | E21: -26.898 | F21: -78.068 | G21: -87.967 | H21: -79.101
A22: Net (Investments in) or Liquidation of Operating or Investment Non-Current Assets | B22: Investments in property, plant and equipment | C22: -1081.867 | D22: -616.551 | E22: -460.995 | F22: -851.973 | G22: -850.109 | H22: -783.598
A23: Net (Investments in) or Liquidation of Operating or Investment Non-Current Assets | B23: Acquisition of subsidiaries | C23: -105.718 | D23: 0 | E23: 0 | F23: -6.102 | G23: -7.147 | H23: -28.688
A24: Net (Investments in) or Liquidation of Operating or Investment Non-Current Assets | B24: Acquisition of other financial investments | C24: -12.597 | D24: -25.845 | E24: 0.378 | F24: 21.758 | G24: -10.307 | H24: -6.114
A25: Net (Investments in) or Liquidation of Operating or Investment Non-Current Assets | B25: Investments in other assets | C25: -26.747 | D25: -37.294 | E25: -12.59 | F25: -23.643 | G25: -26.572 | H25: -16.094
A26: Net (Investments in) or Liquidation of Operating or Investment Non-Current Assets | B26: Fixed asset sales and retirements | C26: 0 | D26: 0 | E26: -9.645 | F26: 0.679 | G26: 9.536 | H26: 26.56
A27: Net (Investments in) or Liquidation of Operating or Investment Non-Current Assets | B27: Disposals of entities | C27: 0 | D27: 0 | E27: 0 | F27: 0 | G27: 30.712 | H27: 0
B28: Cash flows from investing activities | C28: -1348.736 | D28: -753.88 | E28: -509.75 | F28: -937.349 | G28: -941.854 | H28: -887.035
A30: Net Debt (Repayment) or Issuance | B30: Decrease/increase in non-current financial debt | C30: -23.223 | D30: -0.824 | E30: -3.52 | F30: -28.644 | G30: -16.513 | H30: -28.226
A31: Net Debt (Repayment) or Issuance | B31: Decrease/increase in non-current non-financial debt | C31: -0.107 | D31: -33.455 | E31: 10.519 | F31: 11.366 | G31: 15.763 | H31: -67.143
A32: Net Debt (Repayment) or Issuance | B32: Decrease/increase in current financial debt | C32: -14.212 | D32: -32.459 | E32: -203.777 | F32: -137.385 | G32: 214.514 | H32: -64.115
A33: Dividend (Payments) | B33: Dividends | C33: -1003.877 | D33: -751.357 | E33: -662.09 | F33: -661.566 | G33: -521.591 | H33: -417.632
A34: Net Share (Repurchase) or Issuance | B34: Other financing activities | C34: 0.617 | D34: -0.667 | E34: 0.316 | F34: -1.997 | G34: 0.518 | H34: 0
B35: Cash flows used in financing activities | C35: -1040.802 | D35: -818.762 | E35: -858.552 | F35: -818.226 | G35: -307.309 | H35: -577.116
B37: Effect of exchange rate fluctuations on cash and cash equivalents | C37: 14.178 | D37: 29.769 | E37: 1.274 | F37: -19.142 | G37: -8.603 | H37: -15.446
B38: Net (decrease) increase in cash and cash equivalents | C38: 33.301 | D38: 1013.339 | E38: 953.819 | F38: 0.459 | G38: 559.686 | H38: -82.256
B39: Cash and cash equivalents at opening date | C39: 3433.452 | D39: 2420.11 | E39: 1466.291 | F39: 1465.835 | G39: 906.148 | H39: 988.408
B40: Cash and cash equivalents at closing date | C40: 3466.753 | D40: 3433.449 | E40: 2420.11 | F40: 1466.294 | G40: 1465.834 | H40: 906.152

Sheet Standardized Statements
A1: STANDARDIZED INCOME STATEMENT | B1: FY 2021 | C1: FY 2020 | D1: FY 2019 | E1: FY 2018 | F1: FY 2017 | G1: FY 2016 | I1: Standard Accounts
B2: =DSUM('Income Statements'!$A:$H,B$1,$I$1:$I$2) -> 17125.99 | C2: =DSUM('Income Statements'!$A:$H,C$1,$I$1:$I$2) -> 15494.198 | D2: =DSUM('Income Statements'!$A:$H,D$1,$I$1:$I$2) -> 12411.875 | E2: =DSUM('Income Statements'!$A:$H,E$1,$I$1:$I$2) -> 11611.139 | F2: =DSUM('Income Statements'!$A:$H,F$1,$I$1:$I$2) -> 11143.709 | G2: =DSUM('Income Statements'!$A:$H,G$1,$I$1:$I$2) -> 9302.275
A3: Revenue | B3: 13792.612 | C3: 12524.827 | D3: 11080.814 | E3: 10404.222 | F3: 9432.992 | G3: 8194.518
A4: Cost of Sales (function) | B4: 0 | C4: 0 | D4: 0 | E4: 0 | F4: 0 | G4: 0
A5: SG&A (function) | B5: 0 | C5: 0 | D5: 0 | E5: 0 | F5: 0 | G5: 0
A6: Other Operating Income, Net of Other Operating Expenses (function) | B6: -2688.546 | C6: -2446.386 | D6: -2162.188 | E6: -2024.196 | F6: -1726.968 | G6: -1566.458
A7: Personnel Expenses (nature) | B7: -2234.178 | C7: -2009.429 | D7: -1791.632 | E7: -1703.188 | F7: -1472.9 | G7: -1250.845
A8: Cost of Materials (nature) | B8: -5612.216 | C8: -5104.573 | D8: -4755.505 | E8: -4492.72 | F8: -4085.959 | G8: -3589.276
A9: Depreciation and Amortization (nature) | B9: -735.666 | C9: -675.738 | D9: -645.801 | E9: -578.32 | F9: -496.663 | G9: -433.427
A10: Interest Expense | B10: -3.672 | C10: -3.561 | D10: -9.428 | E10: -9.372 | F10: -4.659 | G10: -10.993
A11: Interest Income | B11: 30.237 | C11: 21.026 | D11: 8.368 | E11: 26.067 | F11: 20.603 | G11: 16.425
A12: Investment Income | B12: -10.039 | C12: 1.999 | D12: 3.011 | E12: 2.915 | F12: -5.686 | G12: -0.816
A13: Other Income, Net of Other Expense | B13: 20.48 | C13: 13.42 | D13: 4.531 | E13: -38.471 | F13: -15.124 | G13: -19.689
A14: Tax Expense | B14: -613.48 | C14: -580.305 | D14: -410.033 | E14: -325.322 | F14: -387.872 | G14: -329.502
... A17: Profit/Loss to Ordinary Shareholders | B17: 1932.288 | C17: 1731.829 | D17: 1314.354 | E17: 1253.451 | F17: 1250.269 | G17: 1001.541
A19: STANDARDIZED BALANCE SHEET - ASSETS
B20: =DSUM('Balance Sheets'!A:H,B$1,$I$1:$I$2) -> 65755.068 | C20: =DSUM('Balance Sheets'!A:H,C$1,$I$1:$I$2) -> 58956.477 | D20: =DSUM('Balance Sheets'!A:H,D$1,$I$1:$I$2) -> 50012.622 | E20: =DSUM('Balance Sheets'!A:H,E$1,$I$1:$I$2) -> 46659.876 | F20: =DSUM('Balance Sheets'!A:H,F$1,$I$1:$I$2) -> 42633.012 | G20: =DSUM('Balance Sheets'!A:H,G$1,$I$1:$I$2) -> 34452.972
A21: Cash and Cash Equivalents | B21: 3466.752 | C21: 3433.452 | D21: 2420.11 | E21: 1466.291 | F21: 1465.835 | G21: 906.148
A22: Trade Receivables | B22: 531.048 | C22: 481.844 | D22: 421.781 | E22: 585.311 | F22: 463.716 | G22: 363.635
A23: Inventories | B23: 1277.009 | C23: 1214.623 | D23: 992.57 | E23: 1054.84 | F23: 1007.213 | G23: 823.903
A24: Other Current Assets | B24: 162.48 | C24: 72.593 | D24: 109.334 | E24: 157.599 | F24: 44.831 | G24: 54.646
A25: Non-Current Tangible Assets | B25: 4063.066 | C25: 3397.083 | D25: 3293.535 | E25: 3442.321 | F25: 3182.112 | G25: 2788.816
A26: Non-Current Intangible Assets | B26: 832.202 | C26: 687.435 | D26: 664.962 | E26: 679.629 | F26: 643.531 | G26: 568.408
A27: Minority Equity Investments | B27: 0 | C27: 0 | D27: 0 | E27: 0 | F27: 0 | G27: 0
A28: Other Non-Operating Investments | B28: 270.249 | C28: 239.7 | D28: 198.942 | E28: 187.555 | F28: 165.344 | G28: 147.755
A29: Deferred Tax Assets | B29: 356.372 | C29: 299.35 | D29: 234.203 | E29: 203.1 | F29: 133.02 | G29: 88.851
A30: Derivatives - Asset | B30: 0 | C30: 0 | D30: 0 | E30: 0 | F30: 0 | G30: 0
A31: Assets Held For Sale | B31: 0 | C31: 0 | D31: 0 | E31: 0 | F31: 0 | G31: 0
A32: Total Assets | B32: 10959.178 | C32: 9826.08 | D32: 8335.437 | E32: 7776.646 | F32: 7105.602 | G32: 5742.162
A34: STANDARDIZED BALANCE SHEET - EQUITY & LIABILITIES
B35: =DSUM('Balance Sheets'!A:H,B$1,$I$1:$I$2) -> 65755.068 | C35: =DSUM('Balance Sheets'!A:H,C$1,$I$1:$I$2) -> 58956.477 | D35: =DSUM('Balance Sheets'!A:H,D$1,$I$1:$I$2) -> 50012.622 | E35: =DSUM('Balance Sheets'!A:H,E$1,$I$1:$I$2) -> 46659.876 | F35: =DSUM('Balance Sheets'!A:H,F$1,$I$1:$I$2) -> 42633.012 | G35: =DSUM('Balance Sheets'!A:H,G$1,$I$1:$I$2) -> 34452.972
A36: Current Debt | B36: 0.686 | C36: 2.682 | D36: 35.058 | E36: 234.037 | F36: 371.276 | G36: 145.077
A37: Trade Payables | B37: 2498.02 | C37: 2458.857 | D37: 2103.029 | E37: 2073.141 | F37: 1975.251 | G37: 1618.825
A38: Other Current Liabilities | B38: 204.068 | C38: 213.368 | D38: 166.873 | E38: 83.67 | F38: 111.54 | G38: 120.839
A39: Non-Current Debt | B39: 148.862 | C39: 160.782 | D39: 132.05 | E39: 115.061 | F39: 89.839 | G39: 92.428
A40: Deferred Tax Liabilities | B40: 182.531 | C40: 172.648 | D40: 172.892 | E40: 213.847 | F40: 110.957 | G40: 104.319
A41: Derivatives - Liability | B41: 0 | C41: 0 | D41: 0 | E41: 0 | F41: 0 | G41: 0
A42: Other Non-Current Liabilities (non interest bearing) | B42: 469.434 | C42: 394.575 | D42: 354.989 | E42: 308.29 | F42: 229.488 | G42: 190.07
A43: Non-Controlling Interest in Equity | B43: 40.771 | C43: 36.984 | D43: 41.38 | E43: 26.886 | F43: 23.922 | G43: 22.227
A44: Preference Shares | B44: 0 | C44: 0 | D44: 0 | E44: 0 | F44: 0 | G44: 0
...
