Workbook
Name asd: #REF!
Name Forecast: #REF!
Name Forecast: #REF!
Name IQ_CH: 110000
Name IQ_CQ: 5000
Name IQ_CY: 10000
Name IQ_DAILY: 500000
Name IQ_FH: 100000
Name IQ_FQ: 500
Name IQ_FY: 1000
Name IQ_LTM: 2000
Name IQ_MONTH: 15000
Name IQ_NTM: 6000
Name IQ_WEEK: 50000
Name IQ_YTD: 3000
Name rampup: #REF!
Name Step_1: #REF!
Name Step_1: #REF!
Name Step_2: #REF!
Name Step_2: #REF!
Name Step_3: #REF!
Name Step_3: #REF!
Name Step_4: #REF!
Name Step_4: #REF!
Name Step_5: #REF!
Name Step_5: #REF!
Name Step_6: #REF!
Name Step_6: #REF!
Name Step1: #REF!
Name Step2: #REF!
Name Step3: #REF!
Name Step4: #REF!
Name Step5: #REF!
Name Step6: #REF!

Sheet BioNTech Financial Analysis>>>
B45: <<< End of sheet >>>

Sheet Adjustments Slide Output
C2: BioNTech | E2: Astra Zeneca | G2: Moderna | I2: Sanofi | K2: GSK | M2: Takeda
B3: Depreciation policy adjustment | C3: 2020 | D3: =C3+3 -> 2023 | E3: 2020 | F3: =E3+3 -> 2023 | G3: 2020 | H3: =G3+3 -> 2023 | I3: 2020 | J3: =I3+3 -> 2023 | K3: 2020 | L3: =K3+3 -> 2023 | M3: 2020 | N3: =M3+3 -> 2023
B4: PP/E over PP/E + intangibles | C4: ='BionTech Ratios'!H40 -> 0.62342945 | D4: ='BionTech Ratios'!K40 -> 0.79022248 | E4: ='Astra Zeneca Ratios'!H40 -> 0.21842537 | F4: ='Astra Zeneca Ratios'!K40 -> 0.14906814 | G4: ='Moderna Ratios'!H40 -> 0.95768087 | H4: ='Moderna Ratios'!K40 -> 0.69335496 | I4: ='Sanofi Ratios'!H40 -> 0.15729014 | J4: ='Sanofi Ratios'!K40 -> 0.14776535 | K4: ='GSK Ratios'!H40 -> 0.22872429 | L4: ='GSK Ratios'!K40 -> 0.33536586 | M4: ='Takeda Ratios'!H40 -> 0.15609811 | N4: ='Takeda Ratios'!K40 -> 0.19112822
B5: Depreciation (% of non-current operating assets) | C5: ='BionTech Ratios'!H38 -> 0.16295011 | D5: ='BionTech Ratios'!K38 -> 0.17511697 | E5: ='Astra Zeneca Ratios'!H38 -> 0.063550355 | F5: ='Astra Zeneca Ratios'!K38 -> 0.052849078 | G5: ='Moderna Ratios'!H38 -> 0.1402021 | H5: ='Moderna Ratios'!K38 -> 0.26347133 | I5: ='Sanofi Ratios'!H38 -> 0.043580406 | J5: ='Sanofi Ratios'!K38 -> 0.03634536 | K5: ='GSK Ratios'!H38 -> 0.052812283 | L5: ='GSK Ratios'!K38 -> 0.039171095 | M5: ='Takeda Ratios'!H38 -> 0.018164495 | N5: ='Takeda Ratios'!K38 -> 0.012150903
B6: Implied useful life | C6: ='BionTech Ratios'!H39 -> 6.1368475 | D6: ='BionTech Ratios'!K39 -> 5.7104689 | E6: ='Astra Zeneca Ratios'!H39 -> 15.735553 | F6: ='Astra Zeneca Ratios'!K39 -> 18.921806 | G6: ='Moderna Ratios'!H39 -> 7.1325606 | H6: ='Moderna Ratios'!K39 -> 3.7954793 | I6: ='Sanofi Ratios'!H39 -> 22.946092 | J6: ='Sanofi Ratios'!K39 -> 27.513829 | K6: ='GSK Ratios'!H39 -> 18.934989 | L6: ='GSK Ratios'!K39 -> 25.529028 | M6: ='Takeda Ratios'!H39 -> 55.052453 | N6: ='Takeda Ratios'!K39 -> 82.298412

Sheet Dashboard Slide Output
C2: BioNTech | H2: Astra Zeneca | M2: Moderna | R2: Sanofi | W2: GSK | AB2: Takeda | AH2: Industry avg.* | AI2: BioNTech | AJ2: Industry avg.* | AK2: BioNTech | AL2: Industry avg.* | AM2: BioNTech | AN2: Industry avg.* | AO2: BioNTech | AP2: Industry avg.* | AQ2: BioNTech | AS2: *excluding Moderna
B3: Ratio analysis | C3: 2019 | D3: 2020 | E3: 2021 | F3: 2022 | G3: 2023 | H3: 2019 | I3: 2020 | J3: 2021 | K3: 2022 | L3: 2023 | M3: 2019 | N3: 2020 | O3: 2021 | P3: 2022 | Q3: 2023 | R3: 2019 | S3: 2020 | T3: 2021 | U3: 2022 | V3: 2023 | W3: 2019 | X3: 2020 | Y3: 2021 | Z3: 2022 | AA3: 2023 | AB3: 2019 | AC3: 2020 | AD3: 2021 | AE3: 2022 | AF3: 2023 | AH3: 2019 | AI3: =AH3 -> 2019 | AJ3: 2020 | AK3: =AJ3 -> 2020 | AL3: 2021 | AM3: =AL3 -> 2021 | AN3: 2022 | AO3: =AN3 -> 2022 | AP3: 2023 | AQ3: =AP3 -> 2023
A5: x | B5: Decomposition of ROE
B6: Net profit margin (ROS) | C6: =+'BionTech Ratios'!G8 -> -1.6500921 | D6: =+'BionTech Ratios'!H8 -> 0.031515654 | E6: =+'BionTech Ratios'!I8 -> 0.54237565 | F6: =+'BionTech Ratios'!J8 -> 0.54500711 | G6: =+'BionTech Ratios'!K8 -> 0.2435978 | H6: =+'Astra Zeneca Ratios'!G8 -> 0.050319815 | I6: =+'Astra Zeneca Ratios'!H8 -> 0.11811994 | J6: =+'Astra Zeneca Ratios'!I8 -> 0.0030734728 | K6: =+'Astra Zeneca Ratios'!J8 -> 0.074248582 | L6: =+'Astra Zeneca Ratios'!K8 -> 0.13012158 | M6: =+'Moderna Ratios'!G8 -> -8.5666978 | N6: =+'Moderna Ratios'!H8 -> -0.93026056 | O6: =+'Moderna Ratios'!I8 -> 0.66060313 | P6: =+'Moderna Ratios'!J8 -> 0.43409645 | Q6: =+'Moderna Ratios'!K8 -> -0.68837627 | R6: =+'Sanofi Ratios'!G8 -> 0.076692089 | S6: =+'Sanofi Ratios'!H8 -> 0.32995263 | T6: =+'Sanofi Ratios'!I8 -> 0.16028079 | U6: =+'Sanofi Ratios'!J8 -> 0.20055081 | V6: =+'Sanofi Ratios'!K8 -> 0.12401177 | W6: =+'GSK Ratios'!G8 -> 0.15607038 | X6: =+'GSK Ratios'!H8 -> 0.20953439 | Y6: =+'GSK Ratios'!I8 -> 0.14237124 | Z6: =+'GSK Ratios'!J8 -> 0.16781473 | AA6: =+'GSK Ratios'!K8 -> 0.17501982 | AB6: =+'Takeda Ratios'!G8 -> 0.0041569725 | AC6: =+'Takeda Ratios'!H8 -> 0.056447463 | AD6: =+'Takeda Ratios'!I8 -> 0.12656836 | AE6: =+'Takeda Ratios'!J8 -> 0.069595524 | AF6: =+'Takeda Ratios'!K8 -> 0.042774069 | AH6: =AVERAGE(H6,R6,W6,AB6) -> 0.071809814 | AI6: =C6 -> -1.6500921 | AJ6: =AVERAGE(I6,S6,X6,AC6) -> 0.17851361 | AK6: =D6 -> 0.031515654 | AL6: =AVERAGE(J6,T6,Y6,AD6) -> 0.10807347 | AM6: =E6 -> 0.54237565 | AN6: =AVERAGE(K6,U6,Z6,AE6) -> 0.12805241 | AO6: =F6 -> 0.54500711 | AP6: =AVERAGE(L6,V6,AA6,AF6) -> 0.11798181 | AQ6: =G6 -> 0.2435978
B7: × Asset turnover | C7: =+'BionTech Ratios'!G9 -> 0.14972774 | D7: =+'BionTech Ratios'!H9 -> 0.30953901 | E7: =+'BionTech Ratios'!I9 -> 2.0911655 | F7: =+'BionTech Ratios'!J9 -> 0.88522855 | G7: =+'BionTech Ratios'!K9 -> 0.16501964 | H7: =+'Astra Zeneca Ratios'!G9 -> 0.40464257 | I7: =+'Astra Zeneca Ratios'!H9 -> 0.42742084 | J7: =+'Astra Zeneca Ratios'!I9 -> 0.43007935 | K7: =+'Astra Zeneca Ratios'!J9 -> 0.46130157 | L7: =+'Astra Zeneca Ratios'!K9 -> 0.46620346 | M7: =+'Moderna Ratios'!G9 -> 0.034248392 | N7: =+'Moderna Ratios'!H9 -> 0.18999301 | O7: =+'Moderna Ratios'!I9 -> 1.1286351 | P7: =+'Moderna Ratios'!J9 -> 0.79871252 | Q7: =+'Moderna Ratios'!K9 -> 0.30996763 | R7: =+'Sanofi Ratios'!G9 -> 0.33593408 | S7: =+'Sanofi Ratios'!H9 -> 0.32917994 | T7: =+'Sanofi Ratios'!I9 -> 0.33389444 | U7: =+'Sanofi Ratios'!J9 -> 0.32639575 | V7: =+'Sanofi Ratios'!K9 -> 0.3247336 | W7: =+'GSK Ratios'!G9 -> 0.48508677 | X7: =+'GSK Ratios'!H9 -> 0.29814702 | Y7: =+'GSK Ratios'!I9 -> 0.31238223 | Z7: =+'GSK Ratios'!J9 -> 0.42471307 | AA7: =+'GSK Ratios'!K9 -> 0.51358952 | AB7: =+'Takeda Ratios'!G9 -> 0.34732494 | AC7: =+'Takeda Ratios'!H9 -> 0.25739257 | AD7: =+'Takeda Ratios'!I9 -> 0.27480826 | AE7: =+'Takeda Ratios'!J9 -> 0.29688703 | AF7: =+'Takeda Ratios'!K9 -> 0.29389344 | AH7: =AVERAGE(H7,R7,W7,AB7) -> 0.39324709 | AI7: =C7 -> 0.14972774 | AJ7: =AVERAGE(I7,S7,X7,AC7) -> 0.32803509 | AK7: =D7 -> 0.30953901 | AL7: =AVERAGE(J7,T7,Y7,AD7) -> 0.33779107 | AM7: =E7 -> 2.0911655 | AN7: =AVERAGE(K7,U7,Z7,AE7) -> 0.37732436 | AO7: =F7 -> 0.88522855 | AP7: =AVERAGE(L7,V7,AA7,AF7) -> 0.399605 | AQ7: =G7 -> 0.16501964
B8: = Return on assets (ROA) | C8: =+'BionTech Ratios'!G10 -> -0.24706456 | D8: =+'BionTech Ratios'!H10 -> 0.0097553243 | E8: =+'BionTech Ratios'!I10 -> 1.1341973 | F8: =+'BionTech Ratios'!J10 -> 0.48245585 | G8: =+'BionTech Ratios'!K10 -> 0.040198421 | H8: =+'Astra Zeneca Ratios'!G10 -> 0.02036154 | I8: =+'Astra Zeneca Ratios'!H10 -> 0.050486925 | J8: =+'Astra Zeneca Ratios'!I10 -> 0.0013218372 | K8: =+'Astra Zeneca Ratios'!J10 -> 0.034250988 | L8: =+'Astra Zeneca Ratios'!K10 -> 0.060663132 | M8: =+'Moderna Ratios'!G10 -> -0.29339562 | N8: =+'Moderna Ratios'!H10 -> -0.176743 | O8: =+'Moderna Ratios'!I10 -> 0.74557989 | P8: =+'Moderna Ratios'!J10 -> 0.34671827 | Q8: =+'Moderna Ratios'!K10 -> -0.21337436 | R8: =+'Sanofi Ratios'!G10 -> 0.025763487 | S8: =+'Sanofi Ratios'!H10 -> 0.10861379 | T8: =+'Sanofi Ratios'!I10 -> 0.053516865 | U8: =+'Sanofi Ratios'!J10 -> 0.065458933 | V8: =+'Sanofi Ratios'!K10 -> 0.040270789 | W8: =+'GSK Ratios'!G10 -> 0.075707677 | X8: =+'GSK Ratios'!H10 -> 0.062472055 | Y8: =+'GSK Ratios'!I10 -> 0.044474244 | Z8: =+'GSK Ratios'!J10 -> 0.071273111 | AA8: =+'GSK Ratios'!K10 -> 0.089888347 | AB8: =+'Takeda Ratios'!G10 -> 0.0014438202 | AC8: =+'Takeda Ratios'!H10 -> 0.014529158 | AD8: =+'Takeda Ratios'!I10 -> 0.034782031 | AE8: =+'Takeda Ratios'!J10 -> 0.020662009 | AF8: =+'Takeda Ratios'!K10 -> 0.012571019 | AH8: =AVERAGE(H8,R8,W8,AB8) -> 0.030819131 | AI8: =C8 -> -0.24706456 | AJ8: =AVERAGE(I8,S8,X8,AC8) -> 0.059025481 | AK8: =D8 -> 0.0097553243 | AL8: =AVERAGE(J8,T8,Y8,AD8) -> 0.033523744 | AM8: =E8 -> 1.1341973 | AN8: =AVERAGE(K8,U8,Z8,AE8) -> 0.04791126 | AO8: =F8 -> 0.48245585 | AP8: =AVERAGE(L8,V8,AA8,AF8) -> 0.050848322 | AQ8: =G8 -> 0.040198421
B9: × Financial Leverage | C9: =+'BionTech Ratios'!G11 -> 1.9074928 | D9: =+'BionTech Ratios'!H11 -> 1.6706483 | E9: =+'BionTech Ratios'!I11 -> 1.3681655 | F9: =+'BionTech Ratios'!J11 -> 1.2241238 | G9: =+'BionTech Ratios'!K11 -> 1.1484783 | H9: =+'Astra Zeneca Ratios'!G11 -> 4.2601848 | I9: =+'Astra Zeneca Ratios'!H11 -> 4.2358134 | J9: =+'Astra Zeneca Ratios'!I11 -> 3.1100648 | K9: =+'Astra Zeneca Ratios'!J11 -> 2.6426498 | L9: =+'Astra Zeneca Ratios'!K11 -> 2.5925688 | M9: =+'Moderna Ratios'!G11 -> 1.3132882 | N9: =+'Moderna Ratios'!H11 -> 2.3608836 | O9: =+'Moderna Ratios'!I11 -> 1.9055022 | P9: =+'Moderna Ratios'!J11 -> 1.512863 | Q9: =+'Moderna Ratios'!K11 -> 1.3430569 | R9: =+'Sanofi Ratios'!G11 -> 1.8943728 | S9: =+'Sanofi Ratios'!H11 -> 1.8536846 | T9: =+'Sanofi Ratios'!I11 -> 1.7738863 | U9: =+'Sanofi Ratios'!J11 -> 1.712851 | V9: =+'Sanofi Ratios'!K11 -> 1.6934952 | W9: =+'GSK Ratios'!G11 -> 6.1621251 | X9: =+'GSK Ratios'!H11 -> 4.0950431 | Y9: =+'GSK Ratios'!I11 -> 3.7823462 | Z9: =+'GSK Ratios'!J11 -> 4.4028177 | AA9: =+'GSK Ratios'!K11 -> 5.1978934 | AB9: =+'Takeda Ratios'!G11 -> 2.7161262 | AC9: =+'Takeda Ratios'!H11 -> 2.660841 | AD9: =+'Takeda Ratios'!I11 -> 2.5080938 | AE9: =+'Takeda Ratios'!J11 -> 2.2804708 | AF9: =+'Takeda Ratios'!K11 -> 2.1481836 | AH9: =AVERAGE(H9,R9,W9,AB9) -> 3.7582022 | AI9: =C9 -> 1.9074928 | AJ9: =AVERAGE(I9,S9,X9,AC9) -> 3.2113455 | AK9: =D9 -> 1.6706483 | AL9: =AVERAGE(J9,T9,Y9,AD9) -> 2.7935978 | AM9: =E9 -> 1.3681655 | AN9: =AVERAGE(K9,U9,Z9,AE9) -> 2.7596973 | AO9: =F9 -> 1.2241238 | AP9: =AVERAGE(L9,V9,AA9,AF9) -> 2.9080352 | AQ9: =G9 -> 1.1484783
B10: = Return on equity (ROE) | C10: =+'BionTech Ratios'!G12 -> -0.47127386 | D10: =+'BionTech Ratios'!H12 -> 0.016297716 | E10: =+'BionTech Ratios'!I12 -> 1.5517696 | F10: =+'BionTech Ratios'!J12 -> 0.59058571 | G10: =+'BionTech Ratios'!K12 -> 0.046167016 | H10: =+'Astra Zeneca Ratios'!G12 -> 0.086743921 | I10: =+'Astra Zeneca Ratios'!H12 -> 0.21385319 | J10: =+'Astra Zeneca Ratios'!I12 -> 0.0041109993 | K10: =+'Astra Zeneca Ratios'!J12 -> 0.090513366 | L10: =+'Astra Zeneca Ratios'!K12 -> 0.15727334 | M10: =+'Moderna Ratios'!G12 -> -0.385313 | N10: =+'Moderna Ratios'!H12 -> -0.41726965 | O10: =+'Moderna Ratios'!I12 -> 1.4207041 | P10: =+'Moderna Ratios'!J12 -> 0.52453725 | Q10: =+'Moderna Ratios'!K12 -> -0.2865739 | R10: =+'Sanofi Ratios'!G12 -> 0.048805648 | S10: =+'Sanofi Ratios'!H12 -> 0.20133571 | T10: =+'Sanofi Ratios'!I12 -> 0.094932833 | U10: =+'Sanofi Ratios'!J12 -> 0.1121214 | V10: =+'Sanofi Ratios'!K12 -> 0.068198388 | W10: =+'GSK Ratios'!G12 -> 0.46652018 | X10: =+'GSK Ratios'!H12 -> 0.25582575 | Y10: =+'GSK Ratios'!I12 -> 0.16821699 | Z10: =+'GSK Ratios'!J12 -> 0.31380252 | AA10: =+'GSK Ratios'!K12 -> 0.46723005 | AB10: =+'Takeda Ratios'!G12 -> 0.003921598 | AC10: =+'Takeda Ratios'!H12 -> 0.038659779 | AD10: =+'Takeda Ratios'!I12 -> 0.087236598 | AE10: =+'Takeda Ratios'!J12 -> 0.047119107 | AF10: =+'Takeda Ratios'!K12 -> 0.027004856 | AH10: =AVERAGE(H10,R10,W10,AB10) -> 0.15149784 | AI10: =C10 -> -0.47127386 | AJ10: =AVERAGE(I10,S10,X10,AC10) -> 0.17741861 | AK10: =D10 -> 0.016297716 | AL10: =AVERAGE(J10,T10,Y10,AD10) -> 0.088624355 | AM10: =E10 -> 1.5517696 | AN10: =AVERAGE(K10,U10,Z10,AE10) -> 0.1408891 | AO10: =F10 -> 0.59058571 | AP10: =AVERAGE(L10,V10,AA10,AF10) -> 0.17992666 | AQ10: =G10 -> 0.046167016
B12: Decomposition of RNOA
B13: Net Operating Profit Margin | C13: =+'BionTech Ratios'!G16 -> -1.6560866 | D13: =+'BionTech Ratios'!H16 -> 0.072266224 | E13: =+'BionTech Ratios'!I16 -> 0.54625377 | F13: =+'BionTech Ratios'!J16 -> 0.53943052 | G13: =+'BionTech Ratios'!K16 -> 0.2033603 | H13: =+'Astra Zeneca Ratios'!G16 -> 0.050319815 | I13: =+'Astra Zeneca Ratios'!H16 -> 0.11811994 | J13: =+'Astra Zeneca Ratios'!I16 -> 0.0030734728 | K13: =+'Astra Zeneca Ratios'!J16 -> 0.074248582 | L13: =+'Astra Zeneca Ratios'!K16 -> 0.13012158 | M13: =+'Moderna Ratios'!G16 -> -8.5666978 | N13: =+'Moderna Ratios'!H16 -> -0.93026056 | O13: =+'Moderna Ratios'!I16 -> 0.66060313 | P13: =+'Moderna Ratios'!J16 -> 0.43409645 | Q13: =+'Moderna Ratios'!K16 -> -0.68837627 | R13: =+'Sanofi Ratios'!G16 -> 0.076692089 | S13: =+'Sanofi Ratios'!H16 -> 0.32995263 | T13: =+'Sanofi Ratios'!I16 -> 0.16028079 | U13: =+'Sanofi Ratios'!J16 -> 0.20055081 | V13: =+'Sanofi Ratios'!K16 -> 0.12401177 | W13: =+'GSK Ratios'!G16 -> 0.15680007 | X13: =+'GSK Ratios'!H16 -> 0.21104585 | Y13: =+'GSK Ratios'!I16 -> 0.14366132 | Z13: =+'GSK Ratios'!J16 -> 0.16863215 | AA13: =+'GSK Ratios'!K16 -> 0.17613364 | AB13: =+'Takeda Ratios'!G16 -> 0.0052042531 | AC13: =+'Takeda Ratios'!H16 -> 0.058279239 | AD13: =+'Takeda Ratios'!I16 -> 0.12752956 | AE13: =+'Takeda Ratios'!J16 -> 0.070306446 | AF13: =+'Takeda Ratios'!K16 -> 0.043828044 | AH13: =AVERAGE(H13,R13,W13,AB13) -> 0.072254058 | AI13: =C13 -> -1.6560866 | AJ13: =AVERAGE(I13,S13,X13,AC13) -> 0.17934942 | AK13: =D13 -> 0.072266224 | AL13: =AVERAGE(J13,T13,Y13,AD13) -> 0.10863629 | AM13: =E13 -> 0.54625377 | AN13: =AVERAGE(K13,U13,Z13,AE13) -> 0.1284345 | AO13: =F13 -> 0.53943052 | AP13: =AVERAGE(L13,V13,AA13,AF13) -> 0.11852376 | AQ13: =G13 -> 0.2033603
B14: × Net Operating Asset Turnover | C14: =+'BionTech Ratios'!G17 -> -2.5810975 | D14: =+'BionTech Ratios'!H17 -> 2.0104252 | E14: =+'BionTech Ratios'!I17 -> 3.2012382 | F14: =+'BionTech Ratios'!J17 -> 1.8605481 | G14: =+'BionTech Ratios'!K17 -> 0.50939765 | H14: =+'Astra Zeneca Ratios'!G17 -> 0.76102786 | I14: =+'Astra Zeneca Ratios'!H17 -> 0.82850143 | J14: =+'Astra Zeneca Ratios'!I17 -> 0.71431685 | K14: =+'Astra Zeneca Ratios'!J17 -> 0.69730988 | L14: =+'Astra Zeneca Ratios'!K17 -> 0.71170839 | M14: =+'Moderna Ratios'!G17 -> -1.6970081 | N14: =+'Moderna Ratios'!H17 -> -0.73307656 | O14: =+'Moderna Ratios'!I17 -> -9.2139921 | P14: =+'Moderna Ratios'!J17 -> 25.812795 | Q14: =+'Moderna Ratios'!K17 -> 2.6697392 | R14: =+'Sanofi Ratios'!G17 -> 0.49359446 | S14: =+'Sanofi Ratios'!H17 -> 0.49168443 | T14: =+'Sanofi Ratios'!I17 -> 0.49004523 | U14: =+'Sanofi Ratios'!J17 -> 0.47768001 | V14: =+'Sanofi Ratios'!K17 -> 0.48197207 | W14: =+'GSK Ratios'!G17 -> 0.89187875 | X14: =+'GSK Ratios'!H17 -> 0.53721839 | Y14: =+'GSK Ratios'!I17 -> 0.58446901 | Z14: =+'GSK Ratios'!J17 -> 0.82239206 | AA14: =+'GSK Ratios'!K17 -> 1.0333967 | AB14: =+'Takeda Ratios'!G17 -> 0.46154454 | AC14: =+'Takeda Ratios'!H17 -> 0.33692916 | AD14: =+'Takeda Ratios'!I17 -> 0.36690055 | AE14: =+'Takeda Ratios'!J17 -> 0.39493164 | AF14: =+'Takeda Ratios'!K17 -> 0.36392835 | AH14: =AVERAGE(H14,R14,W14,AB14) -> 0.6520114 | AI14: =C14 -> -2.5810975 | AJ14: =AVERAGE(I14,S14,X14,AC14) -> 0.54858335 | AK14: =D14 -> 2.0104252 | AL14: =AVERAGE(J14,T14,Y14,AD14) -> 0.53893291 | AM14: =E14 -> 3.2012382 | AN14: =AVERAGE(K14,U14,Z14,AE14) -> 0.5980784 | AO14: =F14 -> 1.8605481 | AP14: =AVERAGE(L14,V14,AA14,AF14) -> 0.64775139 | AQ14: =G14 -> 0.50939765
B15: = Return on Net Operating Assets | C15: =+'BionTech Ratios'!G18 -> 4.2745209 | D15: =+'BionTech Ratios'!H18 -> 0.14528584 | E15: =+'BionTech Ratios'!I18 -> 1.7486885 | F15: =+'BionTech Ratios'!J18 -> 1.0036364 | G15: =+'BionTech Ratios'!K18 -> 0.10359126 | H15: =+'Astra Zeneca Ratios'!G18 -> 0.038294781 | I15: =+'Astra Zeneca Ratios'!H18 -> 0.097862539 | J15: =+'Astra Zeneca Ratios'!I18 -> 0.0021954334 | K15: =+'Astra Zeneca Ratios'!J18 -> 0.05177427 | L15: =+'Astra Zeneca Ratios'!K18 -> 0.092608624 | M15: =+'Moderna Ratios'!G18 -> 14.537755 | N15: =+'Moderna Ratios'!H18 -> 0.68195221 | O15: =+'Moderna Ratios'!I18 -> -6.086792 | P15: =+'Moderna Ratios'!J18 -> 11.205243 | Q15: =+'Moderna Ratios'!K18 -> -1.8377851 | R15: =+'Sanofi Ratios'!G18 -> 0.03785479 | S15: =+'Sanofi Ratios'!H18 -> 0.16223257 | T15: =+'Sanofi Ratios'!I18 -> 0.078544838 | U15: =+'Sanofi Ratios'!J18 -> 0.095799115 | V15: =+'Sanofi Ratios'!K18 -> 0.059770211 | W15: =+'GSK Ratios'!G18 -> 0.13984665 | X15: =+'GSK Ratios'!H18 -> 0.11337771 | Y15: =+'GSK Ratios'!I18 -> 0.083965592 | Z15: =+'GSK Ratios'!J18 -> 0.13868175 | AA15: =+'GSK Ratios'!K18 -> 0.18201593 | AB15: =+'Takeda Ratios'!G18 -> 0.0024019947 | AC15: =+'Takeda Ratios'!H18 -> 0.019635975 | AD15: =+'Takeda Ratios'!I18 -> 0.046790665 | AE15: =+'Takeda Ratios'!J18 -> 0.02776624 | AF15: =+'Takeda Ratios'!K18 -> 0.015950268 | AH15: =AVERAGE(H15,R15,W15,AB15) -> 0.054599555 | AI15: =TEXT(C15, "0%") & "**" -> 427%** | AJ15: =AVERAGE(I15,S15,X15,AC15) -> 0.0982772 | AK15: =D15 -> 0.14528584 | AL15: =AVERAGE(J15,T15,Y15,AD15) -> 0.052874132 | AM15: =E15 -> 1.7486885 | AN15: =AVERAGE(K15,U15,Z15,AE15) -> 0.078505342 | AO15: =F15 -> 1.0036364 | AP15: =AVERAGE(L15,V15,AA15,AF15) -> 0.087586259 | AQ15: =G15 -> 0.10359126
B17: Other key profitability ratios
B18: Gross profit margin | C18: =+'BionTech Ratios'!G44 -> 0.83977901 | D18: =+'BionTech Ratios'!H44 -> 0.87704748 | E18: =+'BionTech Ratios'!I44 -> 0.84657501 | F18: =+'BionTech Ratios'!J44 -> 0.82698462 | G18: =+'BionTech Ratios'!K44 -> 0.84294318 | H18: =+'Astra Zeneca Ratios'!G44 -> 0.80118109 | I18: =+'Astra Zeneca Ratios'!H44 -> 0.8029079 | J18: =+'Astra Zeneca Ratios'!I44 -> 0.67915655 | K18: =+'Astra Zeneca Ratios'!J44 -> 0.80516786 | L18: =+'Astra Zeneca Ratios'!K44 -> 0.82449631 | M18: =+'Moderna Ratios'!G44 -> -7.2666791 | N18: =+'Moderna Ratios'!H44 -> -0.71606449 | O18: =+'Moderna Ratios'!I44 -> 0.75052787 | P18: =+'Moderna Ratios'!J44 -> 0.5477859 | Q18: =+'Moderna Ratios'!K44 -> -0.39281547 | R18: =+'Sanofi Ratios'!G44 -> 0.68175175 | S18: =+'Sanofi Ratios'!H44 -> 0.67604164 | T18: =+'Sanofi Ratios'!I44 -> 0.68727505 | U18: =+'Sanofi Ratios'!J44 -> 0.7055131 | V18: =+'Sanofi Ratios'!K44 -> 0.69303559 | W18: =+'GSK Ratios'!G44 -> 0.68027493 | X18: =+'GSK Ratios'!H44 -> 0.69939229 | Y18: =+'GSK Ratios'!I44 -> 0.67472466 | Z18: =+'GSK Ratios'!J44 -> 0.67920476 | AA18: =+'GSK Ratios'!K44 -> 0.72342389 | AB18: =+'Takeda Ratios'!G44 -> 0.72106007 | AC18: =+'Takeda Ratios'!H44 -> 0.63973568 | AD18: =+'Takeda Ratios'!I44 -> 0.69065874 | AE18: =+'Takeda Ratios'!J44 -> 0.67810995 | AF18: =+'Takeda Ratios'!K44 -> 0.67761089 | AH18: =AVERAGE(H18,R18,W18,AB18) -> 0.72106696 | AI18: =C18 -> 0.83977901 | AJ18: =AVERAGE(I18,S18,X18,AC18) -> 0.70451938 | AK18: =D18 -> 0.87704748 | AL18: =AVERAGE(J18,T18,Y18,AD18) -> 0.68295375 | AM18: =E18 -> 0.84657501 | AN18: =AVERAGE(K18,U18,Z18,AE18) -> 0.71699892 | AO18: =F18 -> 0.82698462 | AP18: =AVERAGE(L18,V18,AA18,AF18) -> 0.72964167 | AQ18: =G18 -> 0.84294318
B19: EBITDA margin | C19: =+'BionTech Ratios'!G45 -> -1.9456722 | D19: =+'BionTech Ratios'!H45 -> -0.2477711 | E19: =+'BionTech Ratios'!I45 -> 0.80500298 | F19: =+'BionTech Ratios'!J45 -> 0.7423024 | G19: =+'BionTech Ratios'!K45 -> 0.26881383 | H19: =+'Astra Zeneca Ratios'!G45 -> -0.015830153 | I19: =+'Astra Zeneca Ratios'!H45 -> 0.068339722 | J19: =+'Astra Zeneca Ratios'!I45 -> -0.094288654 | K19: =+'Astra Zeneca Ratios'!J45 -> -0.039683441 | L19: =+'Astra Zeneca Ratios'!K45 -> 0.071314751 | M19: =+'Moderna Ratios'!G45 -> -10.105243 | N19: =+'Moderna Ratios'!H45 -> -1.1927205 | O19: =+'Moderna Ratios'!I45 -> 0.69896916 | P19: =+'Moderna Ratios'!J45 -> 0.46723082 | Q19: =+'Moderna Ratios'!K45 -> -0.59768452 | R19: =+'Sanofi Ratios'!G45 -> -0.0011161011 | S19: =+'Sanofi Ratios'!H45 -> 0.3053333 | T19: =+'Sanofi Ratios'!I45 -> 0.13268666 | U19: =+'Sanofi Ratios'!J45 -> 0.18214073 | V19: =+'Sanofi Ratios'!K45 -> 0.084093508 | W19: =+'GSK Ratios'!G45 -> 0.14113883 | X19: =+'GSK Ratios'!H45 -> 0.16276587 | Y19: =+'GSK Ratios'!I45 -> 0.090662441 | Z19: =+'GSK Ratios'!J45 -> 0.15359432 | AA19: =+'GSK Ratios'!K45 -> 0.15441182 | AB19: =+'Takeda Ratios'!G45 -> -0.0122057 | AC19: =+'Takeda Ratios'!H45 -> 0.064554723 | AD19: =+'Takeda Ratios'!I45 -> 0.13957242 | AE19: =+'Takeda Ratios'!J45 -> 0.054394059 | AF19: =+'Takeda Ratios'!K45 -> 0.062961157 | AH19: =AVERAGE(H19,R19,W19,AB19) -> 0.027996719 | AI19: =C19 -> -1.9456722 | AJ19: =AVERAGE(I19,S19,X19,AC19) -> 0.1502484 | AK19: =D19 -> -0.2477711 | AL19: =AVERAGE(J19,T19,Y19,AD19) -> 0.067158218 | AM19: =E19 -> 0.80500298 | AN19: =AVERAGE(K19,U19,Z19,AE19) -> 0.087611417 | AO19: =F19 -> 0.7423024 | AP19: =AVERAGE(L19,V19,AA19,AF19) -> 0.093195309 | AQ19: =G19 -> 0.26881383
B21: Asset management ratios
B22: PP&E turnover | C22: =+'BionTech Ratios'!G55 -> 0.82264002 | D22: =+'BionTech Ratios'!H55 -> 2.0304718 | E22: =+'BionTech Ratios'!I55 -> 44.039684 | F22: =+'BionTech Ratios'!J55 -> 25.41192 | G22: =+'BionTech Ratios'!K55 -> 4.057155 | H22: =+'Astra Zeneca Ratios'!G54 -> 2.8826184 | I22: =+'Astra Zeneca Ratios'!H54 -> 2.9046863 | J22: =+'Astra Zeneca Ratios'!I54 -> 3.5606724 | K22: =+'Astra Zeneca Ratios'!J54 -> 4.3295753 | L22: =+'Astra Zeneca Ratios'!K54 -> 4.2103907 | M22: =+'Moderna Ratios'!G54 -> 0.24270031 | N22: =+'Moderna Ratios'!H54 -> 2.45872 | O22: =+'Moderna Ratios'!I54 -> 20.393091 | P22: =+'Moderna Ratios'!J54 -> 11.390819 | Q22: =+'Moderna Ratios'!K54 -> 2.8748262 | R22: =+'Sanofi Ratios'!G54 -> 3.4977924 | S22: =+'Sanofi Ratios'!H54 -> 3.3081622 | T22: =+'Sanofi Ratios'!I54 -> 3.3024236 | U22: =+'Sanofi Ratios'!J54 -> 3.2112182 | V22: =+'Sanofi Ratios'!K54 -> 3.3061766 | W22: =+'GSK Ratios'!G54 -> 2.6853841 | X22: =+'GSK Ratios'!H54 -> 1.9642623 | Y22: =+'GSK Ratios'!I54 -> 2.0507632 | Z22: =+'GSK Ratios'!J54 -> 2.5668748 | AA22: =+'GSK Ratios'!K54 -> 2.7436194 | AB22: =+'Takeda Ratios'!G54 -> 2.9056943 | AC22: =+'Takeda Ratios'!H54 -> 1.9850567 | AD22: =+'Takeda Ratios'!I54 -> 1.9424458 | AE22: =+'Takeda Ratios'!J54 -> 2.0477972 | AF22: =+'Takeda Ratios'!K54 -> 1.9583968 | AH22: =AVERAGE(H22,R22,W22,AB22) -> 2.9928723 | AI22: =C22 -> 0.82264002 | AJ22: =AVERAGE(I22,S22,X22,AC22) -> 2.5405419 | AK22: =D22 -> 2.0304718 | AL22: =AVERAGE(J22,T22,Y22,AD22) -> 2.7140762 | AM22: =E22 -> 44.039684 | AN22: =AVERAGE(K22,U22,Z22,AE22) -> 3.0388664 | AO22: =F22 -> 25.41192 | AP22: =AVERAGE(L22,V22,AA22,AF22) -> 3.0546459 | AQ22: =G22 -> 4.057155
B24: Days’ receivables | C24: =+'BionTech Ratios'!G57 -> 51.134254 | D24: =+'BionTech Ratios'!H57 -> 66.212606 | E24: =+'BionTech Ratios'!I57 -> 119.01416 | F24: =+'BionTech Ratios'!J57 -> 203.04981 | G24: =+'BionTech Ratios'!K57 -> 438.39592 | H24: =+'Astra Zeneca Ratios'!G56 -> 48.013336 | I24: =+'Astra Zeneca Ratios'!H56 -> 48.61867 | J24: =+'Astra Zeneca Ratios'!I56 -> 47.85005 | K24: =+'Astra Zeneca Ratios'!J56 -> 51.413805 | L24: =+'Astra Zeneca Ratios'!K56 -> 60.981837 | M24: =+'Moderna Ratios'!G56 -> 52.979104 | N24: =+'Moderna Ratios'!H56 -> 291.83069 | O24: =+'Moderna Ratios'!I56 -> 45.259302 | P24: =+'Moderna Ratios'!J56 -> 40.48275 | Q24: =+'Moderna Ratios'!K56 -> 60.723784 | R24: =+'Sanofi Ratios'!G56 -> 72.691664 | S24: =+'Sanofi Ratios'!H56 -> 74.314004 | T24: =+'Sanofi Ratios'!I56 -> 69.192597 | U24: =+'Sanofi Ratios'!J56 -> 71.421199 | V24: =+'Sanofi Ratios'!K56 -> 73.810115 | W24: =+'GSK Ratios'!G56 -> 57.37516 | X24: =+'GSK Ratios'!H56 -> 83.399532 | Y24: =+'GSK Ratios'!I56 -> 85.600901 | Z24: =+'GSK Ratios'!J56 -> 71.252592 | AA24: =+'GSK Ratios'!K56 -> 66.965374 | AB24: =+'Takeda Ratios'!G56 -> 73.178707 | AC24: =+'Takeda Ratios'!H56 -> 89.046083 | AD24: =+'Takeda Ratios'!I56 -> 79.111858 | AE24: =+'Takeda Ratios'!J56 -> 65.931628 | AF24: =+'Takeda Ratios'!K56 -> 62.950564 | AH24: =AVERAGE(H24,R24,W24,AB24) -> 62.814717 | AI24: =C24 -> 51.134254 | AJ24: =AVERAGE(I24,S24,X24,AC24) -> 73.844572 | AK24: =D24 -> 66.212606 | AL24: =AVERAGE(J24,T24,Y24,AD24) -> 70.438852 | AM24: =E24 -> 119.01416 | AN24: =AVERAGE(K24,U24,Z24,AE24) -> 65.004806 | AO24: =F24 -> 203.04981 | AP24: =AVERAGE(L24,V24,AA24,AF24) -> 66.176972 | AQ24: =G24 -> 438.39592
B25: Days’ inventories | C25: =+'BionTech Ratios'!G59 -> 181.14828 | D25: =+'BionTech Ratios'!H59 -> 230.1511 | E25: =+'BionTech Ratios'!I59 -> 35.029366 | F25: =+'BionTech Ratios'!J59 -> 56.620367 | G25: =+'BionTech Ratios'!K59 -> 239.26976 | H25: =+'Astra Zeneca Ratios'!G58 -> 223.16319 | I25: =+'Astra Zeneca Ratios'!H58 -> 239.98693 | J25: =+'Astra Zeneca Ratios'!I58 -> 198.30319 | K25: =+'Astra Zeneca Ratios'!J58 -> 269.23669 | L25: =+'Astra Zeneca Ratios'!K58 -> 225.21954 | M25: =+IFERROR('Moderna Ratios'!G58,"N/A") -> N/A | N25: =+'Moderna Ratios'!H58 -> 5.722032 | O25: =+'Moderna Ratios'!I58 -> 71.934791 | P25: =+'Moderna Ratios'!J58 -> 56.74244 | Q25: =+'Moderna Ratios'!K58 -> 26.029634 | R25: =+'Sanofi Ratios'!G58 -> 232.53006 | S25: =+'Sanofi Ratios'!H58 -> 243.04312 | T25: =+'Sanofi Ratios'!I58 -> 250.75994 | U25: =+'Sanofi Ratios'!J58 -> 268.05123 | V25: =+'Sanofi Ratios'!K58 -> 265.68508 | W25: =+'GSK Ratios'!G58 -> 191.82484 | X25: =+'GSK Ratios'!H58 -> 299.59727 | Y25: =+'GSK Ratios'!I58 -> 261.50698 | Z25: =+'GSK Ratios'!J58 -> 206.94158 | AA25: =+'GSK Ratios'!K58 -> 226.50694 | AB25: =+'Takeda Ratios'!G58 -> 203.08273 | AC25: =+'Takeda Ratios'!H58 -> 236.29755 | AD25: =+'Takeda Ratios'!I58 -> 262.69105 | AE25: =+'Takeda Ratios'!J58 -> 249.61842 | AF25: =+'Takeda Ratios'!K58 -> 286.05073 | AH25: =AVERAGE(H25,R25,W25,AB25) -> 212.6502 | AI25: =C25 -> 181.14828 | AJ25: =AVERAGE(I25,S25,X25,AC25) -> 254.73122 | AK25: =D25 -> 230.1511 | AL25: =AVERAGE(J25,T25,Y25,AD25) -> 243.31529 | AM25: =E25 -> 35.029366 | AN25: =AVERAGE(K25,U25,Z25,AE25) -> 248.46198 | AO25: =F25 -> 56.620367 | AP25: =AVERAGE(L25,V25,AA25,AF25) -> 250.86557 | AQ25: =G25 -> 239.26976
B26: Days’ payables | C26: =+'BionTech Ratios'!G61 -> 643.64483 | D26: =+'BionTech Ratios'!H61 -> 372.74266 | E26: =+'BionTech Ratios'!I61 -> 16.216383 | F26: =+'BionTech Ratios'!J61 -> 21.882471 | G26: =+'BionTech Ratios'!K61 -> 167.48583 | H26: =+'Astra Zeneca Ratios'!G60 -> 128.13801 | I26: =+'Astra Zeneca Ratios'!H60 -> 136.98978 | J26: =+'Astra Zeneca Ratios'!I60 -> 78.061439 | K26: =+'Astra Zeneca Ratios'!J60 -> 106.62031 | L26: =+'Astra Zeneca Ratios'!K60 -> 129.30566 | M26: =+'Moderna Ratios'!G60 -> 13.640131 | N26: =+'Moderna Ratios'!H60 -> 3.1322775 | O26: =+'Moderna Ratios'!I60 -> 12.941357 | P26: =+'Moderna Ratios'!J60 -> 15.665963 | Q26: =+'Moderna Ratios'!K60 -> 18.897724 | R26: =+'Sanofi Ratios'!G60 -> 155.62124 | S26: =+'Sanofi Ratios'!H60 -> 157.72675 | T26: =+'Sanofi Ratios'!I60 -> 168.59848 | U26: =+'Sanofi Ratios'!J60 -> 197.04609 | V26: =+'Sanofi Ratios'!K60 -> 201.71012 | W26: =+'GSK Ratios'!G60 -> 130.88676 | X26: =+'GSK Ratios'!H60 -> 213.12799 | Y26: =+'GSK Ratios'!I60 -> 197.65539 | Z26: =+'GSK Ratios'!J60 -> 159.16614 | AA26: =+'GSK Ratios'!K60 -> 161.27504 | AB26: =+'Takeda Ratios'!G60 -> 107.95345 | AC26: =+'Takeda Ratios'!H60 -> 96.005125 | AD26: =+'Takeda Ratios'!I60 -> 114.90617 | AE26: =+'Takeda Ratios'!J60 -> 105.23813 | AF26: =+'Takeda Ratios'!K60 -> 117.94975 | AH26: =AVERAGE(H26,R26,W26,AB26) -> 130.64987 | AI26: =C26 -> 643.64483 | AJ26: =AVERAGE(I26,S26,X26,AC26) -> 150.96241 | AK26: =D26 -> 372.74266 | AL26: =AVERAGE(J26,T26,Y26,AD26) -> 139.80537 | AM26: =E26 -> 16.216383 | AN26: =AVERAGE(K26,U26,Z26,AE26) -> 142.01767 | AO26: =F26 -> 21.882471 | AP26: =AVERAGE(L26,V26,AA26,AF26) -> 152.56014 | AQ26: =G26 -> 167.48583
B27: Cash conversion cycle | C27: =+'BionTech Ratios'!G62 -> -411.3623 | D27: =+'BionTech Ratios'!H62 -> -76.378962 | E27: =+'BionTech Ratios'!I62 -> 137.82714 | F27: =+'BionTech Ratios'!J62 -> 237.7877 | G27: =+'BionTech Ratios'!K62 -> 510.17984 | H27: =+'Astra Zeneca Ratios'!G61 -> 143.03851 | I27: =+'Astra Zeneca Ratios'!H61 -> 151.61582 | J27: =+'Astra Zeneca Ratios'!I61 -> 168.09181 | K27: =+'Astra Zeneca Ratios'!J61 -> 214.03018 | L27: =+'Astra Zeneca Ratios'!K61 -> 156.89572 | M27: =+IFERROR('Moderna Ratios'!G61,"N/A") -> N/A | N27: =+'Moderna Ratios'!H61 -> 294.42044 | O27: =+'Moderna Ratios'!I61 -> 104.25274 | P27: =+'Moderna Ratios'!J61 -> 81.559227 | Q27: =+'Moderna Ratios'!K61 -> 67.855694 | R27: =+'Sanofi Ratios'!G61 -> 149.60048 | S27: =+'Sanofi Ratios'!H61 -> 159.63038 | T27: =+'Sanofi Ratios'!I61 -> 151.35405 | U27: =+'Sanofi Ratios'!J61 -> 142.42634 | V27: =+'Sanofi Ratios'!K61 -> 137.78507 | W27: =+'GSK Ratios'!G61 -> 118.31324 | X27: =+'GSK Ratios'!H61 -> 169.86881 | Y27: =+'GSK Ratios'!I61 -> 149.45249 | Z27: =+'GSK Ratios'!J61 -> 119.02804 | AA27: =+'GSK Ratios'!K61 -> 132.19727 | AB27: =+'Takeda Ratios'!G61 -> 168.30798 | AC27: =+'Takeda Ratios'!H61 -> 229.33851 | AD27: =+'Takeda Ratios'!I61 -> 226.89674 | AE27: =+'Takeda Ratios'!J61 -> 210.31192 | AF27: =+'Takeda Ratios'!K61 -> 231.05154 | AH27: =AVERAGE(H27,R27,W27,AB27) -> 144.81505 | AI27: =C27 -> -411.3623 | AJ27: =AVERAGE(I27,S27,X27,AC27) -> 177.61338 | AK27: =D27 -> -76.378962 | AL27: =AVERAGE(J27,T27,Y27,AD27) -> 173.94877 | AM27: =E27 -> 137.82714 | AN27: =AVERAGE(K27,U27,Z27,AE27) -> 171.44912 | AO27: =F27 -> 237.7877 | AP27: =AVERAGE(L27,V27,AA27,AF27) -> 164.4824 | AQ27: =G27 -> 510.17984
B29: Solvency ratios
B30: Debt-to-equity | C30: =+'BionTech Ratios'!G74 -> 0.097582881 | D30: =+'BionTech Ratios'!H74 -> 0.16850498 | E30: =+'BionTech Ratios'!I74 -> 0.040827711 | F30: =+'BionTech Ratios'!J74 -> 0.0160786 | G30: =+'BionTech Ratios'!K74 -> 0.010701835 | H30: =+'Astra Zeneca Ratios'!G73 -> 1.6311232 | I30: =+'Astra Zeneca Ratios'!H73 -> 1.62418 | J30: =+'Astra Zeneca Ratios'!I73 -> 1.1130268 | K30: =+'Astra Zeneca Ratios'!J73 -> 0.89164405 | L30: =+'Astra Zeneca Ratios'!K73 -> 0.83334241 | M30: =+'Moderna Ratios'!G73 -> 0.063100118 | N30: =+'Moderna Ratios'!H73 -> 0.10026805 | O30: =+'Moderna Ratios'!I73 -> 0.068760944 | P30: =+'Moderna Ratios'!J73 -> 0.063574341 | Q30: =+'Moderna Ratios'!K73 -> 0.073861217 | R30: =+'Sanofi Ratios'!G73 -> 0.48785355 | S30: =+'Sanofi Ratios'!H73 -> 0.4611698 | T30: =+'Sanofi Ratios'!I73 -> 0.39546276 | U30: =+'Sanofi Ratios'!J73 -> 0.3371618 | V30: =+'Sanofi Ratios'!K73 -> 0.2935554 | W30: =+'GSK Ratios'!G73 -> 2.8183341 | X30: =+'GSK Ratios'!H73 -> 1.6588459 | Y30: =+'GSK Ratios'!I73 -> 1.3748711 | Z30: =+'GSK Ratios'!J73 -> 1.6051355 | AA30: =+'GSK Ratios'!K73 -> 1.9148282 | AB30: =+'Takeda Ratios'!G73 -> 1.235481 | AC30: =+'Takeda Ratios'!H73 -> 1.1778722 | AD30: =+'Takeda Ratios'!I73 -> 0.99990007 | AE30: =+'Takeda Ratios'!J73 -> 0.82190953 | AF30: =+'Takeda Ratios'!K73 -> 0.79493856 | AH30: =AVERAGE(H30,R30,W30,AB30) -> 1.543198 | AI30: =C30 -> 0.097582881 | AJ30: =AVERAGE(I30,S30,X30,AC30) -> 1.230517 | AK30: =D30 -> 0.16850498 | AL30: =AVERAGE(J30,T30,Y30,AD30) -> 0.97081516 | AM30: =E30 -> 0.040827711 | AN30: =AVERAGE(K30,U30,Z30,AE30) -> 0.91396271 | AO30: =F30 -> 0.0160786 | AP30: =AVERAGE(L30,V30,AA30,AF30) -> 0.95916614 | AQ30: =G30 -> 0.010701835
B31: Debt-to-invested capital | C31: =+'BionTech Ratios'!G75 -> 0.088907072 | D31: =+'BionTech Ratios'!H75 -> 0.14420562 | E31: =+'BionTech Ratios'!I75 -> 0.039226195 | F31: =+'BionTech Ratios'!J75 -> 0.015824169 | G31: =+'BionTech Ratios'!K75 -> 0.010588518 | H31: =+'Astra Zeneca Ratios'!G74 -> 0.61993418 | I31: =+'Astra Zeneca Ratios'!H74 -> 0.61892857 | J31: =+'Astra Zeneca Ratios'!I74 -> 0.52674523 | K31: =+'Astra Zeneca Ratios'!J74 -> 0.47135932 | L31: =+'Astra Zeneca Ratios'!K74 -> 0.45454815 | M31: =+'Moderna Ratios'!G74 -> 0.059354821 | N31: =+'Moderna Ratios'!H74 -> 0.091130564 | O31: =+'Moderna Ratios'!I74 -> 0.064337066 | P31: =+'Moderna Ratios'!J74 -> 0.059774234 | Q31: =+'Moderna Ratios'!K74 -> 0.068780971 | R31: =+'Sanofi Ratios'!G74 -> 0.32789084 | S31: =+'Sanofi Ratios'!H74 -> 0.31561685 | T31: =+'Sanofi Ratios'!I74 -> 0.28339184 | U31: =+'Sanofi Ratios'!J74 -> 0.25214735 | V31: =+'Sanofi Ratios'!K74 -> 0.22693686 | W31: =+'GSK Ratios'!G74 -> 0.73810568 | X31: =+'GSK Ratios'!H74 -> 0.62389697 | Y31: =+'GSK Ratios'!I74 -> 0.57892451 | Z31: =+'GSK Ratios'!J74 -> 0.6161428 | AA31: =+'GSK Ratios'!K74 -> 0.6569266 | AB31: =+'Takeda Ratios'!G74 -> 0.55266898 | AC31: =+'Takeda Ratios'!H74 -> 0.54083623 | AD31: =+'Takeda Ratios'!I74 -> 0.49997502 | AE31: =+'Takeda Ratios'!J74 -> 0.45112533 | AF31: =+'Takeda Ratios'!K74 -> 0.44287787 | AH31: =AVERAGE(H31,R31,W31,AB31) -> 0.55964992 | AI31: =C31 -> 0.088907072 | AJ31: =AVERAGE(I31,S31,X31,AC31) -> 0.52481965 | AK31: =D31 -> 0.14420562 | AL31: =AVERAGE(J31,T31,Y31,AD31) -> 0.47225915 | AM31: =E31 -> 0.039226195 | AN31: =AVERAGE(K31,U31,Z31,AE31) -> 0.4476937 | AO31: =F31 -> 0.015824169 | AP31: =AVERAGE(L31,V31,AA31,AF31) -> 0.44532237 | AQ31: =G31 -> 0.010588518
B32: Interest coverage (earnings based) | C32: =+'BionTech Ratios'!G76 -> 87.7 | D32: =+'BionTech Ratios'!H76 -> 0.24307692 | E32: =+'BionTech Ratios'!I76 -> -51.31629 | F32: =+'BionTech Ratios'!J76 -> -687.40212 | G32: =+'BionTech Ratios'!K76 -> -51.627615 | H32: =+'Astra Zeneca Ratios'!G75 -> -3.9846139 | I32: =+'Astra Zeneca Ratios'!H75 -> -7.306234 | J32: =+'Astra Zeneca Ratios'!I75 -> -1.6585057 | K32: =+'Astra Zeneca Ratios'!J75 -> -4.7273693 | L32: =+'Astra Zeneca Ratios'!K75 -> -7.6595548 | M32: =+IFERROR('Moderna Ratios'!G75,"N/A") -> N/A | N32: =+'Moderna Ratios'!H75 -> 72.402577 | O32: =+'Moderna Ratios'!I75 -> -783.4839 | P32: =+'Moderna Ratios'!J75 -> -332.17392 | Q32: =+'Moderna Ratios'!K75 -> 101.73629 | R32: =+'Sanofi Ratios'!G75 -> -7.5275735 | S32: =+'Sanofi Ratios'!H75 -> -32.799564 | T32: =+'Sanofi Ratios'!I75 -> -23.649171 | U32: =+'Sanofi Ratios'!J75 -> -26.855721 | V32: =+'Sanofi Ratios'!K75 -> -12.382003 | W32: =+'GSK Ratios'!G75 -> -9.0935 | X32: =+'GSK Ratios'!H75 -> -8.125592 | Y32: =+'GSK Ratios'!I75 -> -6.7230976 | Z32: =+'GSK Ratios'!J75 -> -8.8717923 | AA32: =+'GSK Ratios'!K75 -> -10.540843 | AB32: =+'Takeda Ratios'!G75 -> -1.8134132 | AC32: =+'Takeda Ratios'!H75 -> -2.5530348 | AD32: =+'Takeda Ratios'!I75 -> -6.2806327 | AE32: =+'Takeda Ratios'!J75 -> -4.5850221 | AF32: =+'Takeda Ratios'!K75 -> -2.8923008 | AH32: =AVERAGE(H32,R32,W32,AB32) -> -5.6047752 | AI32: =C32 -> 87.7 | AJ32: =AVERAGE(I32,S32,X32,AC32) -> -12.696106 | AK32: =D32 -> 0.24307692 | AL32: =AVERAGE(J32,T32,Y32,AD32) -> -9.5778518 | AM32: =E32 -> -51.31629 | AN32: =AVERAGE(K32,U32,Z32,AE32) -> -11.259976 | AO32: =F32 -> -687.40212 | AP32: =AVERAGE(L32,V32,AA32,AF32) -> -8.3686754 | AQ32: =G32 -> -51.627615
B34: Sustainable growth rate
B35: ROE | C35: =+'BionTech Ratios'!G83 -> -0.47127386 | D35: =+'BionTech Ratios'!H83 -> 0.016297716 | E35: =+'BionTech Ratios'!I83 -> 1.5517696 | F35: =+'BionTech Ratios'!J83 -> 0.59058571 | G35: =+'BionTech Ratios'!K83 -> 0.046167016 | H35: =+'Astra Zeneca Ratios'!G82 -> 0.086743921 | I35: =+'Astra Zeneca Ratios'!H82 -> 0.21385319 | J35: =+'Astra Zeneca Ratios'!I82 -> 0.0041109993 | K35: =+'Astra Zeneca Ratios'!J82 -> 0.090513366 | L35: =+'Astra Zeneca Ratios'!K82 -> 0.15727334 | M35: =+'Moderna Ratios'!G82 -> -0.385313 | N35: =+'Moderna Ratios'!H82 -> -0.41726965 | O35: =+'Moderna Ratios'!I82 -> 1.4207041 | P35: =+'Moderna Ratios'!J82 -> 0.52453725 | Q35: =+'Moderna Ratios'!K82 -> -0.2865739 | R35: =+'Sanofi Ratios'!G82 -> 0.048805648 | S35: =+'Sanofi Ratios'!H82 -> 0.20133571 | T35: =+'Sanofi Ratios'!I82 -> 0.094932833 | U35: =+'Sanofi Ratios'!J82 -> 0.1121214 | V35: =+'Sanofi Ratios'!K82 -> 0.068198388 | W35: =+'GSK Ratios'!G82 -> 0.46652018 | X35: =+'GSK Ratios'!H82 -> 0.25582575 | Y35: =+'GSK Ratios'!I82 -> 0.16821699 | Z35: =+'GSK Ratios'!J82 -> 0.31380252 | AA35: =+'GSK Ratios'!K82 -> 0.46723005 | AB35: =+'Takeda Ratios'!G82 -> 0.003921598 | AC35: =+'Takeda Ratios'!H82 -> 0.038659779 | AD35: =+'Takeda Ratios'!I82 -> 0.087236598 | AE35: =+'Takeda Ratios'!J82 -> 0.047119107 | AF35: =+'Takeda Ratios'!K82 -> 0.027004856 | AH35: =AVERAGE(H35,R35,W35,AB35) -> 0.15149784 | AI35: =C35 -> -0.47127386 | AJ35: =AVERAGE(I35,S35,X35,AC35) -> 0.17741861 | AK35: =D35 -> 0.016297716 | AL35: =AVERAGE(J35,T35,Y35,AD35) -> 0.088624355 | AM35: =E35 -> 1.5517696 | AN35: =AVERAGE(K35,U35,Z35,AE35) -> 0.1408891 | AO35: =F35 -> 0.59058571 | AP35: =AVERAGE(L35,V35,AA35,AF35) -> 0.17992666 | AQ35: =G35 -> 0.046167016
B36: × Dividend payout ratio | C36: =+'BionTech Ratios'!G84 -> 0 | D36: =+'BionTech Ratios'!H84 -> 0 | E36: =+'BionTech Ratios'!I84 -> 0 | F36: =+'BionTech Ratios'!J84 -> 0.051333418 | G36: =+'BionTech Ratios'!K84 -> 0 | H36: =+'Astra Zeneca Ratios'!G83 -> 2.9274696 | I36: =+'Astra Zeneca Ratios'!H83 -> 1.1361328 | J36: =+'Astra Zeneca Ratios'!I83 -> 33.5304 | K36: =+'Astra Zeneca Ratios'!J83 -> 1.362284 | L36: =+'Astra Zeneca Ratios'!K83 -> 0.75339713 | M36: =+'Moderna Ratios'!G83 -> 0 | N36: =+'Moderna Ratios'!H83 -> 0 | O36: =+'Moderna Ratios'!I83 -> 0 | P36: =+'Moderna Ratios'!J83 -> 0 | Q36: =+'Moderna Ratios'!K83 -> 0 | R36: =+'Sanofi Ratios'!G83 -> 1.3284823 | S36: =+'Sanofi Ratios'!H83 -> 0.31930251 | T36: =+'Sanofi Ratios'!I83 -> 0.6383182 | U36: =+'Sanofi Ratios'!J83 -> 0.51565013 | V36: =+'Sanofi Ratios'!K83 -> 0.87367595 | W36: =+'GSK Ratios'!G83 -> 0 | X36: =+'GSK Ratios'!H83 -> 0 | Y36: =+'GSK Ratios'!I83 -> 0 | Z36: =+'GSK Ratios'!J83 -> 0 | AA36: =+'GSK Ratios'!K83 -> 0 | AB36: =+'Takeda Ratios'!G83 -> 20.917647 | AC36: =+'Takeda Ratios'!H83 -> 1.5671108 | AD36: =+'Takeda Ratios'!I83 -> 0.64215133 | AE36: =+'Takeda Ratios'!J83 -> 1.0186167 | AF36: =+'Takeda Ratios'!K83 -> 1.6177063 | AH36: =AVERAGE(H36,R36,W36,AB36) -> 6.2933997 | AI36: =C36 -> 0 | AJ36: =AVERAGE(I36,S36,X36,AC36) -> 0.75563653 | AK36: =D36 -> 0 | AL36: =AVERAGE(J36,T36,Y36,AD36) -> 8.7027175 | AM36: =E36 -> 0 | AN36: =AVERAGE(K36,U36,Z36,AE36) -> 0.7241377 | AO36: =F36 -> 0.051333418 | AP36: =AVERAGE(L36,V36,AA36,AF36) -> 0.81119485 | AQ36: =G36 -> 0
A37: x | B37: Sustainable growth rate | C37: =+'BionTech Ratios'!G85 -> -0.47127386 | D37: =+'BionTech Ratios'!H85 -> 0.016297716 | E37: =+'BionTech Ratios'!I85 -> 1.5517696 | F37: =+'BionTech Ratios'!J85 -> 0.56026893 | G37: =+'BionTech Ratios'!K85 -> 0.046167016 | H37: =+'Astra Zeneca Ratios'!G84 -> -0.16719627 | I37: =+'Astra Zeneca Ratios'!H84 -> -0.029112433 | J37: =+'Astra Zeneca Ratios'!I84 -> -0.13373245 | K37: =+'Astra Zeneca Ratios'!J84 -> -0.032791541 | L37: =+'Astra Zeneca Ratios'!K84 -> 0.038784058 | M37: {=IFERROR(+'Moderna Ratios'!G84,_xleta.N/A)} -> -0.385313 | N37: =+'Moderna Ratios'!H84 -> -0.41726965 | O37: =+'Moderna Ratios'!I84 -> 1.4207041 | P37: =+'Moderna Ratios'!J84 -> 0.52453725 | Q37: =+'Moderna Ratios'!K84 -> -0.2865739 | R37: =+'Sanofi Ratios'!G84 -> -0.016031793 | S37: =+'Sanofi Ratios'!H84 -> 0.13704871 | T37: =+'Sanofi Ratios'!I84 -> 0.034335478 | U37: =+'Sanofi Ratios'!J84 -> 0.054305986 | V37: =+'Sanofi Ratios'!K84 -> 0.0086150965 | W37: =+'GSK Ratios'!G84 -> 0.46652018 | X37: =+'GSK Ratios'!H84 -> 0.25582575 | Y37: =+'GSK Ratios'!I84 -> 0.16821699 | Z37: =+'GSK Ratios'!J84 -> 0.31380252 | AA37: =+'GSK Ratios'!K84 -> 0.46723005 | AB37: =+'Takeda Ratios'!G84 -> -0.078109003 | AC37: =+'Takeda Ratios'!H84 -> -0.021924379 | AD37: =+'Takeda Ratios'!I84 -> 0.0312175 | AE37: =+'Takeda Ratios'!J84 -> -0.00087720176 | AF37: =+'Takeda Ratios'!K84 -> -0.01668107 | AH37: =AVERAGE(H37,R37,W37,AB37) -> 0.051295779 | AI37: =C37 -> -0.47127386 | AJ37: =AVERAGE(I37,S37,X37,AC37) -> 0.085459413 | AK37: =D37 -> 0.016297716 | AL37: =AVERAGE(J37,T37,Y37,AD37) -> 0.025009379 | AM37: =E37 -> 1.5517696 | AN37: =AVERAGE(K37,U37,Z37,AE37) -> 0.08360994 | AO37: =F37 -> 0.56026893 | AP37: =AVERAGE(L37,V37,AA37,AF37) -> 0.12448703 | AQ37: =G37 -> 0.046167016

Sheet Football field
B2: Comps
B3: Metric | D3: Comps | F3: EV | G3: Net Debt | H3: Equity Value | I3: Shares | J3: Share Price | L3: Key Assumptions
B4: EV/ NTM Revenue | D4: ='Public comps'!J16 -> 2.7870309 | F4: =$Q4*D4 -> 7803.6865 | G4: =($N$6-$N$7) -> -15838.037 | H4: =+F4-G4 -> 23641.723 | I4: =$N$5 -> 239.9708 | J4: =H4/I4 -> 98.519165 | L4: Current Price | N4: ='DCF Model with IRR'!C25 -> 93.14232 | P4: Revenue (NTM) | Q4: ='DCF Model with IRR'!$H$31 -> 2800
B5: EV/ LTM Revenue | D5: ='Public comps'!H16 -> 2.4898284 | F5: =$Q5*D5 -> 9508.6545 | G5: =($N$6-$N$7) -> -15838.037 | H5: =+F5-G5 -> 25346.691 | I5: =$N$5 -> 239.9708 | J5: =H5/I5 -> 105.62406 | L5: Shares Outstanding (m) | N5: ='DCF Model with IRR'!C26 -> 239.9708 | P5: Revenue (LTM) | Q5: ='DCF Model with IRR'!$G$31 -> 3819
B6: P/E | D6: n.a. | L6: Net Debt ($000) | N6: =('Public comps'!F5-'Public comps'!E5) -> -15838.037 | P6: EBIT | Q6: ='DCF Model with IRR'!G39 -> 690.4
P7: Earnings | Q7: ='Public comps'!R5 -> -1207.431
B8: Lo | H8: =MIN(H4:H6) -> 23641.723 | I8: =$N$5 -> 239.9708 | J8: =H8/I8 -> 98.519165
B9: Hi | H9: =MAX(H4:H6) -> 25346.691 | I9: =$N$5 -> 239.9708 | J9: =H9/I9 -> 105.62406
B12: Football Field Data
D13: lo | E13: lo | F13: hi | G13: hi | J13: Price (model)
B14: Comps | D14: =J8 -> 98.519165 | E14: =J8 -> 98.519165 | F14: =J9 -> 105.62406 | G14: =J9 -> 105.62406 | J14: =AVERAGE(J4:J5) -> 102.07161
B15: PV of FCF | D15: =E15 -> 56.260757 | E15: =J15*$E$17 -> 56.260757 | F15: =J15*$F$17 -> 68.763148 | G15: =F15 -> 68.763148 | J15: ='DCF Model with IRR'!C64 -> 62.511953
B16: PV of ANOPAT | D16: =E16 -> 62.379103 | E16: =J16*$E$17 -> 62.379103 | F16: =J16*$F$17 -> 76.241126 | G16: =F16 -> 76.241126 | J16: ='DCF Model with IRR'!C90 -> 69.310114
E17: 0.9 | F17: 1.1 | I17: Avg. | J17: =AVERAGE(J14:J16) -> 77.96456
B21: Valuation Summary

Sheet >>>Valuation>>>

Sheet DCF Model with IRR
C2: Historicals | H2: Forecast
C3: 2019 | D3: =C3+1 -> 2020 | E3: =D3+1 -> 2021 | F3: =E3+1 -> 2022 | G3: =F3+1 -> 2023 | H3: =G3+1 -> 2024 | I3: =H3+1 -> 2025 | J3: =I3+1 -> 2026 | K3: =J3+1 -> 2027 | L3: =K3+1 -> 2028
H4: 1 | I4: 2 | J4: 3 | K4: 4 | L4: 5
A5: x | B5: Assumptions
B7: Income Statement
B8: Revenue Growth (% YoY) | C8: =('BionTech Adjusted'!G8/'BionTech Adjusted'!F8)-1 -> -0.14873604 | D8: =('BionTech Adjusted'!H8/'BionTech Adjusted'!G8)-1 -> 3.4410681 | E8: =('BionTech Adjusted'!I8/'BionTech Adjusted'!H8)-1 -> 38.346258 | F8: =('BionTech Adjusted'!J8/'BionTech Adjusted'!I8)-1 -> -0.087797141 | G8: =('BionTech Adjusted'!K8/'BionTech Adjusted'!J8)-1 -> -0.77938373 | H8: =('Revenue forecasts'!C46/G31)-1 -> -0.26682378 | I8: =('Revenue forecasts'!D46/'Revenue forecasts'!C46)-1 -> -0.19642857 | J8: =('Revenue forecasts'!E46/'Revenue forecasts'!D46)-1 -> -0.032222222 | K8: =('Revenue forecasts'!F46/'Revenue forecasts'!E46)-1 -> -0.085258324 | L8: =('Revenue forecasts'!G46/'Revenue forecasts'!F46)-1 -> 0.032168587 | M8: > Calculated in Revenue Forcast Sheet
B9: Cost of Goods Sold (% of Revenue) | C9: =C32/C31 -> -0.16022099 | D9: =D32/D31 -> -0.12295252 | E9: =E32/E31 -> -0.15342499 | F9: =F32/F31 -> -0.17301538 | G9: =G32/G31 -> -0.15705682 | H9: =AVERAGE(C9:G9) -> -0.15333414 | I9: =H9 -> -0.15333414 | J9: =I9 -> -0.15333414 | K9: =J9 -> -0.15333414 | L9: =K9 -> -0.15333414 | M9: > Based on Average of prior 5 years
B11: SG&A (% of Revenue) | C11: =C36/C31 -> -0.44383057 | D11: =D36/D31 -> -0.22496372 | E11: =E36/E31 -> -0.017242197 | F11: =F36/F31 -> -0.031264081 | G11: =G36/G31 -> -0.14603299 | H11: =G11 -> -0.14603299 | I11: =H11 -> -0.14603299 | J11: =I11 -> -0.14603299 | K11: =J11 -> -0.14603299 | L11: =K11 -> -0.14603299 | M11: > remains flat
B12: R&D (% of Revenue) | C12: =-C37/C31 -> 2.0856354 | D12: =-D37/D31 -> 1.3373419 | E12: =-E37/E31 -> 0.050019234 | F12: =-F37/F31 -> 0.088789528 | G12: =-G37/G31 -> 0.46690233 | H12: 0.8 | I12: 1.1764978 | J12: 1.1476739 | K12: 1.2021688 | L12: 1.1771782 | M12: > Analyst consensus
B13: Other Operating Income/ Expenses (% of Revenue) | C13: =C38/C31 -> 0.018416206 | D13: =D38/D31 -> 0.51441012 | E13: =E38/E31 -> 0.02608462 | F13: =F38/F31 -> 0.0234134 | G13: =G38/G31 -> -0.049227546 | H13: 0.02 | I13: 0.02 | J13: 0.02 | K13: 0.02 | L13: 0.02
B15: Other
B16: Tax Rate | H16: 0.3 | I16: 0.3 | J16: 0.3 | K16: 0.3 | L16: 0.3 | M16: > German tax rate
A18: x | B18: PV of FCF Valuation
B20: Assumptions
B21: Tax Rate | C21: ='WACC Analysis'!C12 -> 0.3
B22: WACC | C22: ='WACC Analysis'!C19 -> 0.086676583
B23: Perpetural Growth Rate | C23: 0.02
B24: EV / NTM Revenue Multiple | C24: ='Public comps'!J16 -> 2.7870309
B25: Current Price | C25: ='Public comps'!C5 -> 93.14232 | D25: *As of 25/03/2025
B26: Shares Outstanding (m) | C26: ='Public comps'!D5 -> 239.9708
B27: Cash | C27: ='BionTech Adjusted'!AM45 -> 11663.7
B28: Debt | C28: =SUM('BionTech Adjusted'!AN57,'BionTech Adjusted'!AN64) -> 0
B29: Terminal Revenue Growth Rate | C29: 0.05
B31: Revenue | C31: ='BionTech Adjusted'!AI8 -> 108.6 | D31: ='BionTech Adjusted'!AJ8 -> 482.3 | E31: ='BionTech Adjusted'!AK8 -> 18976.7 | F31: ='BionTech Adjusted'!AL8 -> 17310.6 | G31: ='BionTech Adjusted'!AM8 -> 3819 | H31: ='Revenue forecasts'!C46 -> 2800 | I31: ='Revenue forecasts'!D46 -> 2250 | J31: ='Revenue forecasts'!E46 -> 2177.5 | K31: ='Revenue forecasts'!F46 -> 1991.85 | L31: ='Revenue forecasts'!G46 -> 2055.925
B32: Cost of Goods Sold (COGS) | C32: ='BionTech Adjusted'!AI24 -> -17.4 | D32: ='BionTech Adjusted'!AJ24 -> -59.3 | E32: ='BionTech Adjusted'!AK24 -> -2911.5 | F32: ='BionTech Adjusted'!AL24 -> -2995 | G32: ='BionTech Adjusted'!AM24 -> -599.8 | H32: =H31*H9 -> -429.33559 | I32: =I31*I9 -> -345.00182 | J32: =J31*J9 -> -333.88509 | K32: =K31*K9 -> -305.41861 | L32: =L31*L9 -> -315.24349
B33: Gross Profit | C33: =C31+C32 -> 91.2 | D33: =D31+D32 -> 423 | E33: =E31+E32 -> 16065.2 | F33: =F31+F32 -> 14315.6 | G33: =G31+G32 -> 3219.2 | H33: =H31+H32 -> 2370.6644 | I33: =I31+I32 -> 1904.9982 | J33: =J31+J32 -> 1843.6149 | ... L33: =L31+L32 -> 1740.6815
B34: Gross Margin (%) | C34: =C33/C31 -> 0.83977901 | D34: =D33/D31 -> 0.87704748 | E34: =E33/E31 -> 0.84657501 | F34: =F33/F31 -> 0.82698462 | G34: =G33/G31 -> 0.84294318 | H34: =H33/H31 -> 0.84666586 | I34: =I33/I31 -> 0.84666586 | J34: =J33/J31 -> 0.84666586 | ... L34: =L33/L31 -> 0.84666586
B35: Operating Income/Expenses | C35: =SUM(C36:C38) -> -272.7 | D35: =SUM(D36:D38) -> -505.4 | E35: =SUM(E36:E38) -> -781.4 | F35: =SUM(F36:F38) -> -1672.9 | G35: =SUM(G36:G38) -> -2528.8 | H35: =SUM(H36:H38) -> -2592.8924 | I35: =SUM(I36:I38) -> -2930.6942 | J35: =SUM(J36:J38) -> -2773.4968 | ... L35: =SUM(L36:L38) -> -2679.3044
B36: SG&A | C36: ='BionTech Adjusted'!AI25 -> -48.2 | D36: ='BionTech Adjusted'!AJ25 -> -108.5 | E36: ='BionTech Adjusted'!AK25 -> -327.2 | F36: ='BionTech Adjusted'!AL25 -> -541.2 | G36: ='BionTech Adjusted'!AM25 -> -557.7 | H36: =H$31*H11 -> -408.89238 | I36: =I$31*I11 -> -328.57423 | J36: =J$31*J11 -> -317.98684 | K36: =K$31*K11 -> -290.87582 | L36: =L$31*L11 -> -300.23288
B37: R&D | C37: ='BionTech Adjusted'!AI26 -> -226.5 | D37: ='BionTech Adjusted'!AJ26 -> -645 | E37: ='BionTech Adjusted'!AK26 -> -949.2 | F37: ='BionTech Adjusted'!AL26 -> -1537 | G37: ='BionTech Adjusted'!AM26 -> -1783.1 | H37: =-H12*H31 -> -2240 | I37: =-I12*I31 -> -2647.12 | J37: =-J12*J31 -> -2499.06 | K37: =-K12*K31 -> -2394.54 | L37: =-L12*L31 -> -2420.19
B38: Other Operating Income/Expenses | C38: ='BionTech Adjusted'!AI27 -> 2 | D38: ='BionTech Adjusted'!AJ27 -> 248.1 | E38: ='BionTech Adjusted'!AK27 -> 495 | F38: ='BionTech Adjusted'!AL27 -> 405.3 | G38: ='BionTech Adjusted'!AM27 -> -188 | H38: =H$31*H13 -> 56 | I38: =I$31*I13 -> 45 | J38: =J$31*J13 -> 43.55 | K38: =K$31*K13 -> 39.837 | L38: =L$31*L13 -> 41.1185
B39: Operating Profit | C39: =C33+C35 -> -181.5 | D39: =D33+D35 -> -82.4 | E39: =E33+E35 -> 15283.8 | F39: =F33+F35 -> 12642.7 | G39: =G33+G35 -> 690.4 | H39: =H33+H35 -> -222.22797 | I39: =I33+I35 -> -1025.6961 | J39: =J33+J35 -> -929.88193 | ... L39: =L33+L35 -> -938.62287
B40: Operating Margin (%) | C40: =C39/C31 -> -1.6712707 | D40: =D39/D31 -> -0.17084802 | E40: =E39/E31 -> 0.8053982 | F40: =F39/F31 -> 0.73034441 | G40: =G39/G31 -> 0.18078031 | H40: =H39/H31 -> -0.079367133 | I40: =I39/I31 -> -0.45586491 | J40: =J39/J31 -> -0.42704107 | ... L40: =L39/L31 -> -0.45654529
B41: Taxes | C41: ='BionTech Adjusted'!AI16 -> 0.2 | D41: ='BionTech Adjusted'!AJ16 -> 161 | E41: ='BionTech Adjusted'!AK16 -> -4753.9 | F41: ='BionTech Adjusted'!AL16 -> -3519.7 | G41: ='BionTech Adjusted'!AM16 -> -255.8 | H41: =-H39*(H16) -> 66.668392 | I41: =-I39*(I16) -> 307.70882 | J41: =-J39*(J16) -> 278.96458 | K41: =-K39*(K16) -> 287.74423 | L41: =-L39*(L16) -> 281.58686
B42: NOPAT | C42: =SUM(C39:C41) -> -182.97127 | D42: =SUM(D39:D41) -> 78.429152 | E42: =SUM(E39:E41) -> 10530.705 | F42: =SUM(F39:F41) -> 9123.7303 | G42: =SUM(G39:G41) -> 434.78078 | H42: =SUM(H39:H41) -> -155.63895 | I42: =SUM(I39:I41) -> -718.4431 | J42: =SUM(J39:J41) -> -651.34439 | ... L42: =SUM(L39:L41) -> -657.49256
B43: Plus: D&A | H43: =-H117 -> 134.4 | I43: =-I117 -> 108 | J43: =-J117 -> 104.52 | K43: =-K117 -> 95.6088 | L43: =-L117 -> 98.6844
B44: Less: Capex | H44: =-H116 -> -168 | I44: =-I116 -> -135 | J44: =-J116 -> -130.65 | K44: =-K116 -> -119.511 | L44: =-L116 -> -123.3555
B45: Less: Changes in NWC | H45: =H107 -> 1677.8075 | I45: =I107 -> 94.598522 | J45: =J107 -> 12.469805 | K45: =K107 -> 31.931301 | L45: =L107 -> -11.020728
B46: Free Cash Flow | H46: =SUM(H42:H45) -> 1488.5686 | I46: =SUM(I42:I45) -> -650.84458 | J46: =SUM(J42:J45) -> -665.00459 | K46: =SUM(K42:K45) -> -663.85563 | L46: =SUM(L42:L45) -> -693.18438
B48: Discounted Free Cash Flow | H48: =H46/(1+$C$22)^H4 -> 1369.8359 | I48: =I46/(1+$C$22)^I4 -> -551.15871 | J48: =J46/(1+$C$22)^J4 -> -518.23139 | K48: =K46/(1+$C$22)^K4 -> -476.07175 | L48: =L46/(1+$C$22)^L4 -> -457.45379
...

Sheet Revenue forecasts
B2: Revenue by type (EUR m) | C2: 2024 | D2: 2025 | E2: 2026 | F2: 2027 | G2: 2028 | H2: 2029
A3: x | B3: Existing product sales (Comirnaty COVID-19) | C3: 2750 | D3: =C3*(1+D4) -> 2200 | E3: =D3*(1+E4) -> 1870 | F3: =E3*(1+F4) -> 1589.5 | G3: =F3*(1+G4) -> 1351.075 | H3: =G3*(1+H4) -> 1351.075
B4: Volume decline | D4: -0.2 | E4: -0.15 | F4: -0.15 | G4: -0.15 | I4: > normalisation of Covid vaccine market from ('29)
A6: x | B6: Pipeline product sales – oncology | E6: =E13+E21 -> 112.5 | F6: =F13+F21 -> 225 | G6: =G13+G21 -> 416.25 | H6: =H13+H21 -> 562.5
B7: BNT122 TAM (cases m) | E7: 0.15 | F7: 0.15 | G7: 0.15 | H7: 0.15
B8: Penetration (share) | E8: 0.05 | F8: =E8+0.05 -> 0.1 | G8: 0.17 | H8: =G8+0.05 -> 0.22
B9: BNT122 SOM (cases m) | E9: =E7*E8 -> 0.0075 | F9: =F7*F8 -> 0.015 | G9: =G7*G8 -> 0.0255 | H9: =H7*H8 -> 0.033
B11: BNT122 pricing | E11: 50000 | F11: 50000 | G11: 50000 | H11: 50000
B12: BNT122 PoS | E12: 0.3 | F12: 0.3 | G12: 0.3 | H12: 0.3
B13: BNT122 sales | E13: =E9*E11*E12 -> 112.5 | F13: =F9*F11*F12 -> 225 | G13: =G9*G11*G12 -> 382.5 | H13: =H9*H11*H12 -> 495
B15: BNT116 TAM (cases m) | G15: 0.1 | H15: 0.1
B16: Penetration (share) | G16: 0.03 | H16: 0.06
B17: BNT116 SOM (cases m) | G17: =G15*G16 -> 0.003 | H17: =H15*H16 -> 0.006
B19: BNT116 pricing | G19: 75000 | H19: 75000
B20: BNT116 PoS | G20: 0.15 | H20: 0.15
B21: BNT116 sales | G21: =G17*G19*G20 -> 33.75 | H21: =H17*H19*H20 -> 67.5
A23: x | B23: Pipeline product sales – new vaccines | E23: =E32+E40 -> 45 | F23: =F32+F40 -> 127.35 | G23: =G32+G40 -> 238.6 | H23: =H32+H40 -> 292.35
B24: Shingles vaccine market | G24: 5300 | H24: 6000
B25: Pricing | G25: 150 | H25: 150
B26: Shingles TAM (doses m) | G26: =G24/G25 -> 35.333333 | H26: =H24/H25 -> 40
B27: Penetration (share) | G27: 0.05 | H27: 0.05
B28: Shingles SOM (doses m) | G28: =G26*G27 -> 1.7666667 | H28: =H26*H27 -> 2
B30: Shingles pricing | G30: 150 | H30: 150
B31: Shingles PoS | G31: 0.25 | H31: 0.25
B32: Shingles sales | G32: =G28*G30*G31 -> 66.25 | H32: =H28*H30*H31 -> 75
B34: Flu TAM (doses m) | E34: 150 | F34: 150 | G34: 150 | H34: 150 | I34: > US & EU only
B35: Penetration (share) | E35: 0.02 | F35: =E35+0.0366 -> 0.0566 | G35: =F35+0.02 -> 0.0766 | H35: =G35+0.02 -> 0.0966
B36: Flu SOM (doses m) | E36: =E34*E35 -> 3 | F36: =F34*F35 -> 8.49 | G36: =G34*G35 -> 11.49 | H36: =H34*H35 -> 14.49
B38: Flu pricing | E38: 30 | F38: 30 | G38: 30 | H38: 30
B39: Flu PoS | E39: 0.5 | F39: 0.5 | G39: 0.5 | H39: 0.5
B40: Flu sales | E40: =E36*E38*E39 -> 45 | F40: =F36*F38*F39 -> 127.35 | G40: =G36*G38*G39 -> 172.35 | H40: =H36*H38*H39 -> 217.35
A42: x | B42: Partnership & milestone revenue | C42: =SUM(C43:C44) -> 50 | D42: =SUM(D43:D44) -> 50 | E42: =SUM(E43:E44) -> 150 | F42: =SUM(F43:F44) -> 50 | G42: =SUM(G43:G44) -> 50 | H42: =SUM(H43:H44) -> 50
B43: Collaboration revenue | C43: 50 | D43: 50 | E43: 50 | F43: 50 | G43: 50 | H43: 50
B44: Milestone bump | E44: 100
B46: Total revenue | C46: =C42+C23+C6+C3 -> 2800 | D46: =D42+D23+D6+D3 -> 2250 | E46: =E42+E23+E6+E3 -> 2177.5 | F46: =F42+F23+F6+F3 -> 1991.85 | G46: =G42+G23+G6+G3 -> 2055.925 | H46: =H42+H23+H6+H3 -> 2255.925

Sheet Public comps
B2: Date | D2: 45741
B3: (in EUR m)
A4: x | B4: Company name | C4: Price close | D4: Shares oust. (m) | E4: Market Cap | F4: Enterprise Value | G4: Revenue (LTM) | H4: EV / Revenue (LTM) | I4: Revenue (NTM) | J4: EV / Revenue (NTM) | K4: EBITDA (LTM) | L4: EV / EBITDA (LTM) | M4: EBITDA (NTM) | N4: EV / EBITDA (NTM) | O4: Net Income (LTM) | P4: EPS (LTM) | Q4: P / E (LTM) | R4: Net Income (NTM) | S4: EPS (NTM) | T4: P / E (NTM)
B5: BioNTech SE | C5: 93.14232 | D5: 239.9708 | E5: 22351.437 | F5: 6513.4007 | G5: 2751.1 | H5: =$F5/G5 -> 2.3675623 | I5: 2117.5833 | J5: =$F5/I5 -> 3.0758652 | K5: -1033.1 | L5: =$F5/K5 -> -6.3047146 | M5: -1492.0414 | N5: =$F5/M5 -> -4.3654288 | O5: -665.3 | P5: =O5/$D5 -> -2.7724206 | Q5: =C5/P5 -> -33.596028 | R5: -1207.431 | S5: =R5/D5 -> -5.0315748 | T5: =C5/S5 -> -18.511564
B7: Selected Biotech peers
B8: Moderna, Inc. | C8: 31.624335 | D8: 386.6226 | E8: 12226.683 | F8: 4108.1967 | G8: 2991.9574 | H8: =$F8/G8 -> 1.3730799 | I8: 2076.8646 | J8: =$F8/I8 -> 1.9780764 | K8: -3472.7417 | L8: =$F8/K8 -> -1.1829837 | M8: -3681.3596 | N8: =$F8/M8 -> -1.1159455 | O8: -3292.4476 | P8: =O8/$D8 -> -8.5159211 | Q8: =C8/P8 -> -3.7135542 | R8: -3750.8234 | S8: =R8/D8 -> -9.701511 | T8: =C8/S8 -> -3.259733
B9: AstraZeneca PLC | C9: 136.83143 | D9: 1550.6072 | E9: 212171.8 | F9: 236050.66 | G9: 49995.091 | H9: =$F9/G9 -> 4.7214768 | I9: 54519.631 | J9: =$F9/I9 -> 4.3296452 | K9: 16242.187 | L9: =$F9/K9 -> 14.533182 | M9: 19299.581 | N9: =$F9/M9 -> 12.23087 | O9: 6510.0038 | P9: =O9/$D9 -> 4.1983578 | Q9: =C9/P9 -> 32.591656 | R9: 13117.008 | S9: =R9/D9 -> 8.459272 | T9: =C9/S9 -> 16.17532
B10: GSK plc | C10: 17.743161 | D10: 4076.7539 | E10: 72334.501 | F10: 86762.02 | G10: 37066.156 | H10: =$F10/G10 -> 2.3407342 | I10: 39342.573 | J10: =$F10/I10 -> 2.205296 | K10: 9820.594 | L10: =$F10/K10 -> 8.8347019 | M10: 13144.504 | N10: =$F10/M10 -> 6.6006309 | O10: 3486.175 | P10: =O10/$D10 -> 0.85513501 | Q10: =C10/P10 -> 20.748959 | R10: 8346.9543 | S10: =R10/D10 -> 2.0474511 | T10: =C10/S10 -> 8.6659754
B11: Sanofi | C11: 103.88 | D11: 1224.035 | E11: 127152.75 | F11: 137859.75 | G11: 44286 | H11: =$F11/G11 -> 3.1129421 | I11: 46188.493 | J11: =$F11/I11 -> 2.9847208 | K11: 11664 | L11: =$F11/K11 -> 11.819252 | M11: 14351.209 | N11: =$F11/M11 -> 9.6061421 | O11: 5618 | P11: =O11/$D11 -> 4.5897381 | Q11: =C11/P11 -> 22.6331 | R11: 10189.54 | S11: =R11/D11 -> 8.3245493 | T11: =C11/S11 -> 12.478754
B12: Takeda Pharmaceutical Company Limited | C12: 27.928515 | D12: 1529.4981 | E12: 42716.612 | F12: 73060.806 | G12: 27970.201 | H12: =$F12/G12 -> 2.6120944 | I12: 28215.985 | J12: =$F12/I12 -> 2.589341 | K12: 7724.248 | L12: =$F12/K12 -> 9.4586302 | M12: 7825.2334 | N12: =$F12/M12 -> 9.3365657 | O12: 1272.0427 | P12: =O12/$D12 -> 0.8316733 | Q12: =C12/P12 -> 33.581114 | R12: 1446.4214 | S12: =R12/D12 -> 0.9456837 | T12: =C12/S12 -> 29.532618
D15: Min | E15: =MIN(E5:E12) -> 12226.683 | F15: =MIN(F5:F12) -> 4108.1967 | G15: =MIN(G5:G12) -> 2751.1 | H15: =MIN(H5:H12) -> 1.3730799 | I15: =MIN(I5:I12) -> 2076.8646 | J15: =MIN(J5:J12) -> 1.9780764 | K15: =MIN(K5:K12) -> -3472.7417 | L15: =MIN(L5:L12) -> -6.3047146 | ... T15: =MIN(T5:T12) -> -18.511564
D16: Median | E16: =MEDIAN(E5:E12) -> 57525.556 | F16: =MEDIAN(F5:F12) -> 79911.413 | G16: =MEDIAN(G5:G12) -> 32518.179 | H16: =MEDIAN(H5:H12) -> 2.4898284 | I16: =MEDIAN(I5:I12) -> 33779.279 | J16: =MEDIAN(J5:J12) -> 2.7870309 | K16: =MEDIAN(K5:K12) -> 8772.421 | L16: =MEDIAN(L5:L12) -> 9.1466661 | ... T16: =MEDIAN(T5:T12) -> 10.572365
D17: Average | E17: =AVERAGE(E5:E12) -> 81492.298 | F17: =AVERAGE(F5:F12) -> 90725.807 | G17: =AVERAGE(G5:G12) -> 27510.084 | H17: =AVERAGE(H5:H12) -> 2.7546483 | I17: =AVERAGE(I5:I12) -> 28743.522 | J17: =AVERAGE(J5:J12) -> 2.8604908 | K17: =AVERAGE(K5:K12) -> 6824.1978 | L17: =AVERAGE(L5:L12) -> 6.1930114 | ... T17: =AVERAGE(T5:T12) -> 7.5135617
D18: Max | E18: =MAX(E5:E12) -> 212171.8 | F18: =MAX(F5:F12) -> 236050.66 | G18: =MAX(G5:G12) -> 49995.091 | H18: =MAX(H5:H12) -> 4.7214768 | I18: =MAX(I5:I12) -> 54519.631 | J18: =MAX(J5:J12) -> 4.3296452 | K18: =MAX(K5:K12) -> 16242.187 | L18: =MAX(L5:L12) -> 14.533182 | ... T18: =MAX(T5:T12) -> 29.532618
G30: 1000

Sheet WACC Analysis
B2: WACC calculation
L3: Sensitising WACC based on capital structure and levered Beta
A4: x | B4: Input | C4: Value | D4: Comment | E4: Source: | N4: Debt / Value
B5: Risk-free rate | C5: 0.0435 | D5: Yield on 10y U.S. government bond | E5: https://www.marketwatch.com/investing/bond/tmubmusd10y?countrycode=bx | M5: =$C$19 -> 0.086676583 | N5: 0.0097073453 | O5: =N5+0.04 -> 0.049707345 | P5: =O5+0.04 -> 0.089707345 | Q5: =P5+0.04 -> 0.12970735 | R5: =Q5+0.04 -> 0.16970735
B6: Equity Beta | C6: 1.005 | D6: Based on 5y-monthly regression (against S&P 500) | E6: Bloomberg (LSE) | L6: Equity Beta | M6: =M7-0.1 -> 0.805 | N6: 0.078100648 | O6: 0.077046388 | P6: 0.075992128 | Q6: 0.074937868 | R6: 0.073883608
B7: Equity risk premium (ERP) | C7: 0.0433 | D7: Implied current U.S. ERP | E7: https://pages.stern.nyu.edu/~adamodar/New_Home_Page/datafile/ctryprem.html | M7: =M8-0.1 -> 0.905 | N7: 0.082388616 | O7: 0.081161156 | P7: 0.079933696 | Q7: 0.078706236 | R7: 0.077478776
B8: Cost of equity | C8: =C5+C6*C7 -> 0.0870165 | M8: 1.005 | N8: 0.086676583 | O8: 0.085275923 | P8: 0.083875263 | Q8: 0.082474603 | R8: 0.081073943
M9: =M8+0.1 -> 1.105 | N9: 0.09096455 | O9: 0.08939069 | P9: 0.08781683 | Q9: 0.08624297 | R9: 0.08466911
B10: Interest rate | C10: =-'BionTech Adjusted'!K14/SUM('BionTech Adjusted'!K57,'BionTech Adjusted'!K64) -> 0.10908261 | M10: =M9+0.1 -> 1.205 | N10: 0.095252517 | O10: 0.093505457 | P10: 0.091758397 | Q10: 0.090011337 | R10: 0.088264277
B11: Pre-tax cost of debt | C11: =5.2%/(1-C12) -> 0.074285714 | D11: Based on AlphaSpread security analysis | E11: https://www.alphaspread.com/security/nasdaq/bntx/discount-rate | M11: =M10+0.1 -> 1.305 | N11: 0.099540484 | O11: 0.097620224 | P11: 0.095699964 | Q11: 0.093779704 | R11: 0.091859444
B12: Marginal tax rate | C12: 0.3 | D12: German corporate tax rate | E12: https://kpmg.com/dk/en/home/insights/2016/11/tax-rates-online/corporate-tax-rates-table.html
B13: Post-tax cost of debt | C13: =C11*(1-C12) -> 0.052
B15: Debt | C15: ='BionTech Adjusted'!K57+'BionTech Adjusted'!K64 -> 219.1 | E15: total debt
B16: Equity | C16: ='Public comps'!E5 -> 22351.437 | E16: market cap
B17: Debt / Value | C17: =C15/SUM(C15:C16) -> 0.0097073453 | D17: Current capital structure
B18: Equity / Value | C18: =1-C17 -> 0.99029265
B19: WACC | C19: =C17*C13+C8*C18 -> 0.086676583
L23: Sensitising WACC based on capital structure and cost of debt
N24: Debt / Value
M25: =C19 -> 0.086676583 | N25: 0.0097073453 | O25: =N25+0.04 -> 0.049707345 | P25: =O25+0.04 -> 0.089707345 | Q25: =P25+0.04 -> 0.12970735 | R25: =Q25+0.04 -> 0.16970735
L26: Pre-tax cost of debt | M26: =M27-0.02 -> 0.034285714 | N26: 0.086404777 | O26: 0.083884117 | P26: 0.081363457 | Q26: 0.078842797 | R26: 0.076322137
M27: =M28-0.02 -> 0.054285714 | N27: 0.08654068 | O27: 0.08458002 | P27: 0.08261936 | Q27: 0.0806587 | R27: 0.07869804
M28: 0.074285714 | N28: 0.086676583 | O28: 0.085275923 | P28: 0.083875263 | Q28: 0.082474603 | R28: 0.081073943
M29: =M28+0.02 -> 0.094285714 | N29: 0.086812486 | O29: 0.085971826 | P29: 0.085131166 | Q29: 0.084290506 | R29: 0.083449846
