Workbook

Sheet Exhibit 2-Geographic Segment
A1: (in € mn) | B1: Fiscal year | C1: France | D1: Rest of Europe | E1: Latin America | F1: Asia | G1: Global functions/Other regions
A2: Net revenue | B2: 2020 | C2: 34135 | D2: 21239 | E2: 13245 | F2: 2100 | G2: 0
B3: 2019 | C3: 34765 | D3: 20999 | E3: 14665 | F3: 1968 | G3: 0
B4: 2018 | C4: 35615 | D4: 21076 | E4: 13809 | F4: 5501 | G4: 0
B5: 2017 | C5: 35835 | D5: 21112 | E5: 16042 | F5: 5907 | G5: 0
B6: 2016 | C6: 35877 | D6: 20085 | E6: 14507 | F6: 6176 | G6: 0
B7: 2015 | C7: 36272 | D7: 19724 | E7: 14290 | F7: 6659 | G7: 0
A8: Recurring operating income | B8: 2020 | C8: 629 | D8: 698 | E8: 786 | F8: 94 | G8: -33
B9: 2019 | C9: 555 | D9: 659 | E9: 833 | F9: 83 | G9: -32
B10: 2018 | C10: 466 | D10: 664 | E10: 767 | F10: 45 | G10: -38
B11: 2017 | C11: 692 | D11: 677 | E11: 715 | F11: 4 | G11: -83
B12: 2016 | C12: 1031 | D12: 712 | E12: 711 | F12: -58 | G12: -45
B13: 2015 | C13: 1191 | D13: 567 | E13: 705 | F13: 13 | G13: -31
A14: Total segment assets | B14: 2020 | C14: 19742 | D14: 11183 | E14: 7142 | F14: 1133 | G14: 393
B15: 2019 | C15: 20730 | D15: 11847 | E15: 8558 | F15: 1197 | G15: 800
B16: 2018 | C16: 19370 | D16: 9925 | E16: 7057 | F16: 1989 | G16: 1129
B17: 2017 | C17: 19921 | D17: 10427 | E17: 7195 | F17: 2128 | G17: 1015
B18: 2016 | C18: 20134 | D18: 10754 | E18: 7497 | F18: 2438 | G18: 748
B19: 2015 | C19: 19131 | D19: 10272 | E19: 5844 | F19: 2341 | G19: 889
A20: Capital expenditures | B20: 2020 | C20: 582 | D20: 314 | E20: 548 | F20: 34 | G20: 14
B21: 2019 | C21: 875 | D21: 366 | E21: 420 | F21: 47 | G21: 17
B22: 2018 | C22: 537 | D22: 385 | E22: 429 | F22: 94 | G22: 166
B23: 2017 | C23: 903 | D23: 636 | E23: 526 | F23: 164 | G23: 150
B24: 2016 | C24: 1287 | D24: 625 | E24: 519 | F24: 174 | G24: 144
B25: 2015 | C25: 957 | D25: 579 | E25: 517 | F25: 204 | G25: 122
A26: Depreciation and amortization expense | B26: 2020 | C26: -1065 | D26: -867 | E26: -214 | F26: -131 | G26: -15
B27: 2019 | C27: -996 | D27: -878 | E27: -281 | F27: -126 | G27: -37
B28: 2018 | C28: -629 | D28: -458 | E28: -216 | F28: -159 | G28: -102
B29: 2017 | C29: -692 | D29: -459 | E29: -221 | F29: -178 | G29: -81
B30: 2016 | C30: -616 | D30: -414 | E30: -183 | F30: -199 | G30: -74
B31: 2015 | C31: -602 | D31: -389 | E31: -180 | F31: -213 | G31: -87
A32: Total sales area (in square meters, thousands) | B32: 2020 | C32: 5507 | D32: 6165 | E32: 2717 | F32: 1035 | G32: 1486
B33: 2019 | C33: 5475 | D33: 5596 | E33: 2616 | F33: 1050 | G33: 1379
B34: 2018 | C34: 5546 | D34: 5598 | E34: 2510 | F34: 2667 | G34: 1223
B35: 2017 | C35: 5764 | D35: 5599 | E35: 2408 | F35: 2736 | G35: 1111
B36: 2016 | C36: 5719 | D36: 5449 | E36: 2335 | F36: 2758 | G36: 0
B37: 2015 | C37: 5668 | D37: 6039 | E37: 2258 | F37: 2734 | G37: 828
A38: Number of hypermarkets | B38: 2020 | C38: 248 | D38: 456 | E38: 185 | F38: 172 | G38: 151
B39: 2019 | C39: 248 | D39: 455 | E39: 188 | F39: 175 | G39: 141
B40: 2018 | C40: 247 | D40: 452 | E40: 189 | F40: 372 | G40: 124
...

Sheet Exhibit 3-Financial Statements
A1: INCOME STATEMENT – € million | B1: 2020 | C1: 2019 | D1: 2018 | E1: 2017 | F1: 2016 | G1: 2015
A2: Revenue – retail | B2: 70719 | C2: 72397 | D2: 76000 | E2: 78897 | F2: 76645 | G2: 76945
A3: Revenue – Carrefour banque | B3: 297 | C3: 320 | D3: 334 | E3: 379 | F3: 417 | G3: 461
A4: Financing fees and commissions | B4: 899 | C4: 1168 | D4: 1049 | E4: 1005 | F4: 956 | G4: 869
A5: Total revenue | B5: 71915 | C5: 73885 | D5: 77383 | E5: 80281 | F5: 78018 | G5: 78275
A6: Cost of sales | B6: -56705 | C6: -58049 | D6: -60810 | E6: -62692 | F6: -60714 | G6: -60838
A7: SG&A expenses | B7: -13751 | C7: -14302 | D7: -15496 | E7: -16431 | F7: -15771 | G7: -15675
A8: Operating expenses – Carrefour banque | B8: -260 | C8: -429 | D8: -291 | E8: -305 | F8: -325 | G8: -336
A9: Net other operating income or expense | B9: 808 | C9: 789 | D9: 985 | E9: 1021 | F9: 1021 | G9: 924
A10: Non-operating investment income | B10: 162 | C10: 248 | D10: 255 | E10: 249 | F10: 208 | G10: 248
A11: Operating profit | B11: 2169 | C11: 2142 | D11: 2026.2844 | E11: 2123.3988 | F11: 2437.2236 | G11: 2597.587
A12: Impairment losses | B12: -295 | C12: -200 | D12: -202 | E12: -1039 | F12: -130 | G12: -115
... A32: Recurring tax expense | B32: -498 | C32: -401 | D32: -455 | E32: -441 | F32: -622 | G32: -662
A33: Non-recurring tax items | B33: 5 | C33: -96 | D33: -85 | E33: -179 | F33: 140 | G33: 85 | H33: x
A34: Total tax expense | B34: -493 | C34: -497 | D34: -540 | E34: -620 | F34: -482 | G34: -577
A35: Statutory tax rate | B35: 0.32 | C35: 0.344 | D35: 0.344 | E35: 0.344 | F35: 0.344 | G35: 0.38
A37: OTHER INFORMATION – € million | B37: 2020 | C37: 2019 | D37: 2018 | E37: 2017 | F37: 2016 | G37: 2015
A38: Effect of exchange rate changes on revenue | B38: -0.066 | C38: -0.031 | D38: -0.063 | E38: 0.004 | F38: -0.031 | G38: -0.011
A39: Profit/loss of discontinued operations | B39: -22 | C39: 1092 | D39: -301 | E39: 1 | F39: -40 | G39: 4
A40: End-of-year share price (€) | B40: 14.03 | C40: 14.95 | D40: 14.91 | E40: 18.04 | F40: 22.89 | G40: 26.65
A41: Dividend per share (€) | B41: 0.48 | C41: 0.23 | D41: 0.46 | E41: 0.46 | F41: 0.7 | G41: 0.7
A42: Average number of shares outstanding (million) | B42: 808 | C42: 791 | D42: 773 | E42: 757 | F42: 739 | G42: 723
A44: BALANCE SHEET – € million | B44: 2020 | C44: 2019 | D44: 2018 | E44: 2017 | F44: 2016 | G44: 2015
A45: Non-current tangible assets | B45: 15011 | C45: 15759 | D45: 15877 | E45: 16463 | F45: 16668 | G45: 15156
A46: Goodwill | B46: 8034 | C46: 7976 | D46: 7983 | E46: 7977 | F46: 8640 | G46: 8495
A47: Other non-current intangible assets | B47: 1325 | C47: 1452 | D47: 1461 | E47: 1364 | F47: 1266 | G47: 1014
... A96: Net increase (decrease) in cash balance | B96: 428 | C96: 247 | D96: 1026 | E96: 570 | F96: 449 | G96: -139

Sheet Exhibit 4-LFL sales growth
A1: LFL at constant exchange rates | B1: 2020 | C1: 2019 | D1: 2018
A2: France | B2: 0.036 | C2: -0.001 | D2: 0.003
A3: Hypermarkets | B3: 0.01 | C3: -0.021 | D3: -0.014
A4: Supermarkets | B4: 0.068 | C4: 0.019 | D4: 0.016
A5: Covenience & other | B5: 0.083 | C5: 0.022 | D5: 0.033
A6: Spain | B6: 0.071 | C6: 0.001 | D6: -0.019
A7: Italy | B7: -0.052 | C7: -0.026 | D7: -0.04
A8: Brazil | B8: 0.182 | C8: 0.065 | D8: 0.039
A10: Group | B10: 0.078 | C10: 0.031 | D10: 0.014

Sheet Exhibit 5 - Casino
C1: Casino
A3: Ratio | B3: 2020 | C3: 2019 | D3: 2018 | E3: 2017
A4: Net operating profit margin | B4: 0.027 | C4: 0.019 | D4: 0.021 | E4: 0.025
A5: × Net operating asset turnover | B5: 2.18 | C5: 2.09 | D5: 2.26 | E5: 2.07
A6: = Return on net operating assets | B6: =B4*B5 -> 0.05886 | C6: =C4*C5 -> 0.03971 | D6: =D4*D5 -> 0.04746 | E6: =E4*E5 -> 0.05175
A7: ROE | B7: 0.084 | C7: 0.037 | D7: 0.054 | E7: 0.057
A8: Financial leverage | B8: 2.59 | C8: 2.3 | D8: 1.28 | E8: 1.09
A10: Personnel expense-to-revenue | B10: -0.117 | C10: -0.12 | D10: -0.123 | E10: -0.121
A11: Operating working capital/Revenue | B11: -0.111 | C11: -0.09 | D11: -0.078 | E11: -0.069
A12: Net non-current assets/Revenue | B12: -0.569 | C12: -0.569 | D12: -0.521 | E12: -0.552
A13: PP&E/Revenue | B13: -0.287 | C13: -0.287 | D13: -0.221 | E13: -0.256

Sheet Condensed statements
A1: Assumptions: | B1: 2020 | C1: 2019 | D1: 2018 | E1: 2017 | F1: 2016 | G1: 2015
A2: Operating cash percentage | B2: 0.04 | C2: 0.04 | D2: 0.04 | E2: 0.04 | F2: 0.04 | G2: 0.04
A4: CONDENSED STATEMENTS OF EARNINGS | B4: 2020 | C4: 2019 | D4: 2018 | E4: 2017 | F4: 2016 | G4: 2015
A5: Revenue | B5: ='Exhibit 3-Financial Statements'!B2 -> 70719 | C5: ='Exhibit 3-Financial Statements'!C2 -> 72397 | D5: ='Exhibit 3-Financial Statements'!D2 -> 76000 | E5: ='Exhibit 3-Financial Statements'!E2 -> 78897 | F5: ='Exhibit 3-Financial Statements'!F2 -> 76645 | G5: ='Exhibit 3-Financial Statements'!G2 -> 76945
A6: Net operating profit after tax | B6: =B10 -> 316 | C6: =C10 -> -345.832 | D6: =D10 -> -695.61346 | E6: =E10 -> -954.07441 | F6: =F10 -> 458.1147 | G6: =G10 -> 670.80393
A7: Profit or loss | B7: ='Exhibit 3-Financial Statements'!B21-'Exhibit 3-Financial Statements'!B20 -> 858 | C7: ='Exhibit 3-Financial Statements'!C21-'Exhibit 3-Financial Statements'!C20 -> 225 | D7: ='Exhibit 3-Financial Statements'!D21-'Exhibit 3-Financial Statements'!D20 -> -45 | E7: ='Exhibit 3-Financial Statements'!E21-'Exhibit 3-Financial Statements'!E20 -> -366 | F7: ='Exhibit 3-Financial Statements'!F21-'Exhibit 3-Financial Statements'!F20 -> 946 | G7: ='Exhibit 3-Financial Statements'!G21-'Exhibit 3-Financial Statements'!G20 -> 1140
A8: – Investment profit after tax | B8: =-B16 -> -757.56 | C8: =-C16 -> -818.144 | D8: =-D16 -> -909.92 | E8: =-E16 -> -916.992 | F8: =-F16 -> -864.576 | G8: =-G16 -> -819.86
A9: + Interest expense after tax | B9: =B21 -> 215.56 | C9: =C21 -> 247.312 | D9: =D21 -> 259.30654 | E9: =E21 -> 328.91759 | F9: =F21 -> 376.6907 | G9: =G21 -> 350.66393
A10: = Net operating profit after tax | B10: =SUM(B7:B9) -> 316 | C10: =SUM(C7:C9) -> -345.832 | D10: =SUM(D7:D9) -> -695.61346 | E10: =SUM(E7:E9) -> -954.07441 | F10: =SUM(F7:F9) -> 458.1147 | G10: =SUM(G7:G9) -> 670.80393
A11: of which: Net non-recurring expense after tax | B11: =B15 -> 339.76 | C11: =C15 -> 785.456 | D11: =D15 -> 840.712 | E11: =E15 -> 1094.776 | F11: =F15 -> 166.352 | G11: =G15 -> 132.62
A12: = Net non-recurring expense (income) | B12: =-1*SUM('Exhibit 3-Financial Statements'!B12,'Exhibit 3-Financial Statements'!B13,'Exhibit 3-Financial Statements'!B14) -> 507 | C12: =-1*SUM('Exhibit 3-Financial Statements'!C12,'Exhibit 3-Financial Statements'!C13,'Exhibit 3-Financial Statements'!C14) -> 1051 | D12: =-1*SUM('Exhibit 3-Financial Statements'!D12,'Exhibit 3-Financial Statements'!D13,'Exhibit 3-Financial Statements'!D14) -> 1152 | E12: =-1*SUM('Exhibit 3-Financial Statements'!E12,'Exhibit 3-Financial Statements'!E13,'Exhibit 3-Financial Statements'!E14) -> 1396 | F12: =-1*SUM('Exhibit 3-Financial Statements'!F12,'Exhibit 3-Financial Statements'!F13,'Exhibit 3-Financial Statements'!F14) -> 467 | G12: =-1*SUM('Exhibit 3-Financial Statements'!G12,'Exhibit 3-Financial Statements'!G13,'Exhibit 3-Financial Statements'!G14) -> 351
A13: x (1 – Tax rate) | B13: =(1-'Exhibit 3-Financial Statements'!B35) -> 0.68 | C13: =(1-'Exhibit 3-Financial Statements'!C35) -> 0.656 | D13: =(1-'Exhibit 3-Financial Statements'!D35) -> 0.656 | E13: =(1-'Exhibit 3-Financial Statements'!E35) -> 0.656 | F13: =(1-'Exhibit 3-Financial Statements'!F35) -> 0.656 | G13: =(1-'Exhibit 3-Financial Statements'!G35) -> 0.62
A14: + Non-recurring tax expense (income) | B14: =-1*'Exhibit 3-Financial Statements'!B33 -> -5 | C14: =-1*'Exhibit 3-Financial Statements'!C33 -> 96 | D14: =-1*'Exhibit 3-Financial Statements'!D33 -> 85 | E14: =-1*'Exhibit 3-Financial Statements'!E33 -> 179 | F14: =-1*'Exhibit 3-Financial Statements'!F33 -> -140 | G14: =-1*'Exhibit 3-Financial Statements'!G33 -> -85
A15: = Net non-recurring expense after tax | B15: =B13*B12+B14 -> 339.76 | C15: =C13*C12+C14 -> 785.456 | D15: =D13*D12+D14 -> 840.712 | E15: =E13*E12+E14 -> 1094.776 | F15: =F13*F12+F14 -> 166.352 | G15: =G13*G12+G14 -> 132.62
A16: + Net investment profit after tax | B16: =B20 -> 757.56 | C16: =C20 -> 818.144 | D16: =D20 -> 909.92 | E16: =E20 -> 916.992 | F16: =F20 -> 864.576 | G16: =G20 -> 819.86
A17: = Investment and interest income | B17: ='Exhibit 3-Financial Statements'!B4+'Exhibit 3-Financial Statements'!B10+'Exhibit 3-Financial Statements'!B15 -> 1067 | C17: ='Exhibit 3-Financial Statements'!C4+'Exhibit 3-Financial Statements'!C10+'Exhibit 3-Financial Statements'!C15 -> 1424 | D17: ='Exhibit 3-Financial Statements'!D4+'Exhibit 3-Financial Statements'!D10+'Exhibit 3-Financial Statements'!D15 -> 1320 | E17: ='Exhibit 3-Financial Statements'!E4+'Exhibit 3-Financial Statements'!E10+'Exhibit 3-Financial Statements'!E15 -> 1282 | F17: ='Exhibit 3-Financial Statements'!F4+'Exhibit 3-Financial Statements'!F10+'Exhibit 3-Financial Statements'!F15 -> 1196 | G17: ='Exhibit 3-Financial Statements'!G4+'Exhibit 3-Financial Statements'!G10+'Exhibit 3-Financial Statements'!G15 -> 1153
A18: x (1 – Tax rate) | B18: =B13 -> 0.68 | C18: =C13 -> 0.656 | D18: =D13 -> 0.656 | E18: =E13 -> 0.656 | F18: =F13 -> 0.656 | G18: =G13 -> 0.62
A19: + Profit/loss Carrefour Banque | B19: =SUM('Exhibit 3-Financial Statements'!B3,'Exhibit 3-Financial Statements'!B8,'Exhibit 3-Financial Statements'!B19) -> 32 | C19: =SUM('Exhibit 3-Financial Statements'!C3,'Exhibit 3-Financial Statements'!C8,'Exhibit 3-Financial Statements'!C19) -> -116 | D19: =SUM('Exhibit 3-Financial Statements'!D3,'Exhibit 3-Financial Statements'!D8,'Exhibit 3-Financial Statements'!D19) -> 44 | E19: =SUM('Exhibit 3-Financial Statements'!E3,'Exhibit 3-Financial Statements'!E8,'Exhibit 3-Financial Statements'!E19) -> 76 | F19: =SUM('Exhibit 3-Financial Statements'!F3,'Exhibit 3-Financial Statements'!F8,'Exhibit 3-Financial Statements'!F19) -> 80 | G19: =SUM('Exhibit 3-Financial Statements'!G3,'Exhibit 3-Financial Statements'!G8,'Exhibit 3-Financial Statements'!G19) -> 105
A20: = Net investment profit after tax | B20: =B17*B18+B19 -> 757.56 | C20: =C17*C18+C19 -> 818.144 | D20: =D17*D18+D19 -> 909.92 | E20: =E17*E18+E19 -> 916.992 | F20: =F17*F18+F19 -> 864.576 | G20: =G17*G18+G19 -> 819.86
A21: – Interest expense after tax | B21: =B24 -> 215.56 | C21: =C24 -> 247.312 | D21: =D24 -> 259.30654 | E21: =E24 -> 328.91759 | F21: =F24 -> 376.6907 | G21: =G24 -> 350.66393
A22: = Interest expense | B22: =-1*'Exhibit 3-Financial Statements'!B16 -> 317 | C22: =-1*'Exhibit 3-Financial Statements'!C16 -> 377 | D22: =-1*'Exhibit 3-Financial Statements'!D16 -> 395.28436 | E22: =-1*'Exhibit 3-Financial Statements'!E16 -> 501.39876 | F22: =-1*'Exhibit 3-Financial Statements'!F16 -> 574.22363 | G22: =-1*'Exhibit 3-Financial Statements'!G16 -> 565.58699
A23: x (1 – Tax rate) | B23: =B18 -> 0.68 | C23: =C18 -> 0.656 | D23: =D18 -> 0.656 | E23: =E18 -> 0.656 | F23: =F18 -> 0.656 | G23: =G18 -> 0.62
A24: = Interest expense after tax | B24: =B23*B22 -> 215.56 | C24: =C23*C22 -> 247.312 | D24: =D23*D22 -> 259.30654 | E24: =E23*E22 -> 328.91759 | F24: =F23*F22 -> 376.6907 | G24: =G23*G22 -> 350.66393
A25: = Profit or loss | B25: =B10+B16-B21 -> 858 | C25: =C10+C16-C21 -> 225 | D25: =D10+D16-D21 -> -45 | E25: =E10+E16-E21 -> -366 | F25: =F10+F16-F21 -> 946 | G25: =G10+G16-G21 -> 1140
A27: CONDENSED BALANCE SHEETS | B27: 2020 | C27: 2019 | D27: 2018 | E27: 2017 | F27: 2016 | G27: 2015
A28: Ending operating working capital
A29: Operating cash | B29: =MIN('Exhibit 3-Financial Statements'!B57,'Condensed statements'!B2*'Condensed statements'!B5) -> 2828.76 | C29: =MIN('Exhibit 3-Financial Statements'!C57,'Condensed statements'!C2*'Condensed statements'!C5) -> 2895.88 | D29: =MIN('Exhibit 3-Financial Statements'!D57,'Condensed statements'!D2*'Condensed statements'!D5) -> 3040 | E29: =MIN('Exhibit 3-Financial Statements'!E57,'Condensed statements'!E2*'Condensed statements'!E5) -> 3155.88 | F29: =MIN('Exhibit 3-Financial Statements'!F57,'Condensed statements'!F2*'Condensed statements'!F5) -> 3065.8 | G29: =MIN('Exhibit 3-Financial Statements'!G57,'Condensed statements'!G2*'Condensed statements'!G5) -> 2724
A30: + Trade receivables | B30: ='Exhibit 3-Financial Statements'!B54 -> 2526 | C30: ='Exhibit 3-Financial Statements'!C54 -> 2669 | D30: ='Exhibit 3-Financial Statements'!D54 -> 2537 | E30: ='Exhibit 3-Financial Statements'!E54 -> 2750 | F30: ='Exhibit 3-Financial Statements'!F54 -> 2682 | G30: ='Exhibit 3-Financial Statements'!G54 -> 2269
A31: + Inventories | B31: ='Exhibit 3-Financial Statements'!B53 -> 5326 | C31: ='Exhibit 3-Financial Statements'!C53 -> 5867 | D31: ='Exhibit 3-Financial Statements'!D53 -> 6135 | E31: ='Exhibit 3-Financial Statements'!E53 -> 6690 | F31: ='Exhibit 3-Financial Statements'!F53 -> 7039 | G31: ='Exhibit 3-Financial Statements'!G53 -> 6362
A32: + Other current assets | B32: ='Exhibit 3-Financial Statements'!B56 -> 1395 | C32: ='Exhibit 3-Financial Statements'!C56 -> 1577 | D32: ='Exhibit 3-Financial Statements'!D56 -> 1740 | E32: ='Exhibit 3-Financial Statements'!E56 -> 1741 | F32: ='Exhibit 3-Financial Statements'!F56 -> 1951 | G32: ='Exhibit 3-Financial Statements'!G56 -> 1873
A33: – Trade payables | B33: =-'Exhibit 3-Financial Statements'!B69 -> -12560 | C33: =-'Exhibit 3-Financial Statements'!C69 -> -13646 | D33: =-'Exhibit 3-Financial Statements'!D69 -> -14161 | E33: =-'Exhibit 3-Financial Statements'!E69 -> -15082 | F33: =-'Exhibit 3-Financial Statements'!F69 -> -15396 | G33: =-'Exhibit 3-Financial Statements'!G69 -> -13648
A34: – Other current liabilities | B34: =-'Exhibit 3-Financial Statements'!B71 -> -3656 | C34: =-'Exhibit 3-Financial Statements'!C71 -> -3744 | D34: =-'Exhibit 3-Financial Statements'!D71 -> -4080 | E34: =-'Exhibit 3-Financial Statements'!E71 -> -4095 | F34: =-'Exhibit 3-Financial Statements'!F71 -> -4413 | G34: =-'Exhibit 3-Financial Statements'!G71 -> -4341
A35: = Ending operating working capital | B35: =SUM(B29:B34) -> -4140.24 | C35: =SUM(C29:C34) -> -4381.12 | D35: =SUM(D29:D34) -> -4789 | E35: =SUM(E29:E34) -> -4840.12 | F35: =SUM(F29:F34) -> -5071.2 | G35: =SUM(G29:G34) -> -4761
A36: + Ending net non-current operating assets
A37: Non-current tangible assets | B37: ='Exhibit 3-Financial Statements'!B45 -> 15011 | C37: ='Exhibit 3-Financial Statements'!C45 -> 15759 | D37: ='Exhibit 3-Financial Statements'!D45 -> 15877 | E37: ='Exhibit 3-Financial Statements'!E45 -> 16463 | F37: ='Exhibit 3-Financial Statements'!F45 -> 16668 | G37: ='Exhibit 3-Financial Statements'!G45 -> 15156
A38: + Goodwill | B38: ='Exhibit 3-Financial Statements'!B46 -> 8034 | C38: ='Exhibit 3-Financial Statements'!C46 -> 7976 | D38: ='Exhibit 3-Financial Statements'!D46 -> 7983 | E38: ='Exhibit 3-Financial Statements'!E46 -> 7977 | F38: ='Exhibit 3-Financial Statements'!F46 -> 8640 | G38: ='Exhibit 3-Financial Statements'!G46 -> 8495
A39: + Other non-current intangible assets | B39: ='Exhibit 3-Financial Statements'!B47 -> 1325 | C39: ='Exhibit 3-Financial Statements'!C47 -> 1452 | D39: ='Exhibit 3-Financial Statements'!D47 -> 1461 | E39: ='Exhibit 3-Financial Statements'!E47 -> 1364 | F39: ='Exhibit 3-Financial Statements'!F47 -> 1266 | G39: ='Exhibit 3-Financial Statements'!G47 -> 1014
A40: + Derivatives (asset net of liability) | B40: 0 | C40: 0 | D40: 0 | E40: 0 | F40: 0 | G40: 0
A41: – Deferred tax liability (net of asset) | B41: =-('Exhibit 3-Financial Statements'!B67-'Exhibit 3-Financial Statements'!B51) -> 212 | C41: =-('Exhibit 3-Financial Statements'!C67-'Exhibit 3-Financial Statements'!C51) -> 168 | D41: =-('Exhibit 3-Financial Statements'!D67-'Exhibit 3-Financial Statements'!D51) -> 182 | E41: =-('Exhibit 3-Financial Statements'!E67-'Exhibit 3-Financial Statements'!E51) -> 147 | F41: =-('Exhibit 3-Financial Statements'!F67-'Exhibit 3-Financial Statements'!F51) -> 286 | G41: =-('Exhibit 3-Financial Statements'!G67-'Exhibit 3-Financial Statements'!G51) -> 236
A42: – Other non-current liabilities (non-interest-bearing) | B42: 0 | C42: 0 | D42: 0 | E42: 0 | F42: 0 | G42: 0
...

Sheet Ratio analysis
A2: Ratio | B2: 2020 | C2: 2019 | D2: 2018 | E2: 2017 | F2: 2016
A3: Return on equity | B3: ='Condensed statements'!B25/AVERAGE('Condensed statements'!B61,'Condensed statements'!C61) -> 0.07493777 | C3: ='Condensed statements'!C25/AVERAGE('Condensed statements'!C61,'Condensed statements'!D61) -> 0.019627513 | D3: ='Condensed statements'!D25/AVERAGE('Condensed statements'!D61,'Condensed statements'!E61) -> -0.0038469758 | E3: ='Condensed statements'!E25/AVERAGE('Condensed statements'!E61,'Condensed statements'!F61) -> -0.030311814 | F3: ='Condensed statements'!F25/AVERAGE('Condensed statements'!F61,'Condensed statements'!G61) -> 0.083598445
A4: Return on net operating assets | B4: ='Condensed statements'!B10/AVERAGE('Condensed statements'!B35+'Condensed statements'!B43,'Condensed statements'!C35+'Condensed statements'!C43) -> 0.015259936 | C4: ='Condensed statements'!C10/AVERAGE('Condensed statements'!C35+'Condensed statements'!C43,'Condensed statements'!D35+'Condensed statements'!D43) -> -0.016591489 | D4: ='Condensed statements'!D10/AVERAGE('Condensed statements'!D35+'Condensed statements'!D43,'Condensed statements'!E35+'Condensed statements'!E43) -> -0.033263142 | E4: ='Condensed statements'!E10/AVERAGE('Condensed statements'!E35+'Condensed statements'!E43,'Condensed statements'!F35+'Condensed statements'!F43) -> -0.044479325 | F4: ='Condensed statements'!F10/AVERAGE('Condensed statements'!F35+'Condensed statements'!F43,'Condensed statements'!G35+'Condensed statements'!G43) -> 0.02185203
A6: Decomposition of ROE
A7: Ratio | B7: 2020 | C7: 2019 | D7: 2018 | E7: 2017 | F7: 2016
A8: Net profit margin (ROS) | B8: ='Condensed statements'!B25/'Condensed statements'!B5 -> 0.012132524 | C8: ='Condensed statements'!C25/'Condensed statements'!C5 -> 0.0031078636 | D8: ='Condensed statements'!D25/'Condensed statements'!D5 -> -0.00059210526 | E8: ='Condensed statements'!E25/'Condensed statements'!E5 -> -0.0046389597 | F8: ='Condensed statements'!F25/'Condensed statements'!F5 -> 0.012342619
A9: × Asset turnover | B9: ='Condensed statements'!B5/AVERAGE('Exhibit 3-Financial Statements'!B60,'Exhibit 3-Financial Statements'!C60) -> 1.4375241 | C9: ='Condensed statements'!C5/AVERAGE('Exhibit 3-Financial Statements'!C60,'Exhibit 3-Financial Statements'!D60) -> 1.4276812 | D9: ='Condensed statements'!D5/AVERAGE('Exhibit 3-Financial Statements'!D60,'Exhibit 3-Financial Statements'!E60) -> 1.4931531 | E9: ='Condensed statements'!E5/AVERAGE('Exhibit 3-Financial Statements'!E60,'Exhibit 3-Financial Statements'!F60) -> 1.5276941 | F9: ='Condensed statements'!F5/AVERAGE('Exhibit 3-Financial Statements'!F60,'Exhibit 3-Financial Statements'!G60) -> 1.5285437
A10: = Return on assets (ROA) | B10: =B8*B9 -> 0.017440797 | C10: =C8*C9 -> 0.0044370384 | D10: =D8*D9 -> -0.00088410381 | E10: =E8*E9 -> -0.0070869115 | F10: =F8*F9 -> 0.018866231
A11: × Financial leverage | B11: =AVERAGE('Exhibit 3-Financial Statements'!B60,'Exhibit 3-Financial Statements'!C60)/AVERAGE('Condensed statements'!B61,'Condensed statements'!C61) -> 4.2966942 | C11: =AVERAGE('Exhibit 3-Financial Statements'!C60,'Exhibit 3-Financial Statements'!D60)/AVERAGE('Condensed statements'!C61,'Condensed statements'!D61) -> 4.4235617 | D11: =AVERAGE('Exhibit 3-Financial Statements'!D60,'Exhibit 3-Financial Statements'!E60)/AVERAGE('Condensed statements'!D61,'Condensed statements'!E61) -> 4.3512716 | E11: =AVERAGE('Exhibit 3-Financial Statements'!E60,'Exhibit 3-Financial Statements'!F60)/AVERAGE('Condensed statements'!E61,'Condensed statements'!F61) -> 4.2771543 | F11: =AVERAGE('Exhibit 3-Financial Statements'!F60,'Exhibit 3-Financial Statements'!G60)/AVERAGE('Condensed statements'!F61,'Condensed statements'!G61) -> 4.4311152
A12: = Return on equity (ROE) | B12: =B10*B11 -> 0.07493777 | C12: =C10*C11 -> 0.019627513 | D12: =D10*D11 -> -0.0038469758 | E12: =E10*E11 -> -0.030311814 | F12: =F10*F11 -> 0.083598445
A15: RNOA | B15: 2020 | C15: 2019 | D15: 2018 | E15: 2017 | F15: 2016
A16: Net operating profit margin | B16: ='Condensed statements'!B10/'Condensed statements'!B5 -> 0.004468389 | C16: ='Condensed statements'!C10/'Condensed statements'!C5 -> -0.004776883 | D16: ='Condensed statements'!D10/'Condensed statements'!D5 -> -0.0091528087 | E16: ='Condensed statements'!E10/'Condensed statements'!E5 -> -0.012092658 | F16: ='Condensed statements'!F10/'Condensed statements'!F5 -> 0.0059770983
A17: × Net operating asset turnover | B17: ='Condensed statements'!B5/AVERAGE('Condensed statements'!B35+'Condensed statements'!B43,'Condensed statements'!C35+'Condensed statements'!C43) -> 3.4150867 | C17: ='Condensed statements'!C5/AVERAGE('Condensed statements'!C35+'Condensed statements'!C43,'Condensed statements'!D35+'Condensed statements'!D43) -> 3.4732877 | D17: ='Condensed statements'!D5/AVERAGE('Condensed statements'!D35+'Condensed statements'!D43,'Condensed statements'!E35+'Condensed statements'!E43) -> 3.6342005 | E17: ='Condensed statements'!E5/AVERAGE('Condensed statements'!E35+'Condensed statements'!E43,'Condensed statements'!F35+'Condensed statements'!F43) -> 3.6782093 | F17: ='Condensed statements'!F5/AVERAGE('Condensed statements'!F35+'Condensed statements'!F43,'Condensed statements'!G35+'Condensed statements'!G43) -> 3.6559596
A18: = Return on net operating assets | B18: =B16*B17 -> 0.015259936 | C18: =C16*C17 -> -0.016591489 | D18: =D16*D17 -> -0.033263142 | E18: =E16*E17 -> -0.044479325 | F18: =F16*F17 -> 0.02185203
A20: Ratio | B20: 2020 | C20: 2019 | D20: 2018 | E20: 2017 | F20: 2016
A21: ROE (after excluding non-recurring items after tax) | B21: =('Condensed statements'!B25+'Condensed statements'!B11)/AVERAGE('Condensed statements'!B61,'Condensed statements'!C61) -> 0.10461243 | C21: =('Condensed statements'!C25+'Condensed statements'!C11)/AVERAGE('Condensed statements'!C61,'Condensed statements'!D61) -> 0.088145505 | D21: =('Condensed statements'!D25+'Condensed statements'!D11)/AVERAGE('Condensed statements'!D61,'Condensed statements'!E61) -> 0.068024108 | E21: =('Condensed statements'!E25+'Condensed statements'!E11)/AVERAGE('Condensed statements'!E61,'Condensed statements'!F61) -> 0.060356619 | F21: =('Condensed statements'!F25+'Condensed statements'!F11)/AVERAGE('Condensed statements'!F61,'Condensed statements'!G61) -> 0.098299046
A22: RNOA (after excluding non-recurring items after tax) | B22: =('Condensed statements'!B10+'Condensed statements'!B11)/AVERAGE('Condensed statements'!B35+'Condensed statements'!B43,'Condensed statements'!C35+'Condensed statements'!C43) -> 0.031667264 | C22: =('Condensed statements'!C10+'Condensed statements'!C11)/AVERAGE('Condensed statements'!C35+'Condensed statements'!C43,'Condensed statements'!D35+'Condensed statements'!D43) -> 0.021091214 | D22: =('Condensed statements'!D10+'Condensed statements'!D11)/AVERAGE('Condensed statements'!D35+'Condensed statements'!D43,'Condensed statements'!E35+'Condensed statements'!E43) -> 0.0069383841 | E22: =('Condensed statements'!E10+'Condensed statements'!E11)/AVERAGE('Condensed statements'!E35+'Condensed statements'!E43,'Condensed statements'!F35+'Condensed statements'!F43) -> 0.0065595635 | F22: =('Condensed statements'!F10+'Condensed statements'!F11)/AVERAGE('Condensed statements'!F35+'Condensed statements'!F43,'Condensed statements'!G35+'Condensed statements'!G43) -> 0.029787006
A24: Decomposition of ROE (after excluding non-recurring items after tax)
A25: Ratio | B25: 2020 | C25: 2019 | D25: 2018 | E25: 2017 | F25: 2016
A26: Net profit margin (ROS) | B26: =('Condensed statements'!B25+'Condensed statements'!B11)/'Condensed statements'!B5 -> 0.016936891 | C26: =('Condensed statements'!C25+'Condensed statements'!C11)/'Condensed statements'!C5 -> 0.013957153 | D26: =('Condensed statements'!D25+'Condensed statements'!D11)/'Condensed statements'!D5 -> 0.010469895 | E26: =('Condensed statements'!E25+'Condensed statements'!E11)/'Condensed statements'!E5 -> 0.0092370559 | F26: =('Condensed statements'!F25+'Condensed statements'!F11)/'Condensed statements'!F5 -> 0.014513041
A27: × Asset turnover | B27: ='Condensed statements'!B5/AVERAGE('Exhibit 3-Financial Statements'!B60,'Exhibit 3-Financial Statements'!C60) -> 1.4375241 | C27: ='Condensed statements'!C5/AVERAGE('Exhibit 3-Financial Statements'!C60,'Exhibit 3-Financial Statements'!D60) -> 1.4276812 | D27: ='Condensed statements'!D5/AVERAGE('Exhibit 3-Financial Statements'!D60,'Exhibit 3-Financial Statements'!E60) -> 1.4931531 | E27: ='Condensed statements'!E5/AVERAGE('Exhibit 3-Financial Statements'!E60,'Exhibit 3-Financial Statements'!F60) -> 1.5276941 | F27: ='Condensed statements'!F5/AVERAGE('Exhibit 3-Financial Statements'!F60,'Exhibit 3-Financial Statements'!G60) -> 1.5285437
A28: = Return on assets (ROA) | B28: =B26*B27 -> 0.02434719 | C28: =C26*C27 -> 0.019926365 | D28: =D26*D27 -> 0.015633156 | E28: =E26*E27 -> 0.014111396 | F28: =F26*F27 -> 0.022183816
A29: × Financial leverage | B29: =AVERAGE('Exhibit 3-Financial Statements'!B60,'Exhibit 3-Financial Statements'!C60)/AVERAGE('Condensed statements'!B61,'Condensed statements'!C61) -> 4.2966942 | C29: =AVERAGE('Exhibit 3-Financial Statements'!C60,'Exhibit 3-Financial Statements'!D60)/AVERAGE('Condensed statements'!C61,'Condensed statements'!D61) -> 4.4235617 | D29: =AVERAGE('Exhibit 3-Financial Statements'!D60,'Exhibit 3-Financial Statements'!E60)/AVERAGE('Condensed statements'!D61,'Condensed statements'!E61) -> 4.3512716 | E29: =AVERAGE('Exhibit 3-Financial Statements'!E60,'Exhibit 3-Financial Statements'!F60)/AVERAGE('Condensed statements'!E61,'Condensed statements'!F61) -> 4.2771543 | F29: =AVERAGE('Exhibit 3-Financial Statements'!F60,'Exhibit 3-Financial Statements'!G60)/AVERAGE('Condensed statements'!F61,'Condensed statements'!G61) -> 4.4311152
A30: = Return on equity (ROE) | B30: =B28*B29 -> 0.10461243 | C30: =C28*C29 -> 0.088145505 | D30: =D28*D29 -> 0.068024108 | E30: =E28*E29 -> 0.060356619 | F30: =F28*F29 -> 0.098299046
A32: Decomposition of RNOA (after excluding non-recurring items after tax) | G32: Casino
A33: Ratio | B33: 2020 | C33: 2019 | D33: 2018 | E33: 2017 | F33: 2016 | G33: 2020 | H33: 2019 | I33: 2018 | J33: 2017
A34: Net operating profit margin | B34: =('Condensed statements'!B10+'Condensed statements'!B11)/'Condensed statements'!B5 -> 0.0092727556 | C34: =('Condensed statements'!C10+'Condensed statements'!C11)/'Condensed statements'!C5 -> 0.0060724063 | D34: =('Condensed statements'!D10+'Condensed statements'!D11)/'Condensed statements'!D5 -> 0.0019091913 | E34: =('Condensed statements'!E10+'Condensed statements'!E11)/'Condensed statements'!E5 -> 0.0017833579 | F34: =('Condensed statements'!F10+'Condensed statements'!F11)/'Condensed statements'!F5 -> 0.0081475204 | G34: 0.027 | H34: 0.019 | I34: 0.021 | J34: 0.025
A35: × Net operating asset turnover | B35: ='Condensed statements'!B5/AVERAGE('Condensed statements'!B35+'Condensed statements'!B43,'Condensed statements'!C35+'Condensed statements'!C43) -> 3.4150867 | C35: ='Condensed statements'!C5/AVERAGE('Condensed statements'!C35+'Condensed statements'!C43,'Condensed statements'!D35+'Condensed statements'!D43) -> 3.4732877 | D35: ='Condensed statements'!D5/AVERAGE('Condensed statements'!D35+'Condensed statements'!D43,'Condensed statements'!E35+'Condensed statements'!E43) -> 3.6342005 | E35: ='Condensed statements'!E5/AVERAGE('Condensed statements'!E35+'Condensed statements'!E43,'Condensed statements'!F35+'Condensed statements'!F43) -> 3.6782093 | F35: ='Condensed statements'!F5/AVERAGE('Condensed statements'!F35+'Condensed statements'!F43,'Condensed statements'!G35+'Condensed statements'!G43) -> 3.6559596 | G35: 2.18 | H35: 2.09 | I35: 2.26 | J35: 2.07
A36: = Return on net operating assets | B36: =B34*B35 -> 0.031667264 | C36: =C34*C35 -> 0.021091214 | D36: =D34*D35 -> 0.0069383841 | E36: =E34*E35 -> 0.0065595635 | F36: =F34*F35 -> 0.029787006 | G36: =G34*G35 -> 0.05886 | H36: =H34*H35 -> 0.03971 | I36: =I34*I35 -> 0.04746 | J36: =J34*J35 -> 0.05175
A39: Common-sized income statement and profitability ratios
B40: 2020 | C40: 2019 | D40: 2018 | E40: 2017 | F40: 2016
A41: Line items as a percent of sales
A42: Sales | B42: ='Condensed statements'!B5/'Condensed statements'!B5 -> 1 | C42: ='Condensed statements'!C5/'Condensed statements'!C5 -> 1 | D42: ='Condensed statements'!D5/'Condensed statements'!D5 -> 1 | E42: ='Condensed statements'!E5/'Condensed statements'!E5 -> 1 | F42: ='Condensed statements'!F5/'Condensed statements'!F5 -> 1
A43: Interest expense | B43: ='Exhibit 3-Financial Statements'!B16/'Condensed statements'!B5 -> -0.0044825294 | C43: ='Exhibit 3-Financial Statements'!C16/'Condensed statements'!C5 -> -0.0052073981 | D43: ='Exhibit 3-Financial Statements'!D16/'Condensed statements'!D5 -> -0.00520111 | E43: ='Exhibit 3-Financial Statements'!E16/'Condensed statements'!E5 -> -0.0063551055 | F43: ='Exhibit 3-Financial Statements'!F16/'Condensed statements'!F5 -> -0.0074919908
A44: Tax expense | B44: ='Exhibit 3-Financial Statements'!B32/'Condensed statements'!B5 -> -0.0070419548 | C44: ='Exhibit 3-Financial Statements'!C32/'Condensed statements'!C5 -> -0.0055389035 | D44: ='Exhibit 3-Financial Statements'!D32/'Condensed statements'!D5 -> -0.0059868421 | E44: ='Exhibit 3-Financial Statements'!E32/'Condensed statements'!E5 -> -0.0055895661 | F44: ='Exhibit 3-Financial Statements'!F32/'Condensed statements'!F5 -> -0.0081153369
A45: Operating expense line items as a percent of sales (by function)
A46: Cost of sales | B46: ='Exhibit 3-Financial Statements'!B6/'Condensed statements'!B5 -> -0.80183543 | C46: ='Exhibit 3-Financial Statements'!C6/'Condensed statements'!C5 -> -0.80181499 | D46: ='Exhibit 3-Financial Statements'!D6/'Condensed statements'!D5 -> -0.80013158 | E46: ='Exhibit 3-Financial Statements'!E6/'Condensed statements'!E5 -> -0.79460563 | F46: ='Exhibit 3-Financial Statements'!F6/'Condensed statements'!F5 -> -0.79214561
A47: Selling, general, and admin. expense | B47: ='Exhibit 3-Financial Statements'!B7/'Condensed statements'!B5 -> -0.19444562 | C47: ='Exhibit 3-Financial Statements'!C7/'Condensed statements'!C5 -> -0.19754962 | D47: ='Exhibit 3-Financial Statements'!D7/'Condensed statements'!D5 -> -0.20389474 | E47: ='Exhibit 3-Financial Statements'!E7/'Condensed statements'!E5 -> -0.20825887 | F47: ='Exhibit 3-Financial Statements'!F7/'Condensed statements'!F5 -> -0.20576685 | G47: Casino
A48: Operating expense line items as a percent of sales (by nature) | G48: 2020 | H48: 2019 | I48: 2018 | J48: 2017
A49: Personnel expense | B49: ='Exhibit 3-Financial Statements'!B24/'Condensed statements'!B5 -> -0.1026881 | C49: ='Exhibit 3-Financial Statements'!C24/'Condensed statements'!C5 -> -0.10424465 | D49: ='Exhibit 3-Financial Statements'!D24/'Condensed statements'!D5 -> -0.10709211 | E49: ='Exhibit 3-Financial Statements'!E24/'Condensed statements'!E5 -> -0.1089902 | F49: ='Exhibit 3-Financial Statements'!F24/'Condensed statements'!F5 -> -0.10750864 | G49: -0.117 | H49: -0.12 | I49: -0.123 | J49: -0.121
...

Sheet Segment analysis
B1: France | C1: Rest of Europe | D1: Latin America | E1: Asia
A2: Operating profit margin (as reported, including financial services)
A3: 2020 | B3: ='Exhibit 2-Geographic Segment'!C8/'Exhibit 2-Geographic Segment'!C2 -> 0.018426835 | C3: ='Exhibit 2-Geographic Segment'!D8/'Exhibit 2-Geographic Segment'!D2 -> 0.032864071 | D3: ='Exhibit 2-Geographic Segment'!E8/'Exhibit 2-Geographic Segment'!E2 -> 0.059343148 | E3: ='Exhibit 2-Geographic Segment'!F8/'Exhibit 2-Geographic Segment'!F2 -> 0.044761905
A4: 2019 | B4: ='Exhibit 2-Geographic Segment'!C9/'Exhibit 2-Geographic Segment'!C3 -> 0.015964332 | C4: ='Exhibit 2-Geographic Segment'!D9/'Exhibit 2-Geographic Segment'!D3 -> 0.031382447 | D4: ='Exhibit 2-Geographic Segment'!E9/'Exhibit 2-Geographic Segment'!E3 -> 0.056801909 | E4: ='Exhibit 2-Geographic Segment'!F9/'Exhibit 2-Geographic Segment'!F3 -> 0.042174797
A5: 2018 | B5: ='Exhibit 2-Geographic Segment'!C10/'Exhibit 2-Geographic Segment'!C4 -> 0.013084375 | C5: ='Exhibit 2-Geographic Segment'!D10/'Exhibit 2-Geographic Segment'!D4 -> 0.031505029 | D5: ='Exhibit 2-Geographic Segment'!E10/'Exhibit 2-Geographic Segment'!E4 -> 0.055543486 | E5: ='Exhibit 2-Geographic Segment'!F10/'Exhibit 2-Geographic Segment'!F4 -> 0.0081803308
A6: 2017 | B6: ='Exhibit 2-Geographic Segment'!C11/'Exhibit 2-Geographic Segment'!C5 -> 0.01931073 | C6: ='Exhibit 2-Geographic Segment'!D11/'Exhibit 2-Geographic Segment'!D5 -> 0.032067071 | D6: ='Exhibit 2-Geographic Segment'!E11/'Exhibit 2-Geographic Segment'!E5 -> 0.044570502 | E6: ='Exhibit 2-Geographic Segment'!F11/'Exhibit 2-Geographic Segment'!F5 -> 0.00067716269
A7: 2016 | B7: ='Exhibit 2-Geographic Segment'!C12/'Exhibit 2-Geographic Segment'!C6 -> 0.028737074 | C7: ='Exhibit 2-Geographic Segment'!D12/'Exhibit 2-Geographic Segment'!D6 -> 0.03544934 | D7: ='Exhibit 2-Geographic Segment'!E12/'Exhibit 2-Geographic Segment'!E6 -> 0.049010822 | E7: ='Exhibit 2-Geographic Segment'!F12/'Exhibit 2-Geographic Segment'!F6 -> -0.0093911917
A8: Total asset turnover
A9: 2020 | B9: ='Exhibit 2-Geographic Segment'!C2/AVERAGE('Exhibit 2-Geographic Segment'!C14:C15) -> 1.6868452 | C9: ='Exhibit 2-Geographic Segment'!D2/AVERAGE('Exhibit 2-Geographic Segment'!D14:D15) -> 1.8444637 | D9: ='Exhibit 2-Geographic Segment'!E2/AVERAGE('Exhibit 2-Geographic Segment'!E14:E15) -> 1.6872611 | E9: ='Exhibit 2-Geographic Segment'!F2/AVERAGE('Exhibit 2-Geographic Segment'!F14:F15) -> 1.8025751
A10: 2019 | B10: ='Exhibit 2-Geographic Segment'!C3/AVERAGE('Exhibit 2-Geographic Segment'!C15:C16) -> 1.7339152 | C10: ='Exhibit 2-Geographic Segment'!D3/AVERAGE('Exhibit 2-Geographic Segment'!D15:D16) -> 1.9289914 | D10: ='Exhibit 2-Geographic Segment'!E3/AVERAGE('Exhibit 2-Geographic Segment'!E15:E16) -> 1.8783221 | E10: ='Exhibit 2-Geographic Segment'!F3/AVERAGE('Exhibit 2-Geographic Segment'!F15:F16) -> 1.2354049
A11: 2018 | B11: ='Exhibit 2-Geographic Segment'!C4/AVERAGE('Exhibit 2-Geographic Segment'!C16:C17) -> 1.8128834 | C11: ='Exhibit 2-Geographic Segment'!D4/AVERAGE('Exhibit 2-Geographic Segment'!D16:D17) -> 2.0711478 | D11: ='Exhibit 2-Geographic Segment'!E4/AVERAGE('Exhibit 2-Geographic Segment'!E16:E17) -> 1.9378333 | E11: ='Exhibit 2-Geographic Segment'!F4/AVERAGE('Exhibit 2-Geographic Segment'!F16:F17) -> 2.6723342
A12: 2017 | B12: ='Exhibit 2-Geographic Segment'!C5/AVERAGE('Exhibit 2-Geographic Segment'!C17:C18) -> 1.7892897 | C12: ='Exhibit 2-Geographic Segment'!D5/AVERAGE('Exhibit 2-Geographic Segment'!D17:D18) -> 1.9934847 | D12: ='Exhibit 2-Geographic Segment'!E5/AVERAGE('Exhibit 2-Geographic Segment'!E17:E18) -> 2.1837735 | E12: ='Exhibit 2-Geographic Segment'!F5/AVERAGE('Exhibit 2-Geographic Segment'!F17:F18) -> 2.587385
A13: 2016 | B13: ='Exhibit 2-Geographic Segment'!C6/AVERAGE('Exhibit 2-Geographic Segment'!C18:C19) -> 1.827429 | C13: ='Exhibit 2-Geographic Segment'!D6/AVERAGE('Exhibit 2-Geographic Segment'!D18:D19) -> 1.9104918 | D13: ='Exhibit 2-Geographic Segment'!E6/AVERAGE('Exhibit 2-Geographic Segment'!E18:E19) -> 2.1747995 | E13: ='Exhibit 2-Geographic Segment'!F6/AVERAGE('Exhibit 2-Geographic Segment'!F18:F19) -> 2.5846411
A14: Revenue per square metre
A15: 2020 | B15: ='Exhibit 2-Geographic Segment'!C2/AVERAGE('Exhibit 2-Geographic Segment'!C32:C33) -> 6.2165362 | C15: ='Exhibit 2-Geographic Segment'!D2/AVERAGE('Exhibit 2-Geographic Segment'!D32:D33) -> 3.6117677 | D15: ='Exhibit 2-Geographic Segment'!E2/AVERAGE('Exhibit 2-Geographic Segment'!E32:E33) -> 4.9671854 | E15: ='Exhibit 2-Geographic Segment'!F2/AVERAGE('Exhibit 2-Geographic Segment'!F32:F33) -> 2.0143885
A16: 2019 | B16: ='Exhibit 2-Geographic Segment'!C3/AVERAGE('Exhibit 2-Geographic Segment'!C33:C34) -> 6.3088649 | C16: ='Exhibit 2-Geographic Segment'!D3/AVERAGE('Exhibit 2-Geographic Segment'!D33:D34) -> 3.7518313 | D16: ='Exhibit 2-Geographic Segment'!E3/AVERAGE('Exhibit 2-Geographic Segment'!E33:E34) -> 5.7218104 | E16: ='Exhibit 2-Geographic Segment'!F3/AVERAGE('Exhibit 2-Geographic Segment'!F33:F34) -> 1.0589185
A17: 2018 | B17: ='Exhibit 2-Geographic Segment'!C4/AVERAGE('Exhibit 2-Geographic Segment'!C34:C35) -> 6.2979664 | C17: ='Exhibit 2-Geographic Segment'!D4/AVERAGE('Exhibit 2-Geographic Segment'!D34:D35) -> 3.7645798 | D17: ='Exhibit 2-Geographic Segment'!E4/AVERAGE('Exhibit 2-Geographic Segment'!E34:E35) -> 5.6156974 | E17: ='Exhibit 2-Geographic Segment'!F4/AVERAGE('Exhibit 2-Geographic Segment'!F34:F35) -> 2.0362761
A18: 2017 | B18: ='Exhibit 2-Geographic Segment'!C5/AVERAGE('Exhibit 2-Geographic Segment'!C35:C36) -> 6.2414003 | C18: ='Exhibit 2-Geographic Segment'!D5/AVERAGE('Exhibit 2-Geographic Segment'!D35:D36) -> 3.8218682 | D18: ='Exhibit 2-Geographic Segment'!E5/AVERAGE('Exhibit 2-Geographic Segment'!E35:E36) -> 6.764495 | E18: ='Exhibit 2-Geographic Segment'!F5/AVERAGE('Exhibit 2-Geographic Segment'!F35:F36) -> 2.1503458
A19: 2016 | B19: ='Exhibit 2-Geographic Segment'!C6/AVERAGE('Exhibit 2-Geographic Segment'!C36:C37) -> 6.3013963 | C19: ='Exhibit 2-Geographic Segment'!D6/AVERAGE('Exhibit 2-Geographic Segment'!D36:D37) -> 3.4966922 | D19: ='Exhibit 2-Geographic Segment'!E6/AVERAGE('Exhibit 2-Geographic Segment'!E36:E37) -> 6.3170041 | E19: ='Exhibit 2-Geographic Segment'!F6/AVERAGE('Exhibit 2-Geographic Segment'!F36:F37) -> 2.2490896
