Workbook

Sheet Financial Statements
A1: Standard accounts | C1: Income Statement in millions (IFRS) | D1: 2020 | E1: 2019 | F1: 2018 | G1: 2017 | H1: 2016 | I1: 2015 | J1: 2014 | K1: 2013 | L1: 2012 | M1: 2011 | N1: 2010 | O1: 2009 | P1: 2008 | Q1: 2007 | R1: 2006
A3: Revenue | C3: Net sales | D3: 187031 | E3: 232755 | F3: 210400 | G3: 200004 | H3: 192267 | I3: 180861 | J3: 151419 | K3: 128562 | L3: 120799 | M3: 109999 | N3: 108483 | O3: 101393 | P3: 88532 | Q3: 78346 | R3: 68400
A4: Cost of Sales (by function) | C4: Cost of goods sold | D4: -93487 | E4: -110302 | F4: -99513 | G4: -91914 | H4: -86090 | I4: -77694 | J4: -62367 | K4: -52529 | L4: -48928 | M4: -43852 | N4: -40214 | O4: -38919 | P4: -34064 | Q4: -30499 | R4: -27736
C5: Gross profit | D5: =D3+D4 -> 93544 | E5: =E3+E4 -> 122453 | F5: =F3+F4 -> 110887 | G5: =G3+G4 -> 108090 | H5: =H3+H4 -> 106177 | I5: =I3+I4 -> 103167 | J5: =J3+J4 -> 89052 | K5: =K3+K4 -> 76033 | ... R5: =R3+R4 -> 40664
A7: SG&A (by function) | C7: Selling expenses | D7: -81425 | E7: -96279 | F7: -87512 | G7: -80427 | H7: -75729 | I7: -70292 | J7: -58525 | K7: -49878 | L7: -46608 | M7: -42517 | N7: -40751 | O7: -38224 | P7: -32185 | Q7: -27687 | R7: -23971
A8: SG&A (by function) | C8: Administrative expenses | D8: =-9020-D9 -> -9013 | E8: =-8828-E9 -> -8812 | F8: =-7882-F9 -> -7868 | G8: =-7094-G9 -> -7081 | H8: =-6625-H9 -> -6607 | I8: =-5933-I9 -> -5912 | J8: =-4944-J9 -> -4918 | K8: =-3987-K9 -> -3965 | L8: =-3509-L9 -> -3484 | M8: =-3251-M9 -> -3222 | N8: =-2859-N9 -> -2847 | O8: =-2606-O9 -> -2595 | P8: =-2145-P9 -> -2135 | Q8: =-1778-Q9 -> -1770 | R8: =-1395-R9 -> -1386
A9: Interest Expense | C9: Interest on the provision for pensions | D9: -7 | E9: -16 | F9: -14 | G9: -13 | H9: -18 | I9: -21 | J9: -26 | K9: -22 | L9: -25 | M9: -29 | N9: -12 | O9: -11 | P9: -10 | Q9: -8 | R9: -9
C10: Operating profit | D10: =SUM(D5:D9) -> 3099 | E10: =SUM(E5:E9) -> 17346 | F10: =SUM(F5:F9) -> 15493 | G10: =SUM(G5:G9) -> 20569 | H10: =SUM(H5:H9) -> 23823 | I10: =SUM(I5:I9) -> 26942 | J10: =SUM(J5:J9) -> 25583 | K10: =SUM(K5:K9) -> 22168 | ... R10: =SUM(R5:R9) -> 15298
A11: Interest Income | C11: Interest income (incl finance lease) | D11: 252 | E11: 376 | F11: 292 | G11: 281 | H11: 224 | I11: 310 | J11: 328 | K11: 367 | L11: 536 | M11: 568 | N11: 356 | O11: 467 | P11: 1060 | Q11: 793 | R11: 515
A12: Interest Expense | C12: Interest expense and similar items (incl finance lease) | D12: -1299 | E12: -331 | F12: -146 | G12: -41 | H12: -8 | I12: -10 | J12: -16 | K12: -9 | L12: -5 | M12: -5 | N12: -7 | O12: -8 | P12: -8 | Q12: -5 | R12: -5
C13: Profit after financial items | D13: =SUM(D10:D12) -> 2052 | E13: =SUM(E10:E12) -> 17391 | F13: =SUM(F10:F12) -> 15639 | G13: =SUM(G10:G12) -> 20809 | H13: =SUM(H10:H12) -> 24039 | I13: =SUM(I10:I12) -> 27242 | J13: =SUM(J10:J12) -> 25895 | K13: =SUM(K10:K12) -> 22526 | ... R13: =SUM(R10:R12) -> 15808
A14: Tax Expense | C14: Tax | D14: -809 | E14: -3948 | F14: -2987 | G14: -4625 | H14: -5403 | I14: -6344 | J14: -5919 | K14: -5374 | L14: -5418 | M14: -5121 | N14: -6327 | O14: -5719 | P14: -5896 | Q14: -5582 | R14: -5011
A15: Profit/Loss to Ordinary Shareholders | C15: Profit for the year | D15: =SUM(D13:D14) -> 1243 | E15: =SUM(E13:E14) -> 13443 | F15: =SUM(F13:F14) -> 12652 | G15: =SUM(G13:G14) -> 16184 | H15: =SUM(H13:H14) -> 18636 | I15: =SUM(I13:I14) -> 20898 | J15: =SUM(J13:J14) -> 19976 | K15: =SUM(K13:K14) -> 17152 | ... R15: =SUM(R13:R14) -> 10797
C19: Pro Forma IS Items in millions (IFRS) | D19: 2020 | E19: 2019 | F19: 2018 | G19: 2017 | H19: 2016 | I19: 2015 | J19: 2014 | K19: 2013 | L19: 2012 | M19: 2011 | N19: 2010 | O19: 2009 | P19: 2008 | Q19: 2007 | R19: 2006
A21: Personnel Expenses (by nature) | C21: Salaries, other remuneration and payroll overheads | D21: =-88-29771-7100-D9 -> -36952 | E21: =-72-34114-8215-E9 -> -42385 | F21: =-45-31045-7467-F9 -> -38543 | G21: =-48-28620-6979-G9 -> -35634 | H21: =-32579-H9 -> -32561 | I21: =-29973-I9 -> -29952 | J21: =-25074-J9 -> -25048 | K21: =-21445-K9 -> -21423 | L21: =-19918-L9 -> -19893 | M21: =-140-14857-3537-M9 -> -18505 | N21: =-115-13423-3102-N9 -> -16628 | O21: =-125-14058-3335-O9 -> -17507 | P21: =-101-11696-2697-P9 -> -14484 | Q21: =-83-9846-2247-Q9 -> -12168 | R21: =-82-8842-2076-R9 -> -10991
A22: Depreciation and Amortization (by nature) | C22: Depreciation - within cost of goods sold | D22: -1949 | E22: -570 | F22: -558 | G22: -736 | H22: -847 | I22: -725 | J22: -568 | K22: -470 | L22: -415 | M22: -366 | N22: -336 | O22: -310 | P22: -245 | Q22: -203 | R22: -172
A23: Depreciation and Amortization (by nature) | C23: Depreciation - within selling expenses | D23: -22755 | E23: -9887 | F23: -8566 | G23: -7175 | H23: -6256 | I23: -5262 | J23: -4159 | K23: -3463 | L23: -3065 | M23: -2698 | N23: -2540 | O23: -2350 | P23: -1505 | Q23: -1505 | R23: -1374
A24: Depreciation and Amortization (by nature) | C24: Depreciation - within administrative expenses | D24: -1249 | E24: -594 | F24: -547 | G24: -577 | H24: -502 | I24: -412 | J24: -318 | K24: -258 | L24: -225 | M24: -198 | N24: -185 | O24: -170 | P24: -106 | Q24: -132 | R24: -78
A25: Cost of Materials (by nature) | C25: Cost of goods sold excluding depreciation | D25: =D4-D22 -> -91538 | E25: =E4-E22 -> -109732 | F25: =F4-F22 -> -98955 | G25: =G4-G22 -> -91178 | H25: =H4-H22 -> -85243 | I25: =I4-I22 -> -76969 | J25: =J4-J22 -> -61799 | K25: =K4-K22 -> -52059 | ... R25: =R4-R22 -> -27564
C29: Balance Sheet in millions (IFRS) | D29: 2020 | E29: 2019 | F29: 2018 | G29: 2017 | H29: 2016 | I29: 2015 | J29: 2014 | K29: 2013 | L29: 2012 | M29: 2011 | N29: 2010 | O29: 2009 | P29: 2008 | Q29: 2007 | R29: 2006
A31: Non-Current Intangible Assets | C31: Brands | D31: 0 | E31: 0 | F31: 0 | G31: 18 | H31: 66 | I31: 114 | J31: 161 | K31: 208 | L31: 255 | M31: 302 | N31: 349 | O31: 396 | P31: 443 | Q31: 0 | R31: 0
A32: Non-Current Intangible Assets | C32: Customer relations | D32: 0 | E32: 0 | F32: 0 | G32: 8 | H32: 20 | I32: 32 | J32: 45 | K32: 58 | L32: 71 | M32: 84 | N32: 97 | O32: 110 | P32: 123 | Q32: 0 | R32: 0
A33: Non-Current Tangible Assets | C33: Leasehold and similar rights | D33: 191 | E33: 411 | F33: 508 | G33: 592 | H33: 630 | I33: 660 | J33: 509 | K33: 591 | L33: 537 | M33: 585 | N33: 688 | O33: 744 | P33: 659 | Q33: 266 | R33: 222
A34: Non-Current Intangible Assets | C34: Goodwill | D34: 64 | E34: 64 | F34: 64 | G34: 64 | H34: 64 | I34: 64 | J34: 64 | K34: 64 | L34: 64 | M34: 64 | N34: 64 | O34: 424 | P34: 431 | Q34: 0 | R34: 0
A35: Non-Current Intangible Assets | C35: Capitalised development expenditure | D35: 10177 | E35: 10973 | F35: 9046 | G35: 6361 | H35: 4567 | I35: 3245 | J35: 2183 | K35: 1355 | L35: 631 | M35: 0 | N35: 0 | O35: 0 | P35: 0 | Q35: 0 | R35: 0
A36: Non-Current Tangible Assets | C36: Buildings and land | D36: 745 | E36: 813 | F36: 831 | G36: 824 | H36: 850 | I36: 797 | J36: 804 | K36: 814 | L36: 805 | M36: 804 | N36: 656 | O36: 492 | P36: 480 | Q36: 466 | R36: 420
A37: Non-Current Tangible Assets | C37: Equipment, tools, fixtures and fittings | D37: 30894 | E37: 40079 | F37: 41608 | G37: 38994 | H37: 37843 | I37: 32165 | J37: 26144 | K37: 21372 | L37: 18326 | M37: 16589 | N37: 14813 | O37: 14319 | P37: 11961 | Q37: 8821 | R37: 7134
A38: Non-Current Tangible Assets | C38: Right-of-use assets | D38: 59535
A39: Minority Equity Investments | C39: Participations in associated companies | D39: 247 | E39: 210 | F39: 126
A40: Other Non-Operating Investments | C40: Other shares and participating rights | D40: 539 | E40: 429 | F40: 352
A41: Other Non-Operating Investments | C41: Long-term receivables | D41: 907 | E41: 912 | F41: 885 | G41: 1039 | H41: 1014 | I41: 862 | J41: 709 | K41: 659 | L41: 628 | M41: 608 | N41: 518 | O41: 551 | P41: 476 | Q41: 253 | R41: 155
A42: Deferred Tax Asset | C42: Deferred tax receivables | D42: 5714 | E42: 4322 | F42: 3794 | G42: 2916 | H42: 2862 | I42: 2338 | J42: 2237 | K42: 1367 | L42: 1624 | M42: 1234 | N42: 1065 | O42: 1246 | P42: 1299 | Q42: 883 | R42: 102
C43: Total fixed assets | D43: =SUM(D31:D42) -> 109013 | E43: =SUM(E31:E42) -> 58213 | F43: =SUM(F31:F42) -> 57214 | G43: =SUM(G31:G42) -> 50816 | H43: =SUM(H31:H42) -> 47916 | I43: =SUM(I31:I42) -> 40277 | J43: =SUM(J31:J42) -> 32856 | K43: =SUM(K31:K42) -> 26488 | ... R43: =SUM(R31:R42) -> 8033
A45: Inventories | C45: Stock-in-trade | D45: 38209 | E45: 37823 | F45: 37721 | G45: 33712 | H45: 31732 | I45: 24833 | J45: 19403 | K45: 16695 | L45: 15213 | M45: 13819 | N45: 11487 | O45: 10240 | P45: 8500 | Q45: 7969 | R45: 7220
A46: Trade Receivables | C46: Accounts receivable | D46: 3086 | E46: 5879 | F46: 6329 | G46: 5297 | H46: 4881 | I46: 4021 | J46: 3659 | K46: 3107 | L46: 2207 | M46: 2337 | N46: 2258 | O46: 1990 | P46: 1991 | Q46: 1122 | R46: 865
A47: Other Current Assets | C47: Tax receivables | D47: 1686 | E47: 1555 | F47: 1448 | G47: 2375 | H47: 0 | I47: 0 | J47: 0 | K47: 0 | L47: 0 | M47: 0 | N47: 0 | O47: 0 | P47: 0 | Q47: 0
A48: Other Current Assets | C48: Other receivables | D48: =2397-D49 -> 1667 | E48: =1736-E49 -> 1075 | F48: =1607-F49 -> 1235 | G48: =1874-G49 -> 1377 | H48: =2533-H49 -> 1685 | I48: =1469+379-I49 -> 1141 | J48: 1027 | K48: =907-186 -> 721 | L48: =1533-158 -> 1375 | M48: =1375-456 -> 919 | N48: =1453-457 -> 996 | O48: =889-260 -> 629 | P48: =1206-660 -> 546 | Q48: =356-7 -> 349 | R48: 249
A49: Derivatives - Asset | C49: Forward contracts | D49: 730 | E49: 661 | F49: 372 | G49: 497 | H49: 848 | I49: 707 | J49: 443 | K49: =186 -> 186 | L49: 158 | M49: 456 | N49: 457 | O49: 260 | P49: 660 | Q49: 7 | R49: 0
A50: Other Current Assets | C50: Prepaid expenses | D50: 3440 | E50: 2967 | F50: 2881 | G50: 2770 | H50: 2071 | I50: 1884 | J50: 1516 | K50: 1255 | L50: 1136 | M50: 1110 | N50: 876 | O50: 937 | P50: 948 | Q50: 634 | R50: 563
A51: Cash and Cash Equivalents | C51: Short-term investments | D51: 960 | E51: 2242 | F51: 1162 | G51: 601 | H51: 1134 | I51: 1026 | J51: 2602 | K51: 3306 | L51: 2995 | M51: 6958 | N51: 8167 | O51: 3001 | P51: 0 | Q51: 4900 | R51: 8748
...

Sheet Standardized Statements
B1: 2020 | C1: 2019 | D1: 2018 | E1: 2017 | F1: 2016 | G1: 2015 | H1: 2014 | I1: 2013 | J1: 2012 | K1: 2011 | L1: 2010 | M1: 2009 | N1: 2008 | O1: 2007 | P1: 2006
A2: INCOME STATEMENT
B3: =DSUM('Financial Statements'!$A$1:$R$170,"2020",$R$3:$R$4) -> 1043098 | C3: =DSUM('Financial Statements'!$A$1:$R$170,"2019",$R$3:$R$4) -> 774831 | D3: =DSUM('Financial Statements'!$A$1:$R$170,"2018",$R$3:$R$4) -> 765028 | E3: =DSUM('Financial Statements'!$A$1:$R$170,"2017",$R$3:$R$4) -> 712543 | F3: =DSUM('Financial Statements'!$A$1:$R$170,"2016",$R$3:$R$4) -> 674732 | G3: =DSUM('Financial Statements'!$A$1:$R$170,"2015",$R$3:$R$4) -> 629290 | H3: =DSUM('Financial Statements'!$A$1:$R$170,"2014",$R$3:$R$4) -> 575846 | I3: =DSUM('Financial Statements'!$A$1:$R$170,"2013",$R$3:$R$4) -> 504785 | J3: =DSUM('Financial Statements'!$A$1:$R$170,"2012",$R$3:$R$4) -> 473455 | K3: =DSUM('Financial Statements'!$A$1:$R$170,"2011",$R$3:$R$4) -> 464938 | L3: =DSUM('Financial Statements'!$A$1:$R$170,"2010",$R$3:$R$4) -> 487175 | M3: =DSUM('Financial Statements'!$A$1:$R$170,"2009",$R$3:$R$4) -> 441978 | N3: =DSUM('Financial Statements'!$A$1:$R$170,"2008",$R$3:$R$4) -> 445743 | O3: =DSUM('Financial Statements'!$A$1:$R$170,"2007",$R$3:$R$4) -> 368844 | P3: =DSUM('Financial Statements'!$A$1:$R$170,"2006",$R$3:$R$4) -> 291885 | R3: Standard accounts
A4: Revenue | B4: 187031 | C4: 232755 | D4: 210400 | E4: 200004 | F4: 192267 | G4: 180861 | H4: 151419 | I4: 128562 | J4: 120799 | K4: 109999 | L4: 108483 | M4: 101393 | N4: 88532 | O4: 78346 | P4: 68400
A5: Cost of Sales (by function) | B5: -93487 | C5: -110302 | D5: -99513 | E5: -91914 | F5: -86090 | G5: -77694 | H5: -62367 | I5: -52529 | J5: -48928 | K5: -43852 | L5: -40214 | M5: -38919 | N5: -34064 | O5: -30499 | P5: -27736
A6: SG&A (by function) | B6: -90438 | C6: -105091 | D6: -95380 | E6: -87508 | F6: -82336 | G6: -76204 | H6: -63443 | I6: -53843 | J6: -50092 | K6: -45739 | L6: -43598 | M6: -40819 | N6: -34320 | O6: -29457 | P6: -25357
A7: Other Operating Income, Net of Other Operating Expense (by function) | B7: 0 | C7: 0 | D7: 0 | E7: 0 | F7: 0 | G7: 0 | H7: 0 | I7: 0 | J7: 0 | K7: 0 | L7: 0 | M7: 0 | N7: 0 | O7: 0 | P7: 0
A8: Investment Income | B8: 0 | C8: 0 | D8: 0 | E8: 0 | F8: 0 | G8: 0 | H8: 0 | I8: 0 | J8: 0 | K8: 0 | L8: 0 | M8: 0 | N8: 0 | O8: 0 | P8: 0
A9: Interest Income | B9: 252 | C9: 376 | D9: 292 | E9: 281 | F9: 224 | G9: 310 | H9: 328 | I9: 367 | J9: 536 | K9: 568 | L9: 356 | M9: 467 | N9: 1060 | O9: 793 | P9: 515
A10: Interest Expense | B10: -1306 | C10: -347 | D10: -160 | E10: -54 | F10: -26 | G10: -31 | H10: -42 | I10: -31 | J10: -30 | K10: -34 | L10: -19 | M10: -19 | N10: -18 | O10: -13 | P10: -14
A11: Net Non-Recurring Income or Expense | B11: 0 | C11: 0 | D11: 0 | E11: 0 | F11: 0 | G11: 0 | H11: 0 | I11: 0 | J11: 0 | K11: 0 | L11: 0 | M11: 0 | N11: 0 | O11: 0 | P11: 0
A12: Tax Expense | B12: -809 | C12: -3948 | D12: -2987 | E12: -4625 | F12: -5403 | G12: -6344 | H12: -5919 | I12: -5374 | J12: -5418 | K12: -5121 | L12: -6327 | M12: -5719 | N12: -5896 | O12: -5582 | P12: -5011
A13: Profit/Loss to Non-Controlling Interest | B13: 0 | C13: 0 | D13: 0 | E13: 0 | F13: 0 | G13: 0 | H13: 0 | I13: 0 | J13: 0 | K13: 0 | L13: 0 | M13: 0 | N13: 0 | O13: 0 | P13: 0
A14: Profit/Loss to Ordinary Shareholders | B14: =SUM(B4:B13) -> 1243 | C14: =SUM(C4:C13) -> 13443 | D14: =SUM(D4:D13) -> 12652 | E14: =SUM(E4:E13) -> 16184 | F14: =SUM(F4:F13) -> 18636 | G14: =SUM(G4:G13) -> 20898 | H14: =SUM(H4:H13) -> 19976 | I14: =SUM(I4:I13) -> 17152 | ... P14: =SUM(P4:P13) -> 10797
A16: PRO FORMA ITEMS
B17: =DSUM('Financial Statements'!$A$1:$R$170,"2020",$R$3:$R$4) -> 1043098 | C17: =DSUM('Financial Statements'!$A$1:$R$170,"2019",$R$3:$R$4) -> 774831 | D17: =DSUM('Financial Statements'!$A$1:$R$170,"2018",$R$3:$R$4) -> 765028 | E17: =DSUM('Financial Statements'!$A$1:$R$170,"2017",$R$3:$R$4) -> 712543 | F17: =DSUM('Financial Statements'!$A$1:$R$170,"2016",$R$3:$R$4) -> 674732 | G17: =DSUM('Financial Statements'!$A$1:$R$170,"2015",$R$3:$R$4) -> 629290 | H17: =DSUM('Financial Statements'!$A$1:$R$170,"2014",$R$3:$R$4) -> 575846 | I17: =DSUM('Financial Statements'!$A$1:$R$170,"2013",$R$3:$R$4) -> 504785 | J17: =DSUM('Financial Statements'!$A$1:$R$170,"2012",$R$3:$R$4) -> 473455 | K17: =DSUM('Financial Statements'!$A$1:$R$170,"2011",$R$3:$R$4) -> 464938 | L17: =DSUM('Financial Statements'!$A$1:$R$170,"2010",$R$3:$R$4) -> 487175 | M17: =DSUM('Financial Statements'!$A$1:$R$170,"2009",$R$3:$R$4) -> 441978 | N17: =DSUM('Financial Statements'!$A$1:$R$170,"2008",$R$3:$R$4) -> 445743 | O17: =DSUM('Financial Statements'!$A$1:$R$170,"2007",$R$3:$R$4) -> 368844 | P17: =DSUM('Financial Statements'!$A$1:$R$170,"2006",$R$3:$R$4) -> 291885
A18: Profit/Loss of Discontinued Operations | B18: 0 | C18: 0 | D18: 0 | E18: 0 | F18: 0 | G18: 0 | H18: 0 | I18: 0 | J18: 0 | K18: 0 | L18: 0 | M18: 0 | N18: 0 | O18: 0 | P18: 0
A19: Cost of Materials (by nature) | B19: -91538 | C19: -109732 | D19: -98955 | E19: -91178 | F19: -85243 | G19: -76969 | H19: -61799 | I19: -52059 | J19: -48513 | K19: -43486 | L19: -39878 | M19: -38609 | N19: -33819 | O19: -30296 | P19: -27564
A20: Personnel Expenses (by nature) | B20: -36952 | C20: -42385 | D20: -38543 | E20: -35634 | F20: -32561 | G20: -29952 | H20: -25048 | I20: -21423 | J20: -19893 | K20: -18505 | L20: -16628 | M20: -17507 | N20: -14484 | O20: -12168 | P20: -10991
A21: Depreciation and Amortization (by nature) | B21: -25953 | C21: -11051 | D21: -9671 | E21: -8488 | F21: -7605 | G21: -6399 | H21: -5045 | I21: -4191 | J21: -3705 | K21: -3262 | L21: -3061 | M21: -2830 | N21: -1856 | O21: -1840 | P21: -1624
A22: Other Operating Income, Net of Other Operating Expense (by nature) | B22: 0 | C22: 0 | D22: 0 | E22: 0 | F22: 0 | G22: 0 | H22: 0 | I22: 0 | J22: 0 | K22: 0 | L22: 0 | M22: 0 | N22: 0 | O22: 0 | P22: 0
A24: BALANCE SHEET - ASSETS
B25: =DSUM('Financial Statements'!$A$1:$R$170,"2020",$R$3:$R$4) -> 1043098 | C25: =DSUM('Financial Statements'!$A$1:$R$170,"2019",$R$3:$R$4) -> 774831 | D25: =DSUM('Financial Statements'!$A$1:$R$170,"2018",$R$3:$R$4) -> 765028 | E25: =DSUM('Financial Statements'!$A$1:$R$170,"2017",$R$3:$R$4) -> 712543 | F25: =DSUM('Financial Statements'!$A$1:$R$170,"2016",$R$3:$R$4) -> 674732 | G25: =DSUM('Financial Statements'!$A$1:$R$170,"2015",$R$3:$R$4) -> 629290 | H25: =DSUM('Financial Statements'!$A$1:$R$170,"2014",$R$3:$R$4) -> 575846 | I25: =DSUM('Financial Statements'!$A$1:$R$170,"2013",$R$3:$R$4) -> 504785 | J25: =DSUM('Financial Statements'!$A$1:$R$170,"2012",$R$3:$R$4) -> 473455 | K25: =DSUM('Financial Statements'!$A$1:$R$170,"2011",$R$3:$R$4) -> 464938 | L25: =DSUM('Financial Statements'!$A$1:$R$170,"2010",$R$3:$R$4) -> 487175 | M25: =DSUM('Financial Statements'!$A$1:$R$170,"2009",$R$3:$R$4) -> 441978 | N25: =DSUM('Financial Statements'!$A$1:$R$170,"2008",$R$3:$R$4) -> 445743 | O25: =DSUM('Financial Statements'!$A$1:$R$170,"2007",$R$3:$R$4) -> 368844 | P25: =DSUM('Financial Statements'!$A$1:$R$170,"2006",$R$3:$R$4) -> 291885
A26: Cash and Cash Equivalents | B26: 16540 | C26: 12312 | D26: 11590 | E26: 9718 | F26: 9446 | G26: 12950 | H26: 16693 | I26: 17224 | J26: 17143 | K26: 21277 | L26: 24858 | M26: 22025 | N26: 22726 | O26: 20964 | P26: 18625
A27: Trade Receivables | B27: 3086 | C27: 5879 | D27: 6329 | E27: 5297 | F27: 4881 | G27: 4021 | H27: 3659 | I27: 3107 | J27: 2207 | K27: 2337 | L27: 2258 | M27: 1990 | N27: 1991 | O27: 1122 | P27: 865
A28: Inventories | B28: 38209 | C28: 37823 | D28: 37721 | E28: 33712 | F28: 31732 | G28: 24833 | H28: 19403 | I28: 16695 | J28: 15213 | K28: 13819 | L28: 11487 | M28: 10240 | N28: 8500 | O28: 7969 | P28: 7220
A29: Other Current Assets | B29: 6793 | C29: 5597 | D29: 5564 | E29: 6522 | F29: 3756 | G29: 3025 | H29: 2543 | I29: 1976 | J29: 2511 | K29: 2029 | L29: 1872 | M29: 1566 | N29: 1494 | O29: 983 | P29: 812
A30: Non-Current Tangible Assets | B30: 91365 | C30: 41303 | D30: 42947 | E30: 40410 | F30: 39323 | G30: 33622 | H30: 27457 | I30: 22777 | J30: 19668 | K30: 17978 | L30: 16157 | M30: 15555 | N30: 13100 | O30: 9553 | P30: 7776
A31: Non-Current Intangible Assets | B31: 10241 | C31: 11037 | D31: 9110 | E31: 6451 | F31: 4717 | G31: 3455 | H31: 2453 | I31: 1685 | J31: 1021 | K31: 450 | L31: 510 | M31: 930 | N31: 997 | O31: 0 | P31: 0
A32: Minority Equity Investments | B32: 247 | C32: 210 | D32: 126 | E32: 0 | F32: 0 | G32: 0 | H32: 0 | I32: 0 | J32: 0 | K32: 0 | L32: 0 | M32: 0 | N32: 0 | O32: 0 | P32: 0
A33: Other Non-Operating Investments | B33: 1446 | C33: 1341 | D33: 1237 | E33: 1039 | F33: 1014 | G33: 862 | H33: 709 | I33: 659 | J33: 628 | K33: 608 | L33: 518 | M33: 551 | N33: 476 | O33: 253 | P33: 155
A34: Deferred Tax Asset | B34: 5714 | C34: 4322 | D34: 3794 | E34: 2916 | F34: 2862 | G34: 2338 | H34: 2237 | I34: 1367 | J34: 1624 | K34: 1234 | L34: 1065 | M34: 1246 | N34: 1299 | O34: 883 | P34: 102
A35: Derivatives - Asset | B35: 730 | C35: 661 | D35: 372 | E35: 497 | F35: 848 | G35: 707 | H35: 443 | I35: 186 | J35: 158 | K35: 456 | L35: 457 | M35: 260 | N35: 660 | O35: 7 | P35: 0
A36: Assets Held For Sale | B36: 0 | C36: 0 | D36: 0 | E36: 0 | F36: 0 | G36: 0 | H36: 0 | I36: 0 | J36: 0 | K36: 0 | L36: 0 | M36: 0 | N36: 0 | O36: 0 | P36: 0
A37: Total Assets | B37: =SUM(B26:B36) -> 174371 | C37: =SUM(C26:C36) -> 120485 | D37: =SUM(D26:D36) -> 118790 | E37: =SUM(E26:E36) -> 106562 | F37: =SUM(F26:F36) -> 98579 | G37: =SUM(G26:G36) -> 85813 | H37: =SUM(H26:H36) -> 75597 | I37: =SUM(I26:I36) -> 65676 | ... P37: =SUM(P26:P36) -> 35555
A39: BALANCE SHEET - EQUITY & LIABILITIES
B40: =DSUM('Financial Statements'!$A$1:$R$170,"2020",$R$3:$R$4) -> 1043098 | C40: =DSUM('Financial Statements'!$A$1:$R$170,"2019",$R$3:$R$4) -> 774831 | D40: =DSUM('Financial Statements'!$A$1:$R$170,"2018",$R$3:$R$4) -> 765028 | E40: =DSUM('Financial Statements'!$A$1:$R$170,"2017",$R$3:$R$4) -> 712543 | F40: =DSUM('Financial Statements'!$A$1:$R$170,"2016",$R$3:$R$4) -> 674732 | G40: =DSUM('Financial Statements'!$A$1:$R$170,"2015",$R$3:$R$4) -> 629290 | H40: =DSUM('Financial Statements'!$A$1:$R$170,"2014",$R$3:$R$4) -> 575846 | I40: =DSUM('Financial Statements'!$A$1:$R$170,"2013",$R$3:$R$4) -> 504785 | J40: =DSUM('Financial Statements'!$A$1:$R$170,"2012",$R$3:$R$4) -> 473455 | K40: =DSUM('Financial Statements'!$A$1:$R$170,"2011",$R$3:$R$4) -> 464938 | L40: =DSUM('Financial Statements'!$A$1:$R$170,"2010",$R$3:$R$4) -> 487175 | M40: =DSUM('Financial Statements'!$A$1:$R$170,"2009",$R$3:$R$4) -> 441978 | N40: =DSUM('Financial Statements'!$A$1:$R$170,"2008",$R$3:$R$4) -> 445743 | O40: =DSUM('Financial Statements'!$A$1:$R$170,"2007",$R$3:$R$4) -> 368844 | P40: =DSUM('Financial Statements'!$A$1:$R$170,"2006",$R$3:$R$4) -> 291885
A41: Current Debt | B41: 21174 | C41: 7051 | D41: 9289 | E41: 9870 | F41: 2127 | G41: 0 | H41: 0 | I41: 0 | J41: 0 | K41: 0 | L41: 0 | M41: 0 | N41: 0 | O41: 0 | P41: 0
A42: Trade Payables | B42: 9511 | C42: 7838 | D42: 6800 | E42: 7215 | F42: 7262 | G42: 6000 | H42: 5520 | I42: 4870 | J42: 4234 | K42: 4307 | L42: 3965 | M42: 3667 | N42: 3658 | O42: 2483 | P42: 1942
A43: Other Current Liabilities | B43: 25012 | C43: 32468 | D43: 27892 | E43: 22735 | F43: 21140 | G43: 16635 | H43: 14529 | I43: 12242 | J43: 9554 | K43: 10300 | L43: 9706 | M43: 7088 | N43: 6987 | O43: 6219 | P43: 5054
...

Sheet Lease adjustments
A1: Minimum operating lease payments | B1: 2020 | C1: 2019 | D1: 2018 | E1: 2017 | F1: 2016 | G1: 2015 | H1: 2014 | I1: 2013 | J1: 2012 | K1: 2011 | L1: 2010 | M1: 2009 | N1: 2008 | O1: 2007 | P1: 2006 | R1: Notes
A2: Within one year | B2: 0 | C2: 16234 | D2: 16234 | E2: 16219 | F2: 16068 | G2: 14626 | H2: 13210 | I2: 11363 | J2: 10080 | K2: 9942 | L2: 9546 | M2: 9383 | N2: 8918 | O2: 6801 | P2: 6169
A3: In two to five years | B3: 0 | C3: 36562 | D3: 37535 | E3: 41788 | F3: 41605 | G3: 41732 | H3: 39680 | I3: 31446 | J3: 27800 | K3: 28085 | L3: 27255 | M3: 26416 | N3: 26368 | O3: 19732 | P3: 17689
A4: Over five years | B4: 0 | C4: 18110 | D4: 16413 | E4: 20330 | F4: 23820 | G4: 28965 | H4: 25727 | I4: 20831 | J4: 17440 | K4: 18273 | L4: 17878 | M4: 18546 | N4: 18728 | O4: 12478 | P4: 11593
A6: Interest rate | B6: 0.02 | C6: 0.02 | D6: 0.02 | E6: 0.02 | F6: 0.0205 | G6: 0.0215 | H6: 0.019 | I6: 0.021 | J6: 0.0185 | K6: 0.032 | L6: 0.028 | M6: 0.0305 | N6: 0.0515 | O6: 0.0475 | P6: 0.044 | R6: AA Corporate bond yield (BOFA ML Corporate Bond Index)
A7: Actual lease payment | B7: 0 | C7: =26347-5225 -> 21122 | D7: =24801-4428 -> 20373 | E7: 19126 | F7: 20554 | G7: 20554 | H7: 17176 | I7: 15044 | J7: 14056 | K7: 12993 | L7: 12891 | M7: 12249 | N7: 9776 | O7: 8467 | P7: 7549 | R7: Actual lease payment in 2007 (8,467) is higher than minimum operating lease payments within one year in 2006 (6,169) listed in the previous year, because the firm signed up new leasese in 2007 and paid some of the new leaseses
A8: Tax rate | B8: 0.22 | C8: 0.22 | D8: 0.22 | E8: 0.22 | F8: 0.22 | G8: 0.22 | H8: 0.22 | I8: 0.22 | J8: 0.263 | K8: 0.263 | L8: 0.263 | M8: 0.28 | N8: 0.28 | O8: 0.28 | P8: 0.28
A10: 1 | B10: =B2 -> 0 | C10: =C2 -> 16234 | D10: =D2 -> 16234 | E10: =E2 -> 16219 | F10: =F2 -> 16068 | G10: =G2 -> 14626 | H10: =H2 -> 13210 | I10: =I2 -> 11363 | ... P10: =P2 -> 6169
A11: 2 | B11: =B$3/4 -> 0 | C11: =C$3/4 -> 9140.5 | D11: =D$3/4 -> 9383.75 | E11: =E$3/4 -> 10447 | F11: =F$3/4 -> 10401.25 | G11: =G$3/4 -> 10433 | H11: =H$3/4 -> 9920 | I11: =I$3/4 -> 7861.5 | ... P11: =P$3/4 -> 4422.25
A12: 3 | B12: =B$3/4 -> 0 | C12: =C$3/4 -> 9140.5 | D12: =D$3/4 -> 9383.75 | E12: =E$3/4 -> 10447 | F12: =F$3/4 -> 10401.25 | G12: =G$3/4 -> 10433 | H12: =H$3/4 -> 9920 | I12: =I$3/4 -> 7861.5 | ... P12: =P$3/4 -> 4422.25
A13: 4 | B13: =B$3/4 -> 0 | C13: =C$3/4 -> 9140.5 | D13: =D$3/4 -> 9383.75 | E13: =E$3/4 -> 10447 | F13: =F$3/4 -> 10401.25 | G13: =G$3/4 -> 10433 | H13: =H$3/4 -> 9920 | I13: =I$3/4 -> 7861.5 | ... P13: =P$3/4 -> 4422.25
A14: 5 | B14: =B$3/4 -> 0 | C14: =C$3/4 -> 9140.5 | D14: =D$3/4 -> 9383.75 | E14: =E$3/4 -> 10447 | F14: =F$3/4 -> 10401.25 | G14: =G$3/4 -> 10433 | H14: =H$3/4 -> 9920 | I14: =I$3/4 -> 7861.5 | ... P14: =P$3/4 -> 4422.25
A15: 6 | B15: =0 -> 0 | C15: =C14 -> 9140.5 | D15: =D14 -> 9383.75 | E15: =E14 -> 10447 | F15: =F14 -> 10401.25 | G15: =G14 -> 10433 | H15: =H14 -> 9920 | I15: =I14 -> 7861.5 | J15: =J14 -> 6950 | ... P15: =P14 -> 4422.25 | R15: The allocation of minimum operating leases payments over five years is based on assumptions.
A16: 7 | B16: 0 | C16: =C4-C15 -> 8969.5 | D16: =D4-D15 -> 7029.25 | E16: =E4-E15 -> 9883 | F16: =F15 -> 10401.25 | G16: =G15 -> 10433 | H16: =H15 -> 9920 | I16: =I15 -> 7861.5 | J16: =J15 -> 6950 | K16: =K15 -> 7021.25 | L16: =L15 -> 6813.75 | M16: =M15 -> 6604 | ... P16: =P15 -> 4422.25
A17: 8 | F17: =F4-F15-F16 -> 3017.5 | G17: =G4-G15-G16 -> 8099 | H17: =H4-H15-H16 -> 5887 | I17: =I4-I15-I16 -> 5108 | J17: =J4-J15-J16 -> 3540 | K17: =K4-K15-K16 -> 4230.5 | L17: =L4-L15-L16 -> 4250.5 | M17: =M4-M15-M16 -> 5338 | ... P17: =P4-P15-P16 -> 2748.5
A20: Total present value/Total finance lease obligation | B20: =NPV(B6,B10:B17) -> 0 | C20: =NPV(C6,C10:C17) -> 65962.78 | D20: =NPV(D6,D10:D17) -> 65397.744 | E20: =NPV(E6,E10:E17) -> 72780.718 | F20: =NPV(F6,F10:F17) -> 75305.85 | G20: =NPV(G6,G10:G17) -> 78071.029 | H20: =NPV(H6,H10:H17) -> 72742.396 | I20: =NPV(I6,I10:I17) -> 58439.615 | ... P20: =NPV(P6,P10:P17) -> 29775.325
A21: Present value Yr 2 onwards | B21: =NPV(B6,0,B11:B17) -> 0 | C21: =NPV(C6,0,C11:C17) -> 50047.094 | D21: =NPV(D6,0,D11:D17) -> 49482.057 | E21: =NPV(E6,0,E11:E17) -> 56879.738 | F21: =NPV(F6,0,F11:F17) -> 59560.627 | G21: =NPV(G6,0,G11:G17) -> 63752.87 | H21: =NPV(H6,0,H11:H17) -> 59778.706 | I21: =NPV(I6,0,I11:I17) -> 47310.33 | ... P21: =NPV(P6,0,P11:P17) -> 23866.321 | R21: This is the present value of minimum operating lease payments from Year 2 onwards. This number times (1+interest rate) will be the carrying value of current finance lease obligations at the end of the following year.
A22: Current portion of finance lease obligation | B22: =B10-B20*B6 -> 0 | C22: =C10-C20*C6 -> 14914.744 | D22: =D10-D20*D6 -> 14926.045 | E22: =E10-E20*E6 -> 14763.386 | F22: =F10-F20*F6 -> 14524.23 | G22: =G10-G20*G6 -> 12947.473 | H22: =H10-H20*H6 -> 11827.894 | I22: =I10-I20*I6 -> 10135.768 | ... P22: =P10-P20*P6 -> 4858.8857 | R22: Minimum lease payment next year - Finance lease obligation * (1+interest rate)
A24: PV of New lease commitments | B24: 0 | C24: =(C20-(1+D6)*D21)+(C7-D2) -> 20379.082 | D24: =(D20-(1+E6)*E21)+(D7-E2) -> 11534.411 | E24: =(E20-(1+F6)*F21)+(E7-F2) -> 15057.099 | F24: =(F20-(1+G6)*G21)+(F7-G2) -> 16110.293 | G24: =(G20-(1+H6)*H21)+(G7-H2) -> 24500.528 | H24: =(H20-(1+I6)*I21)+(H7-I2) -> 30251.549 | I24: =(I20-(1+J6)*J21)+(I7-J2) -> 21162.138 | J24: =(J20-(1+K6)*K21)+(J7-K2) -> 14307.112 | ... O24: =(O20-(1+P6)*P21)+(O7-P2) -> 9771.4003 | R24: PV of New lease commitments in 2007=[ Total finance lease obligation in 2007 - Carrying value of 2006 finance lease obligation (i.e. 23,866) times (1+interest rate)) ]+Payment of new leases during the year (i.e. 8,467-6,169)
A26: Interest expense | C26: =D20*D6 -> 1307.9549 | D26: =E20*E6 -> 1455.6144 | E26: =F20*F6 -> 1543.7699 | F26: =G20*G6 -> 1678.5271 | G26: =H20*H6 -> 1382.1055 | H26: =I20*I6 -> 1227.2319 | I26: =J20*J6 -> 950.36557 | J26: =K20*K6 -> 1585.1163 | ... O26: =P20*P6 -> 1310.1143 | R26: Interest expense=Carrying value of Finance Lease Obligation * Interest rate
A27: Total lease repayment | C27: =C7-C26 -> 19814.045 | D27: =D7-D26 -> 18917.386 | E27: =E7-E26 -> 17582.23 | F27: =F7-F26 -> 18875.473 | G27: =G7-G26 -> 19171.894 | H27: =H7-H26 -> 15948.768 | I27: =I7-I26 -> 14093.634 | J27: =J7-J26 -> 12470.884 | ... O27: =O7-O26 -> 7156.8857 | R27: Lease repayment=Actual lease payment - Interest expense; this number is higher than current portion of finance lease obligation in the previous year, because the firm paid new leases signed in current year
A28: Lease repayment of new lease | C28: =C27-D22 -> 4888 | D28: =D27-E22 -> 4154 | E28: =E27-F22 -> 3058 | F28: =F27-G22 -> 5928 | G28: =G27-H22 -> 7344 | H28: =H27-I22 -> 5813 | I28: =I27-J22 -> 4964 | J28: =J27-K22 -> 4114 | ... O28: =O27-P22 -> 2298 | R28: The difference between total lease repayment and current portfion of finance lease obligation of the previous year
A29: Depreciation expense | C29: =C27 -> 19814.045 | D29: =D27 -> 18917.386 | E29: =E27 -> 17582.23 | F29: =F27 -> 18875.473 | G29: =G27 -> 19171.894 | H29: =H27 -> 15948.768 | I29: =I27 -> 14093.634 | J29: =J27 -> 12470.884 | ... O29: =O27 -> 7156.8857 | R29: For simplicity, we assume depreciation expense=lease repayment. In this way, the adjustments would have 0 impact on pre-tax profit and shareholder's equity.
A31: Adjustments:
A32: Non-current tangible assets | B32: 0 | C32: =D20+C24-C29 -> 65962.78 | D32: =E20+D24-D29 -> 65397.744 | E32: =F20+E24-E29 -> 72780.718 | F32: =G20+F24-F29 -> 75305.85 | G32: =H20+G24-G29 -> 78071.029 | H32: =I20+H24-H29 -> 72742.396 | I32: =J20+I24-I29 -> 58439.615 | J32: =K20+J24-J29 -> 51371.112 | ... O32: =P20+O24-O29 -> 32389.84 | P32: =P20 -> 29775.325
A33: Current debt | B33: 0 | C33: =C22 -> 14914.744 | D33: =D22 -> 14926.045 | E33: =E22 -> 14763.386 | F33: =F22 -> 14524.23 | G33: =G22 -> 12947.473 | H33: =H22 -> 11827.894 | I33: =I22 -> 10135.768 | J33: =J22 -> 9129.6344 | ... P33: =P22 -> 4858.8857
A34: Non-current debt | B34: 0 | C34: =C20-C33 -> 51048.036 | D34: =D20-D33 -> 50471.699 | E34: =E20-E33 -> 58017.333 | F34: =F20-F33 -> 60781.619 | G34: =G20-G33 -> 65123.557 | H34: =H20-H33 -> 60914.502 | I34: =I20-I33 -> 48303.847 | J34: =J20-J33 -> 42241.477 | ... P34: =P20-P33 -> 24916.439
A35: Deferred tax liability | B35: 0 | C35: =-C41 -> 0 | D35: =-D41 -> 0 | E35: =-E41 -> -4.0017767e-13 | F35: =-F41 -> 0 | G35: =-G41 -> 0 | H35: =-H41 -> 0 | I35: =-I41 -> 0 | J35: =-J41 -> 0 | ... O35: =-O41 -> 0
A36: Equity | B36: 0 | C36: =C42 -> 1.5916157e-12 | D36: =D42 -> 6.8212103e-13 | E36: =E42 -> -1.4188117e-12 | F36: =F42 -> -2.2737368e-13 | G36: =G42 -> 0 | H36: =H42 -> -2.2737368e-13 | I36: =I42 -> 3.4106051e-13 | J36: =J42 -> 4.5474735e-13 | ... O36: =O42 -> 2.2737368e-13
A38: Cost of sales/SG&A (Lease expense) | B38: 0 | C38: =C7 -> 21122 | D38: =D7 -> 20373 | E38: =E7 -> 19126 | F38: =F7 -> 20554 | G38: =G7 -> 20554 | H38: =H7 -> 17176 | I38: =I7 -> 15044 | J38: =J7 -> 14056 | ... O38: =O7 -> 8467
A39: Cost of sales/SG&A (Lease expense) | B39: 0 | C39: =-C29 -> -19814.045 | D39: =-D29 -> -18917.386 | E39: =-E29 -> -17582.23 | F39: =-F29 -> -18875.473 | G39: =-G29 -> -19171.894 | H39: =-H29 -> -15948.768 | I39: =-I29 -> -14093.634 | J39: =-J29 -> -12470.884 | ... O39: =-O29 -> -7156.8857
A40: Interest expense | B40: 0 | C40: =-C26 -> -1307.9549 | D40: =-D26 -> -1455.6144 | E40: =-E26 -> -1543.7699 | F40: =-F26 -> -1678.5271 | G40: =-G26 -> -1382.1055 | H40: =-H26 -> -1227.2319 | I40: =-I26 -> -950.36557 | J40: =-J26 -> -1585.1163 | ... O40: =-O26 -> -1310.1143
A41: Tax expense | B41: 0 | C41: =-C8*SUM(C38:C40) -> 0 | D41: =-D8*SUM(D38:D40) -> 0 | E41: =-E8*SUM(E38:E40) -> 4.0017767e-13 | F41: =-F8*SUM(F38:F40) -> 0 | G41: =-G8*SUM(G38:G40) -> 0 | H41: =-H8*SUM(H38:H40) -> 0 | I41: =-I8*SUM(I38:I40) -> 0 | J41: =-J8*SUM(J38:J40) -> 0 | ... O41: =-O8*SUM(O38:O40) -> 0
A42: Net profit | B42: 0 | C42: =SUM(C38:C41) -> 1.5916157e-12 | D42: =SUM(D38:D41) -> 6.8212103e-13 | E42: =SUM(E38:E41) -> -1.4188117e-12 | F42: =SUM(F38:F41) -> -2.2737368e-13 | G42: =SUM(G38:G41) -> 0 | H42: =SUM(H38:H41) -> -2.2737368e-13 | I42: =SUM(I38:I41) -> 3.4106051e-13 | J42: =SUM(J38:J41) -> 4.5474735e-13 | ... O42: =SUM(O38:O41) -> 2.2737368e-13

Sheet Adjusted Statements
A1: Assumptions: | B1: 2020 | C1: 2019 | D1: 2018 | E1: 2017 | F1: 2016 | G1: 2015 | H1: 2014 | I1: 2013 | J1: 2012 | K1: 2011 | L1: 2010 | M1: 2009 | N1: 2008 | O1: 2007 | P1: 2006 | AH1: 2020 | AI1: 2019 | AJ1: 2018 | AK1: 2017 | AL1: 2016 | AM1: 2015 | AN1: 2014 | AO1: 2013 | AP1: 2012 | AQ1: 2011 | AR1: 2010 | AS1: 2009 | AT1: 2008 | AU1: 2007 | AV1: 2006
A2: Operating cash percentage | B2: 0.05 | C2: 0.05 | D2: 0.05 | E2: 0.05 | F2: 0.05 | G2: 0.05 | H2: 0.05 | I2: 0.05 | J2: 0.05 | K2: 0.05 | L2: 0.05 | M2: 0.05 | N2: 0.05 | O2: 0.05 | P2: 0.05 | AH2: =B2 -> 0.05 | AI2: =C2 -> 0.05 | AJ2: =D2 -> 0.05 | AK2: =E2 -> 0.05 | AL2: =F2 -> 0.05 | AM2: =G2 -> 0.05 | AN2: =H2 -> 0.05 | AO2: =I2 -> 0.05 | ... AV2: =P2 -> 0.05
B4: 2 | C4: 3 | D4: 4 | E4: 5 | F4: 6 | G4: 7 | H4: 8 | I4: 9 | J4: 10 | K4: 11 | L4: 12 | M4: 13 | N4: 14 | O4: 15 | P4: 16
A5: INCOME STATEMENT | B5: 2020 | C5: 2019 | D5: 2018 | E5: 2017 | F5: 2016 | G5: 2015 | H5: 2014 | I5: 2013 | J5: 2012 | K5: 2011 | L5: 2010 | M5: 2009 | N5: 2008 | O5: 2007 | P5: 2006 | R5: Adj 2020 | S5: Adj 2019 | T5: Adj 2018 | U5: Adj 2017 | V5: Adj 2016 | W5: Adj 2015 | X5: Adj 2014 | Y5: Adj 2013 | Z5: Adj 2012 | AA5: Adj 2011 | AB5: Adj 2010 | AC5: Adj 2009 | AD5: Adj 2008 | AE5: Adj 2007 | AF5: Adj 2006 | AH5: 2020 | AI5: 2019 | AJ5: 2018 | AK5: 2017 | AL5: 2016 | AM5: 2015 | AN5: 2014 | AO5: 2013 | AP5: 2012 | AQ5: 2011 | AR5: 2010 | AS5: 2009 | AT5: 2008 | AU5: 2007 | AV5: 2006
A6: Revenue | B6: =VLOOKUP($A6,'Standardized Statements'!$A:$Q,B$4,FALSE) -> 187031 | C6: =VLOOKUP($A6,'Standardized Statements'!$A:$Q,C$4,FALSE) -> 232755 | D6: =VLOOKUP($A6,'Standardized Statements'!$A:$Q,D$4,FALSE) -> 210400 | E6: =VLOOKUP($A6,'Standardized Statements'!$A:$Q,E$4,FALSE) -> 200004 | F6: =VLOOKUP($A6,'Standardized Statements'!$A:$Q,F$4,FALSE) -> 192267 | G6: =VLOOKUP($A6,'Standardized Statements'!$A:$Q,G$4,FALSE) -> 180861 | H6: =VLOOKUP($A6,'Standardized Statements'!$A:$Q,H$4,FALSE) -> 151419 | I6: =VLOOKUP($A6,'Standardized Statements'!$A:$Q,I$4,FALSE) -> 128562 | ... P6: =VLOOKUP($A6,'Standardized Statements'!$A:$Q,P$4,FALSE) -> 68400 | AH6: =B6+R6 -> 187031 | AI6: =C6+S6 -> 232755 | AJ6: =D6+T6 -> 210400 | AK6: =E6+U6 -> 200004 | AL6: =F6+V6 -> 192267 | AM6: =G6+W6 -> 180861 | AN6: =H6+X6 -> 151419 | AO6: =I6+Y6 -> 128562 | ... AV6: =P6+AF6 -> 68400
A7: Operating expenses | B7: =IF(SUM(B21:B23)<>0,SUM(B21:B23),SUM(B25:B28)) -> -183925 | C7: =IF(SUM(C21:C23)<>0,SUM(C21:C23),SUM(C25:C28)) -> -215393 | D7: =IF(SUM(D21:D23)<>0,SUM(D21:D23),SUM(D25:D28)) -> -194893 | E7: =IF(SUM(E21:E23)<>0,SUM(E21:E23),SUM(E25:E28)) -> -179422 | F7: =IF(SUM(F21:F23)<>0,SUM(F21:F23),SUM(F25:F28)) -> -168426 | G7: =IF(SUM(G21:G23)<>0,SUM(G21:G23),SUM(G25:G28)) -> -153898 | H7: =IF(SUM(H21:H23)<>0,SUM(H21:H23),SUM(H25:H28)) -> -125810 | I7: =IF(SUM(I21:I23)<>0,SUM(I21:I23),SUM(I25:I28)) -> -106372 | ... P7: =IF(SUM(P21:P23)<>0,SUM(P21:P23),SUM(P25:P28)) -> -53093 | R7: =IF(SUM(R21:R23)<>0,SUM(R21:R23),SUM(R25:R28)) -> 0 | S7: =IF(SUM(S21:S23)<>0,SUM(S21:S23),SUM(S25:S28)) -> 1307.9549 | T7: =IF(SUM(T21:T23)<>0,SUM(T21:T23),SUM(T25:T28)) -> 1455.6144 | U7: =IF(SUM(U21:U23)<>0,SUM(U21:U23),SUM(U25:U28)) -> 1543.7699 | V7: =IF(SUM(V21:V23)<>0,SUM(V21:V23),SUM(V25:V28)) -> 1678.5271 | W7: =IF(SUM(W21:W23)<>0,SUM(W21:W23),SUM(W25:W28)) -> 1382.1055 | X7: =IF(SUM(X21:X23)<>0,SUM(X21:X23),SUM(X25:X28)) -> 1227.2319 | Y7: =IF(SUM(Y21:Y23)<>0,SUM(Y21:Y23),SUM(Y25:Y28)) -> 950.36557 | ... AF7: =IF(SUM(AF21:AF23)<>0,SUM(AF21:AF23),SUM(AF25:AF28)) -> 0 | AH7: =B7+R7 -> -183925 | AI7: =C7+S7 -> -214085.05 | AJ7: =D7+T7 -> -193437.39 | AK7: =E7+U7 -> -177878.23 | AL7: =F7+V7 -> -166747.47 | AM7: =G7+W7 -> -152515.89 | AN7: =H7+X7 -> -124582.77 | AO7: =I7+Y7 -> -105421.63 | ... AV7: =P7+AF7 -> -53093
A8: Operating profit | B8: =SUM(B6:B7) -> 3106 | C8: =SUM(C6:C7) -> 17362 | D8: =SUM(D6:D7) -> 15507 | E8: =SUM(E6:E7) -> 20582 | F8: =SUM(F6:F7) -> 23841 | G8: =SUM(G6:G7) -> 26963 | H8: =SUM(H6:H7) -> 25609 | I8: =SUM(I6:I7) -> 22190 | ... P8: =SUM(P6:P7) -> 15307 | R8: =SUM(R6:R7) -> 0 | S8: =SUM(S6:S7) -> 1307.9549 | T8: =SUM(T6:T7) -> 1455.6144 | U8: =SUM(U6:U7) -> 1543.7699 | V8: =SUM(V6:V7) -> 1678.5271 | W8: =SUM(W6:W7) -> 1382.1055 | X8: =SUM(X6:X7) -> 1227.2319 | Y8: =SUM(Y6:Y7) -> 950.36557 | ... AF8: =SUM(AF6:AF7) -> 0 | AH8: =B8+R8 -> 3106 | AI8: =C8+S8 -> 18669.955 | AJ8: =D8+T8 -> 16962.614 | AK8: =E8+U8 -> 22125.77 | AL8: =F8+V8 -> 25519.527 | AM8: =G8+W8 -> 28345.106 | AN8: =H8+X8 -> 26836.232 | AO8: =I8+Y8 -> 23140.366 | ... AV8: =P8+AF8 -> 15307
A9: Investment Income | B9: =VLOOKUP($A9,'Standardized Statements'!$A:$Q,B$4,FALSE) -> 0 | C9: =VLOOKUP($A9,'Standardized Statements'!$A:$Q,C$4,FALSE) -> 0 | D9: =VLOOKUP($A9,'Standardized Statements'!$A:$Q,D$4,FALSE) -> 0 | E9: =VLOOKUP($A9,'Standardized Statements'!$A:$Q,E$4,FALSE) -> 0 | F9: =VLOOKUP($A9,'Standardized Statements'!$A:$Q,F$4,FALSE) -> 0 | G9: =VLOOKUP($A9,'Standardized Statements'!$A:$Q,G$4,FALSE) -> 0 | H9: =VLOOKUP($A9,'Standardized Statements'!$A:$Q,H$4,FALSE) -> 0 | I9: =VLOOKUP($A9,'Standardized Statements'!$A:$Q,I$4,FALSE) -> 0 | ... P9: =VLOOKUP($A9,'Standardized Statements'!$A:$Q,P$4,FALSE) -> 0 | AH9: =B9+R9 -> 0 | AI9: =C9+S9 -> 0 | AJ9: =D9+T9 -> 0 | AK9: =E9+U9 -> 0 | AL9: =F9+V9 -> 0 | AM9: =G9+W9 -> 0 | AN9: =H9+X9 -> 0 | AO9: =I9+Y9 -> 0 | ... AV9: =P9+AF9 -> 0
A10: Net non-recurring income or expense | B10: =VLOOKUP($A10,'Standardized Statements'!$A:$Q,B$4,FALSE) -> 0 | C10: =VLOOKUP($A10,'Standardized Statements'!$A:$Q,C$4,FALSE) -> 0 | D10: =VLOOKUP($A10,'Standardized Statements'!$A:$Q,D$4,FALSE) -> 0 | E10: =VLOOKUP($A10,'Standardized Statements'!$A:$Q,E$4,FALSE) -> 0 | F10: =VLOOKUP($A10,'Standardized Statements'!$A:$Q,F$4,FALSE) -> 0 | G10: =VLOOKUP($A10,'Standardized Statements'!$A:$Q,G$4,FALSE) -> 0 | H10: =VLOOKUP($A10,'Standardized Statements'!$A:$Q,H$4,FALSE) -> 0 | I10: =VLOOKUP($A10,'Standardized Statements'!$A:$Q,I$4,FALSE) -> 0 | ... P10: =VLOOKUP($A10,'Standardized Statements'!$A:$Q,P$4,FALSE) -> 0 | AH10: =B10+R10 -> 0 | AI10: =C10+S10 -> 0 | AJ10: =D10+T10 -> 0 | AK10: =E10+U10 -> 0 | AL10: =F10+V10 -> 0 | AM10: =G10+W10 -> 0 | AN10: =H10+X10 -> 0 | AO10: =I10+Y10 -> 0 | ... AV10: =P10+AF10 -> 0
A11: Interest income | B11: =VLOOKUP($A11,'Standardized Statements'!$A:$Q,B$4,FALSE) -> 252 | C11: =VLOOKUP($A11,'Standardized Statements'!$A:$Q,C$4,FALSE) -> 376 | D11: =VLOOKUP($A11,'Standardized Statements'!$A:$Q,D$4,FALSE) -> 292 | E11: =VLOOKUP($A11,'Standardized Statements'!$A:$Q,E$4,FALSE) -> 281 | F11: =VLOOKUP($A11,'Standardized Statements'!$A:$Q,F$4,FALSE) -> 224 | G11: =VLOOKUP($A11,'Standardized Statements'!$A:$Q,G$4,FALSE) -> 310 | H11: =VLOOKUP($A11,'Standardized Statements'!$A:$Q,H$4,FALSE) -> 328 | I11: =VLOOKUP($A11,'Standardized Statements'!$A:$Q,I$4,FALSE) -> 367 | ... P11: =VLOOKUP($A11,'Standardized Statements'!$A:$Q,P$4,FALSE) -> 515 | AH11: =B11+R11 -> 252 | AI11: =C11+S11 -> 376 | AJ11: =D11+T11 -> 292 | AK11: =E11+U11 -> 281 | AL11: =F11+V11 -> 224 | AM11: =G11+W11 -> 310 | AN11: =H11+X11 -> 328 | AO11: =I11+Y11 -> 367 | ... AV11: =P11+AF11 -> 515
A12: Interest expense | B12: =VLOOKUP($A12,'Standardized Statements'!$A:$Q,B$4,FALSE) -> -1306 | C12: =VLOOKUP($A12,'Standardized Statements'!$A:$Q,C$4,FALSE) -> -347 | D12: =VLOOKUP($A12,'Standardized Statements'!$A:$Q,D$4,FALSE) -> -160 | E12: =VLOOKUP($A12,'Standardized Statements'!$A:$Q,E$4,FALSE) -> -54 | F12: =VLOOKUP($A12,'Standardized Statements'!$A:$Q,F$4,FALSE) -> -26 | G12: =VLOOKUP($A12,'Standardized Statements'!$A:$Q,G$4,FALSE) -> -31 | H12: =VLOOKUP($A12,'Standardized Statements'!$A:$Q,H$4,FALSE) -> -42 | I12: =VLOOKUP($A12,'Standardized Statements'!$A:$Q,I$4,FALSE) -> -31 | ... P12: =VLOOKUP($A12,'Standardized Statements'!$A:$Q,P$4,FALSE) -> -14 | R12: ='Lease adjustments'!B40 -> 0 | S12: ='Lease adjustments'!C40 -> -1307.9549 | T12: ='Lease adjustments'!D40 -> -1455.6144 | U12: ='Lease adjustments'!E40 -> -1543.7699 | V12: ='Lease adjustments'!F40 -> -1678.5271 | W12: ='Lease adjustments'!G40 -> -1382.1055 | X12: ='Lease adjustments'!H40 -> -1227.2319 | Y12: ='Lease adjustments'!I40 -> -950.36557 | ... AF12: ='Lease adjustments'!P40 -> 0 | AH12: =B12+R12 -> -1306 | AI12: =C12+S12 -> -1654.9549 | AJ12: =D12+T12 -> -1615.6144 | AK12: =E12+U12 -> -1597.7699 | AL12: =F12+V12 -> -1704.5271 | AM12: =G12+W12 -> -1413.1055 | AN12: =H12+X12 -> -1269.2319 | AO12: =I12+Y12 -> -981.36557 | ... AV12: =P12+AF12 -> -14
A13: Profit before taxes | B13: =SUM(B8:B12) -> 2052 | C13: =SUM(C8:C12) -> 17391 | D13: =SUM(D8:D12) -> 15639 | E13: =SUM(E8:E12) -> 20809 | F13: =SUM(F8:F12) -> 24039 | G13: =SUM(G8:G12) -> 27242 | H13: =SUM(H8:H12) -> 25895 | I13: =SUM(I8:I12) -> 22526 | ... P13: =SUM(P8:P12) -> 15808 | R13: =SUM(R8:R12) -> 0 | S13: =SUM(S8:S12) -> 0 | T13: =SUM(T8:T12) -> 0 | U13: =SUM(U8:U12) -> -1.8189894e-12 | V13: =SUM(V8:V12) -> 0 | W13: =SUM(W8:W12) -> 0 | X13: =SUM(X8:X12) -> 0 | Y13: =SUM(Y8:Y12) -> 0 | ... AF13: =SUM(AF8:AF12) -> 0 | AH13: =B13+R13 -> 2052 | AI13: =C13+S13 -> 17391 | AJ13: =D13+T13 -> 15639 | AK13: =E13+U13 -> 20809 | AL13: =F13+V13 -> 24039 | AM13: =G13+W13 -> 27242 | AN13: =H13+X13 -> 25895 | AO13: =I13+Y13 -> 22526 | ... AV13: =P13+AF13 -> 15808
A14: Tax expense | B14: =VLOOKUP($A14,'Standardized Statements'!$A:$Q,B$4,FALSE) -> -809 | C14: =VLOOKUP($A14,'Standardized Statements'!$A:$Q,C$4,FALSE) -> -3948 | D14: =VLOOKUP($A14,'Standardized Statements'!$A:$Q,D$4,FALSE) -> -2987 | E14: =VLOOKUP($A14,'Standardized Statements'!$A:$Q,E$4,FALSE) -> -4625 | F14: =VLOOKUP($A14,'Standardized Statements'!$A:$Q,F$4,FALSE) -> -5403 | G14: =VLOOKUP($A14,'Standardized Statements'!$A:$Q,G$4,FALSE) -> -6344 | H14: =VLOOKUP($A14,'Standardized Statements'!$A:$Q,H$4,FALSE) -> -5919 | I14: =VLOOKUP($A14,'Standardized Statements'!$A:$Q,I$4,FALSE) -> -5374 | ... P14: =VLOOKUP($A14,'Standardized Statements'!$A:$Q,P$4,FALSE) -> -5011 | R14: ='Lease adjustments'!B41 -> 0 | S14: ='Lease adjustments'!C41 -> 0 | T14: ='Lease adjustments'!D41 -> 0 | U14: ='Lease adjustments'!E41 -> 4.0017767e-13 | V14: ='Lease adjustments'!F41 -> 0 | W14: ='Lease adjustments'!G41 -> 0 | X14: ='Lease adjustments'!H41 -> 0 | Y14: ='Lease adjustments'!I41 -> 0 | ... AF14: ='Lease adjustments'!P41 -> 0 | AH14: =B14+R14 -> -809 | AI14: =C14+S14 -> -3948 | AJ14: =D14+T14 -> -2987 | AK14: =E14+U14 -> -4625 | AL14: =F14+V14 -> -5403 | AM14: =G14+W14 -> -6344 | AN14: =H14+X14 -> -5919 | AO14: =I14+Y14 -> -5374 | ... AV14: =P14+AF14 -> -5011
A15: Profit after taxes | B15: =SUM(B13:B14) -> 1243 | C15: =SUM(C13:C14) -> 13443 | D15: =SUM(D13:D14) -> 12652 | E15: =SUM(E13:E14) -> 16184 | F15: =SUM(F13:F14) -> 18636 | G15: =SUM(G13:G14) -> 20898 | H15: =SUM(H13:H14) -> 19976 | I15: =SUM(I13:I14) -> 17152 | ... P15: =SUM(P13:P14) -> 10797 | R15: =SUM(R13:R14) -> 0 | S15: =SUM(S13:S14) -> 0 | T15: =SUM(T13:T14) -> 0 | U15: =SUM(U13:U14) -> -1.4188117e-12 | V15: =SUM(V13:V14) -> 0 | W15: =SUM(W13:W14) -> 0 | X15: =SUM(X13:X14) -> 0 | Y15: =SUM(Y13:Y14) -> 0 | ... AF15: =SUM(AF13:AF14) -> 0 | AH15: =B15+R15 -> 1243 | AI15: =C15+S15 -> 13443 | AJ15: =D15+T15 -> 12652 | AK15: =E15+U15 -> 16184 | AL15: =F15+V15 -> 18636 | AM15: =G15+W15 -> 20898 | AN15: =H15+X15 -> 19976 | AO15: =I15+Y15 -> 17152 | ... AV15: =P15+AF15 -> 10797
A16: Profit/loss to non-controlling interest | B16: =VLOOKUP($A16,'Standardized Statements'!$A:$Q,B$4,FALSE) -> 0 | C16: =VLOOKUP($A16,'Standardized Statements'!$A:$Q,C$4,FALSE) -> 0 | D16: =VLOOKUP($A16,'Standardized Statements'!$A:$Q,D$4,FALSE) -> 0 | E16: =VLOOKUP($A16,'Standardized Statements'!$A:$Q,E$4,FALSE) -> 0 | F16: =VLOOKUP($A16,'Standardized Statements'!$A:$Q,F$4,FALSE) -> 0 | G16: =VLOOKUP($A16,'Standardized Statements'!$A:$Q,G$4,FALSE) -> 0 | H16: =VLOOKUP($A16,'Standardized Statements'!$A:$Q,H$4,FALSE) -> 0 | I16: =VLOOKUP($A16,'Standardized Statements'!$A:$Q,I$4,FALSE) -> 0 | ... P16: =VLOOKUP($A16,'Standardized Statements'!$A:$Q,P$4,FALSE) -> 0 | AH16: =B16+R16 -> 0 | AI16: =C16+S16 -> 0 | AJ16: =D16+T16 -> 0 | AK16: =E16+U16 -> 0 | AL16: =F16+V16 -> 0 | AM16: =G16+W16 -> 0 | AN16: =H16+X16 -> 0 | AO16: =I16+Y16 -> 0 | ... AV16: =P16+AF16 -> 0
A17: Profit/loss to ordinary shareholders | B17: =SUM(B15:B16) -> 1243 | C17: =SUM(C15:C16) -> 13443 | D17: =SUM(D15:D16) -> 12652 | E17: =SUM(E15:E16) -> 16184 | F17: =SUM(F15:F16) -> 18636 | G17: =SUM(G15:G16) -> 20898 | H17: =SUM(H15:H16) -> 19976 | I17: =SUM(I15:I16) -> 17152 | ... P17: =SUM(P15:P16) -> 10797 | R17: =SUM(R15:R16) -> 0 | S17: =SUM(S15:S16) -> 0 | T17: =SUM(T15:T16) -> 0 | U17: =SUM(U15:U16) -> -1.4188117e-12 | V17: =SUM(V15:V16) -> 0 | W17: =SUM(W15:W16) -> 0 | X17: =SUM(X15:X16) -> 0 | Y17: =SUM(Y15:Y16) -> 0 | ... AF17: =SUM(AF15:AF16) -> 0 | AH17: =B17+R17 -> 1243 | AI17: =C17+S17 -> 13443 | AJ17: =D17+T17 -> 12652 | AK17: =E17+U17 -> 16184 | AL17: =F17+V17 -> 18636 | AM17: =G17+W17 -> 20898 | AN17: =H17+X17 -> 19976 | AO17: =I17+Y17 -> 17152 | ... AV17: =P17+AF17 -> 10797
A19: OPERATING EXPENSES | B19: 2020 | C19: 2019 | D19: 2018 | E19: 2017 | F19: 2016 | G19: 2015 | H19: 2014 | I19: 2013 | J19: 2012 | K19: 2011 | L19: 2010 | M19: 2009 | N19: 2008 | O19: 2007 | P19: 2006 | AH19: 2020 | AI19: 2019 | AJ19: 2018 | AK19: 2017 | AL19: 2016 | AM19: 2015 | AN19: 2014 | AO19: 2013 | AP19: 2012 | AQ19: 2011 | AR19: 2010 | AS19: 2009 | AT19: 2008 | AU19: 2007 | AV19: 2006
A20: Classification by function:
A21: Cost of Sales (by function) | B21: =VLOOKUP($A21,'Standardized Statements'!$A:$Q,B$4,FALSE) -> -93487 | C21: =VLOOKUP($A21,'Standardized Statements'!$A:$Q,C$4,FALSE) -> -110302 | D21: =VLOOKUP($A21,'Standardized Statements'!$A:$Q,D$4,FALSE) -> -99513 | E21: =VLOOKUP($A21,'Standardized Statements'!$A:$Q,E$4,FALSE) -> -91914 | F21: =VLOOKUP($A21,'Standardized Statements'!$A:$Q,F$4,FALSE) -> -86090 | G21: =VLOOKUP($A21,'Standardized Statements'!$A:$Q,G$4,FALSE) -> -77694 | H21: =VLOOKUP($A21,'Standardized Statements'!$A:$Q,H$4,FALSE) -> -62367 | I21: =VLOOKUP($A21,'Standardized Statements'!$A:$Q,I$4,FALSE) -> -52529 | ... P21: =VLOOKUP($A21,'Standardized Statements'!$A:$Q,P$4,FALSE) -> -27736 | AH21: =B21+R21 -> -93487 | AI21: =C21+S21 -> -110302 | AJ21: =D21+T21 -> -99513 | AK21: =E21+U21 -> -91914 | AL21: =F21+V21 -> -86090 | AM21: =G21+W21 -> -77694 | AN21: =H21+X21 -> -62367 | AO21: =I21+Y21 -> -52529 | ... AV21: =P21+AF21 -> -27736
A22: SG&A (by function) | B22: =VLOOKUP($A22,'Standardized Statements'!$A:$Q,B$4,FALSE) -> -90438 | C22: =VLOOKUP($A22,'Standardized Statements'!$A:$Q,C$4,FALSE) -> -105091 | D22: =VLOOKUP($A22,'Standardized Statements'!$A:$Q,D$4,FALSE) -> -95380 | E22: =VLOOKUP($A22,'Standardized Statements'!$A:$Q,E$4,FALSE) -> -87508 | F22: =VLOOKUP($A22,'Standardized Statements'!$A:$Q,F$4,FALSE) -> -82336 | G22: =VLOOKUP($A22,'Standardized Statements'!$A:$Q,G$4,FALSE) -> -76204 | H22: =VLOOKUP($A22,'Standardized Statements'!$A:$Q,H$4,FALSE) -> -63443 | I22: =VLOOKUP($A22,'Standardized Statements'!$A:$Q,I$4,FALSE) -> -53843 | ... P22: =VLOOKUP($A22,'Standardized Statements'!$A:$Q,P$4,FALSE) -> -25357 | R22: =SUM(R27:R28) -> 0 | S22: =SUM(S27:S28) -> 1307.9549 | T22: =SUM(T27:T28) -> 1455.6144 | U22: =SUM(U27:U28) -> 1543.7699 | V22: =SUM(V27:V28) -> 1678.5271 | W22: =SUM(W27:W28) -> 1382.1055 | X22: =SUM(X27:X28) -> 1227.2319 | Y22: =SUM(Y27:Y28) -> 950.36557 | ... AF22: =SUM(AF27:AF28) -> 0 | AH22: =B22+R22 -> -90438 | AI22: =C22+S22 -> -103783.05 | AJ22: =D22+T22 -> -93924.386 | AK22: =E22+U22 -> -85964.23 | AL22: =F22+V22 -> -80657.473 | AM22: =G22+W22 -> -74821.894 | AN22: =H22+X22 -> -62215.768 | AO22: =I22+Y22 -> -52892.634 | ... AV22: =P22+AF22 -> -25357
A23: Other Operating Income, Net of Other Operating Expense (by function) | B23: =VLOOKUP($A23,'Standardized Statements'!$A:$Q,B$4,FALSE) -> 0 | C23: =VLOOKUP($A23,'Standardized Statements'!$A:$Q,C$4,FALSE) -> 0 | D23: =VLOOKUP($A23,'Standardized Statements'!$A:$Q,D$4,FALSE) -> 0 | E23: =VLOOKUP($A23,'Standardized Statements'!$A:$Q,E$4,FALSE) -> 0 | F23: =VLOOKUP($A23,'Standardized Statements'!$A:$Q,F$4,FALSE) -> 0 | G23: =VLOOKUP($A23,'Standardized Statements'!$A:$Q,G$4,FALSE) -> 0 | H23: =VLOOKUP($A23,'Standardized Statements'!$A:$Q,H$4,FALSE) -> 0 | I23: =VLOOKUP($A23,'Standardized Statements'!$A:$Q,I$4,FALSE) -> 0 | ... P23: =VLOOKUP($A23,'Standardized Statements'!$A:$Q,P$4,FALSE) -> 0 | AH23: =B23+R23 -> 0 | AI23: =C23+S23 -> 0 | AJ23: =D23+T23 -> 0 | AK23: =E23+U23 -> 0 | AL23: =F23+V23 -> 0 | AM23: =G23+W23 -> 0 | AN23: =H23+X23 -> 0 | AO23: =I23+Y23 -> 0 | ... AV23: =P23+AF23 -> 0
A24: Classification by nature:
A25: Cost of Materials (by nature) | B25: =IF(VLOOKUP($A25,'Standardized Statements'!$A:$Q,B$4,FALSE)=0,B$21,VLOOKUP($A25,'Standardized Statements'!$A:$Q,B$4,FALSE)) -> -91538 | C25: =IF(VLOOKUP($A25,'Standardized Statements'!$A:$Q,C$4,FALSE)=0,C$21,VLOOKUP($A25,'Standardized Statements'!$A:$Q,C$4,FALSE)) -> -109732 | D25: =IF(VLOOKUP($A25,'Standardized Statements'!$A:$Q,D$4,FALSE)=0,D$21,VLOOKUP($A25,'Standardized Statements'!$A:$Q,D$4,FALSE)) -> -98955 | E25: =IF(VLOOKUP($A25,'Standardized Statements'!$A:$Q,E$4,FALSE)=0,E$21,VLOOKUP($A25,'Standardized Statements'!$A:$Q,E$4,FALSE)) -> -91178 | F25: =IF(VLOOKUP($A25,'Standardized Statements'!$A:$Q,F$4,FALSE)=0,F$21,VLOOKUP($A25,'Standardized Statements'!$A:$Q,F$4,FALSE)) -> -85243 | G25: =IF(VLOOKUP($A25,'Standardized Statements'!$A:$Q,G$4,FALSE)=0,G$21,VLOOKUP($A25,'Standardized Statements'!$A:$Q,G$4,FALSE)) -> -76969 | H25: =IF(VLOOKUP($A25,'Standardized Statements'!$A:$Q,H$4,FALSE)=0,H$21,VLOOKUP($A25,'Standardized Statements'!$A:$Q,H$4,FALSE)) -> -61799 | I25: =IF(VLOOKUP($A25,'Standardized Statements'!$A:$Q,I$4,FALSE)=0,I$21,VLOOKUP($A25,'Standardized Statements'!$A:$Q,I$4,FALSE)) -> -52059 | ... P25: =IF(VLOOKUP($A25,'Standardized Statements'!$A:$Q,P$4,FALSE)=0,P$21,VLOOKUP($A25,'Standardized Statements'!$A:$Q,P$4,FALSE)) -> -27564 | AH25: =B25+R25 -> -91538 | AI25: =C25+S25 -> -109732 | AJ25: =D25+T25 -> -98955 | AK25: =E25+U25 -> -91178 | AL25: =F25+V25 -> -85243 | AM25: =G25+W25 -> -76969 | AN25: =H25+X25 -> -61799 | AO25: =I25+Y25 -> -52059 | ... AV25: =P25+AF25 -> -27564
A26: Personnel Expenses (by nature) | B26: =VLOOKUP($A26,'Standardized Statements'!$A:$Q,B$4,FALSE) -> -36952 | C26: =VLOOKUP($A26,'Standardized Statements'!$A:$Q,C$4,FALSE) -> -42385 | D26: =VLOOKUP($A26,'Standardized Statements'!$A:$Q,D$4,FALSE) -> -38543 | E26: =VLOOKUP($A26,'Standardized Statements'!$A:$Q,E$4,FALSE) -> -35634 | F26: =VLOOKUP($A26,'Standardized Statements'!$A:$Q,F$4,FALSE) -> -32561 | G26: =VLOOKUP($A26,'Standardized Statements'!$A:$Q,G$4,FALSE) -> -29952 | H26: =VLOOKUP($A26,'Standardized Statements'!$A:$Q,H$4,FALSE) -> -25048 | I26: =VLOOKUP($A26,'Standardized Statements'!$A:$Q,I$4,FALSE) -> -21423 | ... P26: =VLOOKUP($A26,'Standardized Statements'!$A:$Q,P$4,FALSE) -> -10991 | AH26: =B26+R26 -> -36952 | AI26: =C26+S26 -> -42385 | AJ26: =D26+T26 -> -38543 | AK26: =E26+U26 -> -35634 | AL26: =F26+V26 -> -32561 | AM26: =G26+W26 -> -29952 | AN26: =H26+X26 -> -25048 | AO26: =I26+Y26 -> -21423 | ... AV26: =P26+AF26 -> -10991
A27: Depreciation and Amortization (by nature) | B27: =VLOOKUP($A27,'Standardized Statements'!$A:$Q,B$4,FALSE) -> -25953 | C27: =VLOOKUP($A27,'Standardized Statements'!$A:$Q,C$4,FALSE) -> -11051 | D27: =VLOOKUP($A27,'Standardized Statements'!$A:$Q,D$4,FALSE) -> -9671 | E27: =VLOOKUP($A27,'Standardized Statements'!$A:$Q,E$4,FALSE) -> -8488 | F27: =VLOOKUP($A27,'Standardized Statements'!$A:$Q,F$4,FALSE) -> -7605 | G27: =VLOOKUP($A27,'Standardized Statements'!$A:$Q,G$4,FALSE) -> -6399 | H27: =VLOOKUP($A27,'Standardized Statements'!$A:$Q,H$4,FALSE) -> -5045 | I27: =VLOOKUP($A27,'Standardized Statements'!$A:$Q,I$4,FALSE) -> -4191 | ... P27: =VLOOKUP($A27,'Standardized Statements'!$A:$Q,P$4,FALSE) -> -1624 | R27: ='Lease adjustments'!B39 -> 0 | S27: ='Lease adjustments'!C39 -> -19814.045 | T27: ='Lease adjustments'!D39 -> -18917.386 | U27: ='Lease adjustments'!E39 -> -17582.23 | V27: ='Lease adjustments'!F39 -> -18875.473 | W27: ='Lease adjustments'!G39 -> -19171.894 | X27: ='Lease adjustments'!H39 -> -15948.768 | Y27: ='Lease adjustments'!I39 -> -14093.634 | ... AF27: ='Lease adjustments'!P39 -> 0 | AH27: =B27+R27 -> -25953 | AI27: =C27+S27 -> -30865.045 | AJ27: =D27+T27 -> -28588.386 | AK27: =E27+U27 -> -26070.23 | AL27: =F27+V27 -> -26480.473 | AM27: =G27+W27 -> -25570.894 | AN27: =H27+X27 -> -20993.768 | AO27: =I27+Y27 -> -18284.634 | ... AV27: =P27+AF27 -> -1624
A28: Other Operating Income, Net of Other Operating Expense (by nature) | B28: =IF(SUM(B21:B23)<>0,SUM(B21:B23)-SUM(B25:B27),VLOOKUP($A28,'Standardized Statements'!$A:$Q,B$4,FALSE)) -> -29482 | C28: =IF(SUM(C21:C23)<>0,SUM(C21:C23)-SUM(C25:C27),VLOOKUP($A28,'Standardized Statements'!$A:$Q,C$4,FALSE)) -> -52225 | D28: =IF(SUM(D21:D23)<>0,SUM(D21:D23)-SUM(D25:D27),VLOOKUP($A28,'Standardized Statements'!$A:$Q,D$4,FALSE)) -> -47724 | E28: =IF(SUM(E21:E23)<>0,SUM(E21:E23)-SUM(E25:E27),VLOOKUP($A28,'Standardized Statements'!$A:$Q,E$4,FALSE)) -> -44122 | F28: =IF(SUM(F21:F23)<>0,SUM(F21:F23)-SUM(F25:F27),VLOOKUP($A28,'Standardized Statements'!$A:$Q,F$4,FALSE)) -> -43017 | G28: =IF(SUM(G21:G23)<>0,SUM(G21:G23)-SUM(G25:G27),VLOOKUP($A28,'Standardized Statements'!$A:$Q,G$4,FALSE)) -> -40578 | H28: =IF(SUM(H21:H23)<>0,SUM(H21:H23)-SUM(H25:H27),VLOOKUP($A28,'Standardized Statements'!$A:$Q,H$4,FALSE)) -> -33918 | I28: =IF(SUM(I21:I23)<>0,SUM(I21:I23)-SUM(I25:I27),VLOOKUP($A28,'Standardized Statements'!$A:$Q,I$4,FALSE)) -> -28699 | ... P28: =IF(SUM(P21:P23)<>0,SUM(P21:P23)-SUM(P25:P27),VLOOKUP($A28,'Standardized Statements'!$A:$Q,P$4,FALSE)) -> -12914 | R28: ='Lease adjustments'!B38 -> 0 | S28: ='Lease adjustments'!C38 -> 21122 | T28: ='Lease adjustments'!D38 -> 20373 | U28: ='Lease adjustments'!E38 -> 19126 | V28: ='Lease adjustments'!F38 -> 20554 | W28: ='Lease adjustments'!G38 -> 20554 | X28: ='Lease adjustments'!H38 -> 17176 | Y28: ='Lease adjustments'!I38 -> 15044 | ... AF28: ='Lease adjustments'!P38 -> 0 | AH28: =B28+R28 -> -29482 | AI28: =C28+S28 -> -31103 | AJ28: =D28+T28 -> -27351 | AK28: =E28+U28 -> -24996 | AL28: =F28+V28 -> -22463 | AM28: =G28+W28 -> -20024 | AN28: =H28+X28 -> -16742 | AO28: =I28+Y28 -> -13655 | ... AV28: =P28+AF28 -> -12914
A30: BALANCE SHEET | B30: 2020 | C30: 2019 | D30: 2018 | E30: 2017 | F30: 2016 | G30: 2015 | H30: 2014 | I30: 2013 | J30: 2012 | K30: 2011 | L30: 2010 | M30: 2009 | N30: 2008 | O30: 2007 | P30: 2006 | AH30: 2020 | AI30: 2019 | AJ30: 2018 | AK30: 2017 | AL30: 2016 | AM30: 2015 | AN30: 2014 | AO30: 2013 | AP30: 2012 | AQ30: 2011 | AR30: 2010 | AS30: 2009 | AT30: 2008 | AU30: 2007 | AV30: 2006
A31: ASSETS
A32: Non-Current Tangible Assets | B32: =VLOOKUP($A32,'Standardized Statements'!$A:$Q,B$4,FALSE) -> 91365 | C32: =VLOOKUP($A32,'Standardized Statements'!$A:$Q,C$4,FALSE) -> 41303 | D32: =VLOOKUP($A32,'Standardized Statements'!$A:$Q,D$4,FALSE) -> 42947 | E32: =VLOOKUP($A32,'Standardized Statements'!$A:$Q,E$4,FALSE) -> 40410 | F32: =VLOOKUP($A32,'Standardized Statements'!$A:$Q,F$4,FALSE) -> 39323 | G32: =VLOOKUP($A32,'Standardized Statements'!$A:$Q,G$4,FALSE) -> 33622 | H32: =VLOOKUP($A32,'Standardized Statements'!$A:$Q,H$4,FALSE) -> 27457 | I32: =VLOOKUP($A32,'Standardized Statements'!$A:$Q,I$4,FALSE) -> 22777 | ... P32: =VLOOKUP($A32,'Standardized Statements'!$A:$Q,P$4,FALSE) -> 7776 | R32: ='Lease adjustments'!B32 -> 0 | S32: ='Lease adjustments'!C32 -> 65962.78 | T32: ='Lease adjustments'!D32 -> 65397.744 | U32: ='Lease adjustments'!E32 -> 72780.718 | V32: ='Lease adjustments'!F32 -> 75305.85 | W32: ='Lease adjustments'!G32 -> 78071.029 | X32: ='Lease adjustments'!H32 -> 72742.396 | Y32: ='Lease adjustments'!I32 -> 58439.615 | ... AF32: ='Lease adjustments'!P32 -> 29775.325 | AH32: =B32+R32 -> 91365 | AI32: =C32+S32 -> 107265.78 | AJ32: =D32+T32 -> 108344.74 | AK32: =E32+U32 -> 113190.72 | AL32: =F32+V32 -> 114628.85 | AM32: =G32+W32 -> 111693.03 | AN32: =H32+X32 -> 100199.4 | AO32: =I32+Y32 -> 81216.615 | ... AV32: =P32+AF32 -> 37551.325
A33: Non-Current Intangible Assets | B33: =VLOOKUP($A33,'Standardized Statements'!$A:$Q,B$4,FALSE) -> 10241 | C33: =VLOOKUP($A33,'Standardized Statements'!$A:$Q,C$4,FALSE) -> 11037 | D33: =VLOOKUP($A33,'Standardized Statements'!$A:$Q,D$4,FALSE) -> 9110 | E33: =VLOOKUP($A33,'Standardized Statements'!$A:$Q,E$4,FALSE) -> 6451 | F33: =VLOOKUP($A33,'Standardized Statements'!$A:$Q,F$4,FALSE) -> 4717 | G33: =VLOOKUP($A33,'Standardized Statements'!$A:$Q,G$4,FALSE) -> 3455 | H33: =VLOOKUP($A33,'Standardized Statements'!$A:$Q,H$4,FALSE) -> 2453 | I33: =VLOOKUP($A33,'Standardized Statements'!$A:$Q,I$4,FALSE) -> 1685 | ... P33: =VLOOKUP($A33,'Standardized Statements'!$A:$Q,P$4,FALSE) -> 0 | AH33: =B33+R33 -> 10241 | AI33: =C33+S33 -> 11037 | AJ33: =D33+T33 -> 9110 | AK33: =E33+U33 -> 6451 | AL33: =F33+V33 -> 4717 | AM33: =G33+W33 -> 3455 | AN33: =H33+X33 -> 2453 | AO33: =I33+Y33 -> 1685 | ... AV33: =P33+AF33 -> 0
A34: Minority Equity Investments | B34: =VLOOKUP($A34,'Standardized Statements'!$A:$Q,B$4,FALSE) -> 247 | C34: =VLOOKUP($A34,'Standardized Statements'!$A:$Q,C$4,FALSE) -> 210 | D34: =VLOOKUP($A34,'Standardized Statements'!$A:$Q,D$4,FALSE) -> 126 | E34: =VLOOKUP($A34,'Standardized Statements'!$A:$Q,E$4,FALSE) -> 0 | F34: =VLOOKUP($A34,'Standardized Statements'!$A:$Q,F$4,FALSE) -> 0 | G34: =VLOOKUP($A34,'Standardized Statements'!$A:$Q,G$4,FALSE) -> 0 | H34: =VLOOKUP($A34,'Standardized Statements'!$A:$Q,H$4,FALSE) -> 0 | I34: =VLOOKUP($A34,'Standardized Statements'!$A:$Q,I$4,FALSE) -> 0 | ... P34: =VLOOKUP($A34,'Standardized Statements'!$A:$Q,P$4,FALSE) -> 0 | AH34: =B34+R34 -> 247 | AI34: =C34+S34 -> 210 | AJ34: =D34+T34 -> 126 | AK34: =E34+U34 -> 0 | AL34: =F34+V34 -> 0 | AM34: =G34+W34 -> 0 | AN34: =H34+X34 -> 0 | AO34: =I34+Y34 -> 0 | ... AV34: =P34+AF34 -> 0
A35: Other Non-Operating Investments | B35: =VLOOKUP($A35,'Standardized Statements'!$A:$Q,B$4,FALSE) -> 1446 | C35: =VLOOKUP($A35,'Standardized Statements'!$A:$Q,C$4,FALSE) -> 1341 | D35: =VLOOKUP($A35,'Standardized Statements'!$A:$Q,D$4,FALSE) -> 1237 | E35: =VLOOKUP($A35,'Standardized Statements'!$A:$Q,E$4,FALSE) -> 1039 | F35: =VLOOKUP($A35,'Standardized Statements'!$A:$Q,F$4,FALSE) -> 1014 | G35: =VLOOKUP($A35,'Standardized Statements'!$A:$Q,G$4,FALSE) -> 862 | H35: =VLOOKUP($A35,'Standardized Statements'!$A:$Q,H$4,FALSE) -> 709 | I35: =VLOOKUP($A35,'Standardized Statements'!$A:$Q,I$4,FALSE) -> 659 | ... P35: =VLOOKUP($A35,'Standardized Statements'!$A:$Q,P$4,FALSE) -> 155 | AH35: =B35+R35 -> 1446 | AI35: =C35+S35 -> 1341 | AJ35: =D35+T35 -> 1237 | AK35: =E35+U35 -> 1039 | AL35: =F35+V35 -> 1014 | AM35: =G35+W35 -> 862 | AN35: =H35+X35 -> 709 | AO35: =I35+Y35 -> 659 | ... AV35: =P35+AF35 -> 155
A36: Deferred Tax Asset | B36: =VLOOKUP($A36,'Standardized Statements'!$A:$Q,B$4,FALSE) -> 5714 | C36: =VLOOKUP($A36,'Standardized Statements'!$A:$Q,C$4,FALSE) -> 4322 | D36: =VLOOKUP($A36,'Standardized Statements'!$A:$Q,D$4,FALSE) -> 3794 | E36: =VLOOKUP($A36,'Standardized Statements'!$A:$Q,E$4,FALSE) -> 2916 | F36: =VLOOKUP($A36,'Standardized Statements'!$A:$Q,F$4,FALSE) -> 2862 | G36: =VLOOKUP($A36,'Standardized Statements'!$A:$Q,G$4,FALSE) -> 2338 | H36: =VLOOKUP($A36,'Standardized Statements'!$A:$Q,H$4,FALSE) -> 2237 | I36: =VLOOKUP($A36,'Standardized Statements'!$A:$Q,I$4,FALSE) -> 1367 | ... P36: =VLOOKUP($A36,'Standardized Statements'!$A:$Q,P$4,FALSE) -> 102 | R36: =(-'Lease adjustments'!B35)+R58 -> 0 | S36: =(-'Lease adjustments'!C35)+S58 -> 0 | T36: =(-'Lease adjustments'!D35)+T58 -> 0 | U36: =(-'Lease adjustments'!E35)+U58 -> 0 | V36: =(-'Lease adjustments'!F35)+V58 -> 0 | W36: =(-'Lease adjustments'!G35)+W58 -> 0 | X36: =(-'Lease adjustments'!H35)+X58 -> 0 | Y36: =(-'Lease adjustments'!I35)+Y58 -> 0 | ... AF36: =(-'Lease adjustments'!P35)+AF58 -> -650 | AH36: =B36+R36 -> 5714 | AI36: =C36+S36 -> 4322 | AJ36: =D36+T36 -> 3794 | AK36: =E36+U36 -> 2916 | AL36: =F36+V36 -> 2862 | AM36: =G36+W36 -> 2338 | AN36: =H36+X36 -> 2237 | AO36: =I36+Y36 -> 1367 | ... AV36: =P36+AF36 -> -548
